[2019-03-12 15:30:20,366: DEBUG/MainProcess] | Worker: Preparing bootsteps.
[2019-03-12 15:30:20,378: DEBUG/MainProcess] | Worker: Building graph...
[2019-03-12 15:30:20,380: DEBUG/MainProcess] | Worker: New boot order: {Timer, Hub, Queues (intra), Pool, Autoscaler, Autoreloader, Beat, StateDB, Consumer}
[2019-03-12 15:30:20,420: DEBUG/MainProcess] | Consumer: Preparing bootsteps.
[2019-03-12 15:30:20,424: DEBUG/MainProcess] | Consumer: Building graph...
[2019-03-12 15:30:20,530: DEBUG/MainProcess] | Consumer: New boot order: {Connection, Events, Mingle, Gossip, Heart, Agent, Tasks, Control, event loop}
[2019-03-12 15:30:20,593: DEBUG/MainProcess] | Worker: Starting Hub
[2019-03-12 15:30:20,595: DEBUG/MainProcess] ^-- substep ok
[2019-03-12 15:30:20,597: DEBUG/MainProcess] | Worker: Starting Pool
[2019-03-12 15:30:20,754: DEBUG/MainProcess] ^-- substep ok
[2019-03-12 15:30:20,756: DEBUG/MainProcess] | Worker: Starting Consumer
[2019-03-12 15:30:20,757: DEBUG/MainProcess] | Consumer: Starting Connection
[2019-03-12 15:30:20,793: INFO/MainProcess] Connected to redis://127.0.0.1:6379/0
[2019-03-12 15:30:20,795: DEBUG/MainProcess] ^-- substep ok
[2019-03-12 15:30:20,797: DEBUG/MainProcess] | Consumer: Starting Events
[2019-03-12 15:30:20,825: DEBUG/MainProcess] ^-- substep ok
[2019-03-12 15:30:20,827: DEBUG/MainProcess] | Consumer: Starting Mingle
[2019-03-12 15:30:20,829: INFO/MainProcess] mingle: searching for neighbors
[2019-03-12 15:30:21,838: INFO/MainProcess] mingle: all alone
[2019-03-12 15:30:21,839: DEBUG/MainProcess] ^-- substep ok
[2019-03-12 15:30:21,840: DEBUG/MainProcess] | Consumer: Starting Gossip
[2019-03-12 15:30:21,846: DEBUG/MainProcess] ^-- substep ok
[2019-03-12 15:30:21,848: DEBUG/MainProcess] | Consumer: Starting Heart
[2019-03-12 15:30:21,851: DEBUG/MainProcess] ^-- substep ok
[2019-03-12 15:30:21,853: DEBUG/MainProcess] | Consumer: Starting Tasks
[2019-03-12 15:30:21,862: DEBUG/MainProcess] ^-- substep ok
[2019-03-12 15:30:21,864: DEBUG/MainProcess] | Consumer: Starting Control
[2019-03-12 15:30:21,868: DEBUG/MainProcess] ^-- substep ok
[2019-03-12 15:30:21,870: DEBUG/MainProcess] | Consumer: Starting event loop
[2019-03-12 15:30:21,872: WARNING/MainProcess] celery@localhost.localdomain ready.
[2019-03-12 15:30:21,873: DEBUG/MainProcess] | Worker: Hub.register Pool...
[2019-03-12 15:30:21,876: DEBUG/MainProcess] basic.qos: prefetch_count->8
[2019-03-12 15:32:38,379: INFO/MainProcess] Received task: 代码上线[2d3e2f7e-c3e8-43df-ae1c-dc790cfcb8f9]
[2019-03-12 15:32:38,382: DEBUG/MainProcess] TaskPool: Apply <function _fast_trace_task at 0x7f14c3cc4510> (args:('代码上线', '2d3e2f7e-c3e8-43df-ae1c-dc790cfcb8f9', ('12', {'status': 3, 'name': 'payask', 'version': 'v2.1.8', 'assign_to': <User: tompson>}), {}, {'task': '代码上线', 'id': '2d3e2f7e-c3e8-43df-ae1c-dc790cfcb8f9', 'args': ('12', {'status': 3, 'name': 'payask', 'version': 'v2.1.8', 'assign_to': <User: tompson>}), 'kwargs': {}, 'retries': 0, 'eta': None, 'expires': None, 'utc': True, 'callbacks': None, 'errbacks': None, 'timelimit': (None, None), 'taskset': None, 'chord': None, 'headers': {}, 'reply_to': '8978ed99-0507-334b-b485-5d7e7d2507ed', 'correlation_id': '2d3e2f7e-c3e8-43df-ae1c-dc790cfcb8f9', 'delivery_info': {'exchange': 'celery', 'routing_key': 'celery', 'priority': 0, 'redelivered': None}, 'hostname': 'celery@localhost.localdomain', 'is_eager': False, 'group': None}) kwargs:{})
[2019-03-12 15:32:38,390: WARNING/Worker-2] {'status': 3, 'name': 'payask', 'version': 'v2.1.8', 'assign_to': <User: tompson>}
[2019-03-12 15:32:38,391: DEBUG/MainProcess] Task accepted: 代码上线[2d3e2f7e-c3e8-43df-ae1c-dc790cfcb8f9] pid:19338
[2019-03-12 15:32:38,399: DEBUG/Worker-2] Starting new HTTP connection (1): 10.5.0.9:9001
[2019-03-12 15:32:38,518: DEBUG/Worker-2] http://10.5.0.9:9001 "GET /jenkins/crumbIssuer/api/json HTTP/1.1" 200 133
[2019-03-12 15:32:38,558: DEBUG/Worker-2] http://10.5.0.9:9001 "GET /jenkins/job/payask/api/json?depth=0 HTTP/1.1" 200 630
[2019-03-12 15:32:38,610: DEBUG/Worker-2] http://10.5.0.9:9001 "POST /jenkins/job/payask/buildWithParameters?Tag=v2.1.8 HTTP/1.1" 201 0
[2019-03-12 15:32:58,658: DEBUG/Worker-2] http://10.5.0.9:9001 "GET /jenkins/job/payask/2/consoleText HTTP/1.1" 200 667
[2019-03-12 15:32:58,678: ERROR/MainProcess] Task 代码上线[2d3e2f7e-c3e8-43df-ae1c-dc790cfcb8f9] raised unexpected: AttributeError("'dict' object has no attribute 'console_output'",)
Traceback (most recent call last):
  File "/home/vagrant/python3.6env/lib/python3.6/site-packages/celery/app/trace.py", line 240, in trace_task
    R = retval = fun(*args, **kwargs)
  File "/home/vagrant/python3.6env/lib/python3.6/site-packages/celery/app/trace.py", line 438, in __protected_call__
    return self.run(*args, **kwargs)
  File "/vagrant/devops/apps/release/tasks.py", line 24, in code_release
    deploy.console_output = console_output
AttributeError: 'dict' object has no attribute 'console_output'
[2019-03-12 15:36:27,735: INFO/MainProcess] Received task: 代码上线[1be81d8d-b359-40dc-8f56-3283e50ed309]
[2019-03-12 15:36:27,736: DEBUG/MainProcess] TaskPool: Apply <function _fast_trace_task at 0x7f14c3cc4510> (args:('代码上线', '1be81d8d-b359-40dc-8f56-3283e50ed309', ('13', {'status': 3, 'name': 'payask', 'version': 'v2.1.8', 'assign_to': <User: tompson>}), {}, {'task': '代码上线', 'id': '1be81d8d-b359-40dc-8f56-3283e50ed309', 'args': ('13', {'status': 3, 'name': 'payask', 'version': 'v2.1.8', 'assign_to': <User: tompson>}), 'kwargs': {}, 'retries': 0, 'eta': None, 'expires': None, 'utc': True, 'callbacks': None, 'errbacks': None, 'timelimit': (None, None), 'taskset': None, 'chord': None, 'headers': {}, 'reply_to': '405998ee-5308-30e0-9831-8d32d6a8f805', 'correlation_id': '1be81d8d-b359-40dc-8f56-3283e50ed309', 'delivery_info': {'exchange': 'celery', 'routing_key': 'celery', 'priority': 0, 'redelivered': None}, 'hostname': 'celery@localhost.localdomain', 'is_eager': False, 'group': None}) kwargs:{})
[2019-03-12 15:36:27,744: DEBUG/MainProcess] Task accepted: 代码上线[1be81d8d-b359-40dc-8f56-3283e50ed309] pid:19337
[2019-03-12 15:36:27,743: WARNING/Worker-1] {'status': 3, 'name': 'payask', 'version': 'v2.1.8', 'assign_to': <User: tompson>}
[2019-03-12 15:36:27,757: DEBUG/Worker-1] Starting new HTTP connection (1): 10.5.0.9:9001
[2019-03-12 15:36:27,873: DEBUG/Worker-1] http://10.5.0.9:9001 "GET /jenkins/crumbIssuer/api/json HTTP/1.1" 200 133
[2019-03-12 15:36:27,901: DEBUG/Worker-1] http://10.5.0.9:9001 "GET /jenkins/job/payask/api/json?depth=0 HTTP/1.1" 200 647
[2019-03-12 15:36:27,919: DEBUG/Worker-1] http://10.5.0.9:9001 "POST /jenkins/job/payask/buildWithParameters?Tag=v2.1.8 HTTP/1.1" 201 0
[2019-03-12 15:36:47,983: ERROR/MainProcess] Task 代码上线[1be81d8d-b359-40dc-8f56-3283e50ed309] raised unexpected: ConnectionError(ProtocolError('Connection aborted.', RemoteDisconnected('Remote end closed connection without response',)),)
Traceback (most recent call last):
  File "/home/vagrant/python3.6env/lib/python3.6/site-packages/celery/app/trace.py", line 240, in trace_task
    R = retval = fun(*args, **kwargs)
  File "/home/vagrant/python3.6env/lib/python3.6/site-packages/celery/app/trace.py", line 438, in __protected_call__
    return self.run(*args, **kwargs)
  File "/vagrant/devops/apps/release/tasks.py", line 23, in code_release
    console_output = jenkins.get_build_console_output(deploy['name'], number)
  File "/vagrant/devops/apps/utils/jenkins_api.py", line 46, in get_build_console_output
    return self.server.get_build_console_output(name, number)
  File "/home/vagrant/python3.6env/lib/python3.6/site-packages/jenkins/__init__.py", line 1621, in get_build_console_output
    'GET', self._build_url(BUILD_CONSOLE_OUTPUT, locals())
  File "/home/vagrant/python3.6env/lib/python3.6/site-packages/jenkins/__init__.py", line 564, in jenkins_open
    return self.jenkins_request(req, add_crumb, resolve_auth).text
  File "/home/vagrant/python3.6env/lib/python3.6/site-packages/jenkins/__init__.py", line 583, in jenkins_request
    self._request(req))
  File "/home/vagrant/python3.6env/lib/python3.6/site-packages/jenkins/__init__.py", line 557, in _request
    return self._session.send(r, **_settings)
  File "/home/vagrant/python3.6env/lib/python3.6/site-packages/requests/sessions.py", line 646, in send
    r = adapter.send(request, **kwargs)
  File "/home/vagrant/python3.6env/lib/python3.6/site-packages/requests/adapters.py", line 498, in send
    raise ConnectionError(err, request=request)
requests.exceptions.ConnectionError: ('Connection aborted.', RemoteDisconnected('Remote end closed connection without response',))
[2019-03-12 15:44:17,749: INFO/MainProcess] Received task: 代码上线[9d5441e0-0211-478d-8abe-689f19658cf4]
[2019-03-12 15:44:17,750: DEBUG/MainProcess] TaskPool: Apply <function _fast_trace_task at 0x7f14c3cc4510> (args:('代码上线', '9d5441e0-0211-478d-8abe-689f19658cf4', ('14', {'status': 3, 'name': 'payask', 'version': 'v2.1.8', 'assign_to': <User: tompson>}), {}, {'task': '代码上线', 'id': '9d5441e0-0211-478d-8abe-689f19658cf4', 'args': ('14', {'status': 3, 'name': 'payask', 'version': 'v2.1.8', 'assign_to': <User: tompson>}), 'kwargs': {}, 'retries': 0, 'eta': None, 'expires': None, 'utc': True, 'callbacks': None, 'errbacks': None, 'timelimit': (None, None), 'taskset': None, 'chord': None, 'headers': {}, 'reply_to': '405998ee-5308-30e0-9831-8d32d6a8f805', 'correlation_id': '9d5441e0-0211-478d-8abe-689f19658cf4', 'delivery_info': {'exchange': 'celery', 'routing_key': 'celery', 'priority': 0, 'redelivered': None}, 'hostname': 'celery@localhost.localdomain', 'is_eager': False, 'group': None}) kwargs:{})
[2019-03-12 15:44:17,755: DEBUG/MainProcess] Task accepted: 代码上线[9d5441e0-0211-478d-8abe-689f19658cf4] pid:19338
[2019-03-12 15:44:17,754: WARNING/Worker-2] {'status': 3, 'name': 'payask', 'version': 'v2.1.8', 'assign_to': <User: tompson>}
[2019-03-12 15:44:17,769: DEBUG/Worker-2] Starting new HTTP connection (1): 10.5.0.9:9001
[2019-03-12 15:44:17,888: DEBUG/Worker-2] http://10.5.0.9:9001 "GET /jenkins/crumbIssuer/api/json HTTP/1.1" 200 133
[2019-03-12 15:44:17,908: DEBUG/Worker-2] http://10.5.0.9:9001 "GET /jenkins/job/payask/api/json?depth=0 HTTP/1.1" 200 654
[2019-03-12 15:44:17,928: DEBUG/Worker-2] http://10.5.0.9:9001 "POST /jenkins/job/payask/buildWithParameters?Tag=v2.1.8 HTTP/1.1" 201 0
[2019-03-12 15:44:38,003: DEBUG/Worker-2] http://10.5.0.9:9001 "GET /jenkins/job/payask/4/consoleText HTTP/1.1" 200 590
[2019-03-12 15:44:38,023: ERROR/MainProcess] Task 代码上线[9d5441e0-0211-478d-8abe-689f19658cf4] raised unexpected: AttributeError("'dict' object has no attribute 'console_output'",)
Traceback (most recent call last):
  File "/home/vagrant/python3.6env/lib/python3.6/site-packages/celery/app/trace.py", line 240, in trace_task
    R = retval = fun(*args, **kwargs)
  File "/home/vagrant/python3.6env/lib/python3.6/site-packages/celery/app/trace.py", line 438, in __protected_call__
    return self.run(*args, **kwargs)
  File "/vagrant/devops/apps/release/tasks.py", line 24, in code_release
    deploy["console_output"] = console_output
AttributeError: 'dict' object has no attribute 'console_output'
[2019-03-12 15:45:09,110: DEBUG/MainProcess] | Worker: Closing Hub...
[2019-03-12 15:45:09,112: DEBUG/MainProcess] | Worker: Closing Pool...
[2019-03-12 15:45:09,115: DEBUG/MainProcess] | Worker: Closing Consumer...
[2019-03-12 15:45:09,117: DEBUG/MainProcess] | Worker: Stopping Consumer...
[2019-03-12 15:45:09,120: DEBUG/MainProcess] | Consumer: Closing Connection...
[2019-03-12 15:45:09,123: DEBUG/MainProcess] | Consumer: Closing Events...
[2019-03-12 15:45:09,126: DEBUG/MainProcess] | Consumer: Closing Mingle...
[2019-03-12 15:45:09,128: DEBUG/MainProcess] | Consumer: Closing Gossip...
[2019-03-12 15:45:09,130: DEBUG/MainProcess] | Consumer: Closing Heart...
[2019-03-12 15:45:09,132: DEBUG/MainProcess] | Consumer: Closing Tasks...
[2019-03-12 15:45:09,134: DEBUG/MainProcess] | Consumer: Closing Control...
[2019-03-12 15:45:09,139: DEBUG/MainProcess] | Consumer: Closing event loop...
[2019-03-12 15:45:09,140: DEBUG/MainProcess] | Consumer: Stopping event loop...
[2019-03-12 15:45:09,141: DEBUG/MainProcess] | Consumer: Stopping Control...
[2019-03-12 15:45:09,145: DEBUG/MainProcess] | Consumer: Stopping Tasks...
[2019-03-12 15:45:09,146: DEBUG/MainProcess] Canceling task consumer...
[2019-03-12 15:45:09,148: DEBUG/MainProcess] | Consumer: Stopping Heart...
[2019-03-12 15:45:09,150: DEBUG/MainProcess] | Consumer: Stopping Gossip...
[2019-03-12 15:45:09,153: DEBUG/MainProcess] | Consumer: Stopping Mingle...
[2019-03-12 15:45:09,154: DEBUG/MainProcess] | Consumer: Stopping Events...
[2019-03-12 15:45:09,155: DEBUG/MainProcess] | Consumer: Stopping Connection...
[2019-03-12 15:45:09,156: DEBUG/MainProcess] | Worker: Stopping Pool...
[2019-03-12 15:45:10,178: DEBUG/MainProcess] | Worker: Stopping Hub...
[2019-03-12 15:45:10,182: DEBUG/MainProcess] | Consumer: Shutdown Control...
[2019-03-12 15:45:10,186: DEBUG/MainProcess] | Consumer: Shutdown Tasks...
[2019-03-12 15:45:10,189: DEBUG/MainProcess] Canceling task consumer...
[2019-03-12 15:45:10,190: DEBUG/MainProcess] Closing consumer channel...
[2019-03-12 15:45:10,191: DEBUG/MainProcess] | Consumer: Shutdown Heart...
[2019-03-12 15:45:10,192: DEBUG/MainProcess] | Consumer: Shutdown Gossip...
[2019-03-12 15:45:10,194: DEBUG/MainProcess] | Consumer: Shutdown Events...
[2019-03-12 15:45:10,195: DEBUG/MainProcess] | Consumer: Shutdown Connection...
[2019-03-12 15:45:10,197: DEBUG/MainProcess] removing tasks from inqueue until task handler finished
[2019-03-12 15:45:42,536: DEBUG/MainProcess] | Worker: Preparing bootsteps.
[2019-03-12 15:45:42,543: DEBUG/MainProcess] | Worker: Building graph...
[2019-03-12 15:45:42,546: DEBUG/MainProcess] | Worker: New boot order: {Beat, StateDB, Timer, Hub, Queues (intra), Pool, Autoreloader, Autoscaler, Consumer}
[2019-03-12 15:45:42,585: DEBUG/MainProcess] | Consumer: Preparing bootsteps.
[2019-03-12 15:45:42,587: DEBUG/MainProcess] | Consumer: Building graph...
[2019-03-12 15:45:42,642: DEBUG/MainProcess] | Consumer: New boot order: {Connection, Events, Mingle, Gossip, Heart, Agent, Tasks, Control, event loop}
[2019-03-12 15:45:42,682: DEBUG/MainProcess] | Worker: Starting Hub
[2019-03-12 15:45:42,684: DEBUG/MainProcess] ^-- substep ok
[2019-03-12 15:45:42,685: DEBUG/MainProcess] | Worker: Starting Pool
[2019-03-12 15:45:42,832: DEBUG/MainProcess] ^-- substep ok
[2019-03-12 15:45:42,834: DEBUG/MainProcess] | Worker: Starting Consumer
[2019-03-12 15:45:42,835: DEBUG/MainProcess] | Consumer: Starting Connection
[2019-03-12 15:45:42,868: INFO/MainProcess] Connected to redis://127.0.0.1:6379/0
[2019-03-12 15:45:42,870: DEBUG/MainProcess] ^-- substep ok
[2019-03-12 15:45:42,871: DEBUG/MainProcess] | Consumer: Starting Events
[2019-03-12 15:45:42,911: DEBUG/MainProcess] ^-- substep ok
[2019-03-12 15:45:42,912: DEBUG/MainProcess] | Consumer: Starting Mingle
[2019-03-12 15:45:42,914: INFO/MainProcess] mingle: searching for neighbors
[2019-03-12 15:45:43,931: INFO/MainProcess] mingle: all alone
[2019-03-12 15:45:43,933: DEBUG/MainProcess] ^-- substep ok
[2019-03-12 15:45:43,934: DEBUG/MainProcess] | Consumer: Starting Gossip
[2019-03-12 15:45:43,941: DEBUG/MainProcess] ^-- substep ok
[2019-03-12 15:45:43,942: DEBUG/MainProcess] | Consumer: Starting Heart
[2019-03-12 15:45:43,945: DEBUG/MainProcess] ^-- substep ok
[2019-03-12 15:45:43,946: DEBUG/MainProcess] | Consumer: Starting Tasks
[2019-03-12 15:45:43,954: DEBUG/MainProcess] ^-- substep ok
[2019-03-12 15:45:43,956: DEBUG/MainProcess] | Consumer: Starting Control
[2019-03-12 15:45:43,961: DEBUG/MainProcess] ^-- substep ok
[2019-03-12 15:45:43,963: DEBUG/MainProcess] | Consumer: Starting event loop
[2019-03-12 15:45:43,964: WARNING/MainProcess] celery@localhost.localdomain ready.
[2019-03-12 15:45:43,965: DEBUG/MainProcess] | Worker: Hub.register Pool...
[2019-03-12 15:45:43,968: DEBUG/MainProcess] basic.qos: prefetch_count->8
[2019-03-12 15:46:28,467: INFO/MainProcess] Received task: 代码上线[37d269b7-f495-43f2-a852-7df2eb33df15]
[2019-03-12 15:46:28,472: DEBUG/MainProcess] TaskPool: Apply <function _fast_trace_task at 0x7f1ef46461e0> (args:('代码上线', '37d269b7-f495-43f2-a852-7df2eb33df15', ('15', {'status': 3, 'name': 'payask', 'version': 'v2.1.8', 'assign_to': <User: tompson>}), {}, {'task': '代码上线', 'id': '37d269b7-f495-43f2-a852-7df2eb33df15', 'args': ('15', {'status': 3, 'name': 'payask', 'version': 'v2.1.8', 'assign_to': <User: tompson>}), 'kwargs': {}, 'retries': 0, 'eta': None, 'expires': None, 'utc': True, 'callbacks': None, 'errbacks': None, 'timelimit': (None, None), 'taskset': None, 'chord': None, 'headers': {}, 'reply_to': '405998ee-5308-30e0-9831-8d32d6a8f805', 'correlation_id': '37d269b7-f495-43f2-a852-7df2eb33df15', 'delivery_info': {'exchange': 'celery', 'routing_key': 'celery', 'priority': 0, 'redelivered': None}, 'hostname': 'celery@localhost.localdomain', 'is_eager': False, 'group': None}) kwargs:{})
[2019-03-12 15:46:28,479: WARNING/Worker-2] {'status': 3, 'name': 'payask', 'version': 'v2.1.8', 'assign_to': <User: tompson>}
[2019-03-12 15:46:28,479: DEBUG/MainProcess] Task accepted: 代码上线[37d269b7-f495-43f2-a852-7df2eb33df15] pid:19580
[2019-03-12 15:46:28,494: DEBUG/Worker-2] Starting new HTTP connection (1): 10.5.0.9:9001
[2019-03-12 15:46:28,615: DEBUG/Worker-2] http://10.5.0.9:9001 "GET /jenkins/crumbIssuer/api/json HTTP/1.1" 200 133
[2019-03-12 15:46:28,637: DEBUG/Worker-2] http://10.5.0.9:9001 "GET /jenkins/job/payask/api/json?depth=0 HTTP/1.1" 200 662
[2019-03-12 15:46:28,661: DEBUG/Worker-2] http://10.5.0.9:9001 "POST /jenkins/job/payask/buildWithParameters?Tag=v2.1.8 HTTP/1.1" 201 0
[2019-03-12 15:46:48,694: DEBUG/Worker-2] Resetting dropped connection: 10.5.0.9
[2019-03-12 15:46:48,823: DEBUG/Worker-2] http://10.5.0.9:9001 "GET /jenkins/job/payask/5/consoleText HTTP/1.1" 200 589
[2019-03-12 15:46:48,886: ERROR/MainProcess] Task 代码上线[37d269b7-f495-43f2-a852-7df2eb33df15] raised unexpected: AttributeError("'dict' object has no attribute 'save'",)
Traceback (most recent call last):
  File "/home/vagrant/python3.6env/lib/python3.6/site-packages/celery/app/trace.py", line 240, in trace_task
    R = retval = fun(*args, **kwargs)
  File "/home/vagrant/python3.6env/lib/python3.6/site-packages/celery/app/trace.py", line 438, in __protected_call__
    return self.run(*args, **kwargs)
  File "/vagrant/devops/apps/release/tasks.py", line 25, in code_release
    deploy.save()
AttributeError: 'dict' object has no attribute 'save'
[2019-03-12 15:47:47,833: DEBUG/MainProcess] | Worker: Closing Hub...
[2019-03-12 15:47:47,835: DEBUG/MainProcess] | Worker: Closing Pool...
[2019-03-12 15:47:47,837: DEBUG/MainProcess] | Worker: Closing Consumer...
[2019-03-12 15:47:47,838: DEBUG/MainProcess] | Worker: Stopping Consumer...
[2019-03-12 15:47:47,840: DEBUG/MainProcess] | Consumer: Closing Connection...
[2019-03-12 15:47:47,841: DEBUG/MainProcess] | Consumer: Closing Events...
[2019-03-12 15:47:47,842: DEBUG/MainProcess] | Consumer: Closing Mingle...
[2019-03-12 15:47:47,843: DEBUG/MainProcess] | Consumer: Closing Gossip...
[2019-03-12 15:47:47,846: DEBUG/MainProcess] | Consumer: Closing Heart...
[2019-03-12 15:47:47,847: DEBUG/MainProcess] | Consumer: Closing Tasks...
[2019-03-12 15:47:47,847: DEBUG/MainProcess] | Consumer: Closing Control...
[2019-03-12 15:47:47,848: DEBUG/MainProcess] | Consumer: Closing event loop...
[2019-03-12 15:47:47,849: DEBUG/MainProcess] | Consumer: Stopping event loop...
[2019-03-12 15:47:47,851: DEBUG/MainProcess] | Consumer: Stopping Control...
[2019-03-12 15:47:47,853: DEBUG/MainProcess] | Consumer: Stopping Tasks...
[2019-03-12 15:47:47,855: DEBUG/MainProcess] Canceling task consumer...
[2019-03-12 15:47:47,856: DEBUG/MainProcess] | Consumer: Stopping Heart...
[2019-03-12 15:47:47,858: DEBUG/MainProcess] | Consumer: Stopping Gossip...
[2019-03-12 15:47:47,861: DEBUG/MainProcess] | Consumer: Stopping Mingle...
[2019-03-12 15:47:47,863: DEBUG/MainProcess] | Consumer: Stopping Events...
[2019-03-12 15:47:47,864: DEBUG/MainProcess] | Consumer: Stopping Connection...
[2019-03-12 15:47:47,865: DEBUG/MainProcess] | Worker: Stopping Pool...
[2019-03-12 15:47:48,051: DEBUG/MainProcess] removing tasks from inqueue until task handler finished
[2019-03-12 15:47:56,338: DEBUG/MainProcess] | Worker: Preparing bootsteps.
[2019-03-12 15:47:56,345: DEBUG/MainProcess] | Worker: Building graph...
[2019-03-12 15:47:56,347: DEBUG/MainProcess] | Worker: New boot order: {Beat, Timer, Hub, Queues (intra), Pool, Autoreloader, Autoscaler, StateDB, Consumer}
[2019-03-12 15:47:56,383: DEBUG/MainProcess] | Consumer: Preparing bootsteps.
[2019-03-12 15:47:56,385: DEBUG/MainProcess] | Consumer: Building graph...
[2019-03-12 15:47:56,452: DEBUG/MainProcess] | Consumer: New boot order: {Connection, Events, Mingle, Gossip, Agent, Tasks, Control, Heart, event loop}
[2019-03-12 15:47:56,488: DEBUG/MainProcess] | Worker: Starting Hub
[2019-03-12 15:47:56,490: DEBUG/MainProcess] ^-- substep ok
[2019-03-12 15:47:56,491: DEBUG/MainProcess] | Worker: Starting Pool
[2019-03-12 15:47:56,655: DEBUG/MainProcess] ^-- substep ok
[2019-03-12 15:47:56,657: DEBUG/MainProcess] | Worker: Starting Consumer
[2019-03-12 15:47:56,659: DEBUG/MainProcess] | Consumer: Starting Connection
[2019-03-12 15:47:56,693: INFO/MainProcess] Connected to redis://127.0.0.1:6379/0
[2019-03-12 15:47:56,694: DEBUG/MainProcess] ^-- substep ok
[2019-03-12 15:47:56,695: DEBUG/MainProcess] | Consumer: Starting Events
[2019-03-12 15:47:56,727: DEBUG/MainProcess] ^-- substep ok
[2019-03-12 15:47:56,728: DEBUG/MainProcess] | Consumer: Starting Mingle
[2019-03-12 15:47:56,730: INFO/MainProcess] mingle: searching for neighbors
[2019-03-12 15:47:57,740: INFO/MainProcess] mingle: all alone
[2019-03-12 15:47:57,742: DEBUG/MainProcess] ^-- substep ok
[2019-03-12 15:47:57,743: DEBUG/MainProcess] | Consumer: Starting Gossip
[2019-03-12 15:47:57,749: DEBUG/MainProcess] ^-- substep ok
[2019-03-12 15:47:57,750: DEBUG/MainProcess] | Consumer: Starting Tasks
[2019-03-12 15:47:57,756: DEBUG/MainProcess] ^-- substep ok
[2019-03-12 15:47:57,757: DEBUG/MainProcess] | Consumer: Starting Control
[2019-03-12 15:47:57,763: DEBUG/MainProcess] ^-- substep ok
[2019-03-12 15:47:57,764: DEBUG/MainProcess] | Consumer: Starting Heart
[2019-03-12 15:47:57,766: DEBUG/MainProcess] ^-- substep ok
[2019-03-12 15:47:57,768: DEBUG/MainProcess] | Consumer: Starting event loop
[2019-03-12 15:47:57,769: WARNING/MainProcess] celery@localhost.localdomain ready.
[2019-03-12 15:47:57,770: DEBUG/MainProcess] | Worker: Hub.register Pool...
[2019-03-12 15:47:57,771: DEBUG/MainProcess] basic.qos: prefetch_count->8
[2019-03-12 15:48:44,953: INFO/MainProcess] Received task: 代码上线[db41d583-96e7-4a46-ac46-99e456846f55]
[2019-03-12 15:48:44,958: DEBUG/MainProcess] TaskPool: Apply <function _fast_trace_task at 0x7fdbe70f51e0> (args:('代码上线', 'db41d583-96e7-4a46-ac46-99e456846f55', ('16', {'status': 3, 'name': 'payask', 'version': 'v2.1.8', 'assign_to': <User: tompson>}), {}, {'task': '代码上线', 'id': 'db41d583-96e7-4a46-ac46-99e456846f55', 'args': ('16', {'status': 3, 'name': 'payask', 'version': 'v2.1.8', 'assign_to': <User: tompson>}), 'kwargs': {}, 'retries': 0, 'eta': None, 'expires': None, 'utc': True, 'callbacks': None, 'errbacks': None, 'timelimit': (None, None), 'taskset': None, 'chord': None, 'headers': {}, 'reply_to': '5aa6c597-7778-35c4-b95e-3aebf8d7511a', 'correlation_id': 'db41d583-96e7-4a46-ac46-99e456846f55', 'delivery_info': {'exchange': 'celery', 'routing_key': 'celery', 'priority': 0, 'redelivered': None}, 'hostname': 'celery@localhost.localdomain', 'is_eager': False, 'group': None}) kwargs:{})
[2019-03-12 15:48:44,965: DEBUG/MainProcess] Task accepted: 代码上线[db41d583-96e7-4a46-ac46-99e456846f55] pid:19757
[2019-03-12 15:48:44,964: WARNING/Worker-1] {'status': 3, 'name': 'payask', 'version': 'v2.1.8', 'assign_to': <User: tompson>}
[2019-03-12 15:48:44,980: DEBUG/Worker-1] Starting new HTTP connection (1): 10.5.0.9:9001
[2019-03-12 15:48:45,098: DEBUG/Worker-1] http://10.5.0.9:9001 "GET /jenkins/crumbIssuer/api/json HTTP/1.1" 200 133
[2019-03-12 15:48:45,140: DEBUG/Worker-1] http://10.5.0.9:9001 "GET /jenkins/job/payask/api/json?depth=0 HTTP/1.1" 200 669
[2019-03-12 15:48:45,189: DEBUG/Worker-1] http://10.5.0.9:9001 "POST /jenkins/job/payask/buildWithParameters?Tag=v2.1.8 HTTP/1.1" 201 0
[2019-03-12 15:49:05,283: ERROR/MainProcess] Task 代码上线[db41d583-96e7-4a46-ac46-99e456846f55] raised unexpected: ConnectionError(ProtocolError('Connection aborted.', RemoteDisconnected('Remote end closed connection without response',)),)
Traceback (most recent call last):
  File "/home/vagrant/python3.6env/lib/python3.6/site-packages/celery/app/trace.py", line 240, in trace_task
    R = retval = fun(*args, **kwargs)
  File "/home/vagrant/python3.6env/lib/python3.6/site-packages/celery/app/trace.py", line 438, in __protected_call__
    return self.run(*args, **kwargs)
  File "/vagrant/devops/apps/release/tasks.py", line 23, in code_release
    console_output = jenkins.get_build_console_output(deploy['name'], number)
  File "/vagrant/devops/apps/utils/jenkins_api.py", line 46, in get_build_console_output
    return self.server.get_build_console_output(name, number)
  File "/home/vagrant/python3.6env/lib/python3.6/site-packages/jenkins/__init__.py", line 1621, in get_build_console_output
    'GET', self._build_url(BUILD_CONSOLE_OUTPUT, locals())
  File "/home/vagrant/python3.6env/lib/python3.6/site-packages/jenkins/__init__.py", line 564, in jenkins_open
    return self.jenkins_request(req, add_crumb, resolve_auth).text
  File "/home/vagrant/python3.6env/lib/python3.6/site-packages/jenkins/__init__.py", line 583, in jenkins_request
    self._request(req))
  File "/home/vagrant/python3.6env/lib/python3.6/site-packages/jenkins/__init__.py", line 557, in _request
    return self._session.send(r, **_settings)
  File "/home/vagrant/python3.6env/lib/python3.6/site-packages/requests/sessions.py", line 646, in send
    r = adapter.send(request, **kwargs)
  File "/home/vagrant/python3.6env/lib/python3.6/site-packages/requests/adapters.py", line 498, in send
    raise ConnectionError(err, request=request)
requests.exceptions.ConnectionError: ('Connection aborted.', RemoteDisconnected('Remote end closed connection without response',))
[2019-03-12 15:50:49,893: DEBUG/MainProcess] | Worker: Closing Hub...
[2019-03-12 15:50:49,896: DEBUG/MainProcess] | Worker: Closing Pool...
[2019-03-12 15:50:49,900: DEBUG/MainProcess] | Worker: Closing Consumer...
[2019-03-12 15:50:49,904: DEBUG/MainProcess] | Worker: Stopping Consumer...
[2019-03-12 15:50:49,907: DEBUG/MainProcess] | Consumer: Closing Connection...
[2019-03-12 15:50:49,911: DEBUG/MainProcess] | Consumer: Closing Events...
[2019-03-12 15:50:49,919: DEBUG/MainProcess] | Consumer: Closing Mingle...
[2019-03-12 15:50:49,924: DEBUG/MainProcess] | Consumer: Closing Gossip...
[2019-03-12 15:50:49,926: DEBUG/MainProcess] | Consumer: Closing Tasks...
[2019-03-12 15:50:49,927: DEBUG/MainProcess] | Consumer: Closing Control...
[2019-03-12 15:50:49,929: DEBUG/MainProcess] | Consumer: Closing Heart...
[2019-03-12 15:50:49,930: DEBUG/MainProcess] | Consumer: Closing event loop...
[2019-03-12 15:50:49,931: DEBUG/MainProcess] | Consumer: Stopping event loop...
[2019-03-12 15:50:49,933: DEBUG/MainProcess] | Consumer: Stopping Heart...
[2019-03-12 15:50:49,936: DEBUG/MainProcess] | Consumer: Stopping Control...
[2019-03-12 15:50:49,942: DEBUG/MainProcess] | Consumer: Stopping Tasks...
[2019-03-12 15:50:49,943: DEBUG/MainProcess] Canceling task consumer...
[2019-03-12 15:50:49,944: DEBUG/MainProcess] | Consumer: Stopping Gossip...
[2019-03-12 15:50:49,949: DEBUG/MainProcess] | Consumer: Stopping Mingle...
[2019-03-12 15:50:49,951: DEBUG/MainProcess] | Consumer: Stopping Events...
[2019-03-12 15:50:49,952: DEBUG/MainProcess] | Consumer: Stopping Connection...
[2019-03-12 15:50:49,953: DEBUG/MainProcess] | Worker: Stopping Pool...
[2019-03-12 15:50:50,727: DEBUG/MainProcess] removing tasks from inqueue until task handler finished
[2019-03-12 15:50:58,541: DEBUG/MainProcess] | Worker: Preparing bootsteps.
[2019-03-12 15:50:58,549: DEBUG/MainProcess] | Worker: Building graph...
[2019-03-12 15:50:58,551: DEBUG/MainProcess] | Worker: New boot order: {Beat, Timer, Hub, Queues (intra), Pool, Autoreloader, StateDB, Autoscaler, Consumer}
[2019-03-12 15:50:58,585: DEBUG/MainProcess] | Consumer: Preparing bootsteps.
[2019-03-12 15:50:58,586: DEBUG/MainProcess] | Consumer: Building graph...
[2019-03-12 15:50:58,648: DEBUG/MainProcess] | Consumer: New boot order: {Connection, Events, Mingle, Tasks, Control, Agent, Heart, Gossip, event loop}
[2019-03-12 15:50:58,696: DEBUG/MainProcess] | Worker: Starting Hub
[2019-03-12 15:50:58,699: DEBUG/MainProcess] ^-- substep ok
[2019-03-12 15:50:58,700: DEBUG/MainProcess] | Worker: Starting Pool
[2019-03-12 15:50:58,865: DEBUG/MainProcess] ^-- substep ok
[2019-03-12 15:50:58,872: DEBUG/MainProcess] | Worker: Starting Consumer
[2019-03-12 15:50:58,873: DEBUG/MainProcess] | Consumer: Starting Connection
[2019-03-12 15:50:58,916: INFO/MainProcess] Connected to redis://127.0.0.1:6379/0
[2019-03-12 15:50:58,917: DEBUG/MainProcess] ^-- substep ok
[2019-03-12 15:50:58,918: DEBUG/MainProcess] | Consumer: Starting Events
[2019-03-12 15:50:58,945: DEBUG/MainProcess] ^-- substep ok
[2019-03-12 15:50:58,946: DEBUG/MainProcess] | Consumer: Starting Mingle
[2019-03-12 15:50:58,947: INFO/MainProcess] mingle: searching for neighbors
[2019-03-12 15:50:59,957: INFO/MainProcess] mingle: all alone
[2019-03-12 15:50:59,960: DEBUG/MainProcess] ^-- substep ok
[2019-03-12 15:50:59,962: DEBUG/MainProcess] | Consumer: Starting Tasks
[2019-03-12 15:50:59,975: DEBUG/MainProcess] ^-- substep ok
[2019-03-12 15:50:59,978: DEBUG/MainProcess] | Consumer: Starting Control
[2019-03-12 15:50:59,985: DEBUG/MainProcess] ^-- substep ok
[2019-03-12 15:50:59,986: DEBUG/MainProcess] | Consumer: Starting Heart
[2019-03-12 15:50:59,988: DEBUG/MainProcess] ^-- substep ok
[2019-03-12 15:50:59,989: DEBUG/MainProcess] | Consumer: Starting Gossip
[2019-03-12 15:50:59,997: DEBUG/MainProcess] ^-- substep ok
[2019-03-12 15:50:59,998: DEBUG/MainProcess] | Consumer: Starting event loop
[2019-03-12 15:51:00,000: WARNING/MainProcess] celery@localhost.localdomain ready.
[2019-03-12 15:51:00,001: DEBUG/MainProcess] | Worker: Hub.register Pool...
[2019-03-12 15:51:00,004: DEBUG/MainProcess] basic.qos: prefetch_count->8
[2019-03-12 15:51:28,359: INFO/MainProcess] Received task: 代码上线[c1705658-8eef-446e-a947-5d758083d913]
[2019-03-12 15:51:28,363: DEBUG/MainProcess] TaskPool: Apply <function _fast_trace_task at 0x7f22087681e0> (args:('代码上线', 'c1705658-8eef-446e-a947-5d758083d913', ('17', {'status': 3, 'name': 'payask', 'version': 'v2.1.8', 'assign_to': <User: tompson>}), {}, {'task': '代码上线', 'id': 'c1705658-8eef-446e-a947-5d758083d913', 'args': ('17', {'status': 3, 'name': 'payask', 'version': 'v2.1.8', 'assign_to': <User: tompson>}), 'kwargs': {}, 'retries': 0, 'eta': None, 'expires': None, 'utc': True, 'callbacks': None, 'errbacks': None, 'timelimit': (None, None), 'taskset': None, 'chord': None, 'headers': {}, 'reply_to': '2534f4a7-d472-37d7-8587-9a5194b00d6a', 'correlation_id': 'c1705658-8eef-446e-a947-5d758083d913', 'delivery_info': {'exchange': 'celery', 'routing_key': 'celery', 'priority': 0, 'redelivered': None}, 'hostname': 'celery@localhost.localdomain', 'is_eager': False, 'group': None}) kwargs:{})
[2019-03-12 15:51:28,370: DEBUG/MainProcess] Task accepted: 代码上线[c1705658-8eef-446e-a947-5d758083d913] pid:19840
[2019-03-12 15:51:28,369: WARNING/Worker-2] {'status': 3, 'name': 'payask', 'version': 'v2.1.8', 'assign_to': <User: tompson>}
[2019-03-12 15:51:28,379: DEBUG/Worker-2] Starting new HTTP connection (1): 10.5.0.9:9001
[2019-03-12 15:51:28,495: DEBUG/Worker-2] http://10.5.0.9:9001 "GET /jenkins/crumbIssuer/api/json HTTP/1.1" 200 133
[2019-03-12 15:51:28,515: DEBUG/Worker-2] http://10.5.0.9:9001 "GET /jenkins/job/payask/api/json?depth=0 HTTP/1.1" 200 675
[2019-03-12 15:51:28,535: DEBUG/Worker-2] http://10.5.0.9:9001 "POST /jenkins/job/payask/buildWithParameters?Tag=v2.1.8 HTTP/1.1" 201 0
[2019-03-12 15:51:48,610: ERROR/MainProcess] Task 代码上线[c1705658-8eef-446e-a947-5d758083d913] raised unexpected: ConnectionError(ProtocolError('Connection aborted.', RemoteDisconnected('Remote end closed connection without response',)),)
Traceback (most recent call last):
  File "/home/vagrant/python3.6env/lib/python3.6/site-packages/celery/app/trace.py", line 240, in trace_task
    R = retval = fun(*args, **kwargs)
  File "/home/vagrant/python3.6env/lib/python3.6/site-packages/celery/app/trace.py", line 438, in __protected_call__
    return self.run(*args, **kwargs)
  File "/vagrant/devops/apps/release/tasks.py", line 32, in code_release
    console_output = jenkins.get_build_console_output(deploy['name'], number)
  File "/vagrant/devops/apps/utils/jenkins_api.py", line 46, in get_build_console_output
    return self.server.get_build_console_output(name, number)
  File "/home/vagrant/python3.6env/lib/python3.6/site-packages/jenkins/__init__.py", line 1621, in get_build_console_output
    'GET', self._build_url(BUILD_CONSOLE_OUTPUT, locals())
  File "/home/vagrant/python3.6env/lib/python3.6/site-packages/jenkins/__init__.py", line 564, in jenkins_open
    return self.jenkins_request(req, add_crumb, resolve_auth).text
  File "/home/vagrant/python3.6env/lib/python3.6/site-packages/jenkins/__init__.py", line 583, in jenkins_request
    self._request(req))
  File "/home/vagrant/python3.6env/lib/python3.6/site-packages/jenkins/__init__.py", line 557, in _request
    return self._session.send(r, **_settings)
  File "/home/vagrant/python3.6env/lib/python3.6/site-packages/requests/sessions.py", line 646, in send
    r = adapter.send(request, **kwargs)
  File "/home/vagrant/python3.6env/lib/python3.6/site-packages/requests/adapters.py", line 498, in send
    raise ConnectionError(err, request=request)
requests.exceptions.ConnectionError: ('Connection aborted.', RemoteDisconnected('Remote end closed connection without response',))
[2019-03-12 15:54:33,326: DEBUG/MainProcess] | Worker: Closing Hub...
[2019-03-12 15:54:33,327: DEBUG/MainProcess] | Worker: Closing Pool...
[2019-03-12 15:54:33,329: DEBUG/MainProcess] | Worker: Closing Consumer...
[2019-03-12 15:54:33,330: DEBUG/MainProcess] | Worker: Stopping Consumer...
[2019-03-12 15:54:33,331: DEBUG/MainProcess] | Consumer: Closing Connection...
[2019-03-12 15:54:33,332: DEBUG/MainProcess] | Consumer: Closing Events...
[2019-03-12 15:54:33,333: DEBUG/MainProcess] | Consumer: Closing Mingle...
[2019-03-12 15:54:33,334: DEBUG/MainProcess] | Consumer: Closing Tasks...
[2019-03-12 15:54:33,335: DEBUG/MainProcess] | Consumer: Closing Control...
[2019-03-12 15:54:33,338: DEBUG/MainProcess] | Consumer: Closing Heart...
[2019-03-12 15:54:33,340: DEBUG/MainProcess] | Consumer: Closing Gossip...
[2019-03-12 15:54:33,341: DEBUG/MainProcess] | Consumer: Closing event loop...
[2019-03-12 15:54:33,342: DEBUG/MainProcess] | Consumer: Stopping event loop...
[2019-03-12 15:54:33,343: DEBUG/MainProcess] | Consumer: Stopping Gossip...
[2019-03-12 15:54:33,347: DEBUG/MainProcess] | Consumer: Stopping Heart...
[2019-03-12 15:54:33,349: DEBUG/MainProcess] | Consumer: Stopping Control...
[2019-03-12 15:54:33,352: DEBUG/MainProcess] | Consumer: Stopping Tasks...
[2019-03-12 15:54:33,353: DEBUG/MainProcess] Canceling task consumer...
[2019-03-12 15:54:33,354: DEBUG/MainProcess] | Consumer: Stopping Mingle...
[2019-03-12 15:54:33,355: DEBUG/MainProcess] | Consumer: Stopping Events...
[2019-03-12 15:54:33,356: DEBUG/MainProcess] | Consumer: Stopping Connection...
[2019-03-12 15:54:33,357: DEBUG/MainProcess] | Worker: Stopping Pool...
[2019-03-12 15:54:34,047: DEBUG/MainProcess] removing tasks from inqueue until task handler finished
[2019-03-12 15:54:41,351: DEBUG/MainProcess] | Worker: Preparing bootsteps.
[2019-03-12 15:54:41,362: DEBUG/MainProcess] | Worker: Building graph...
[2019-03-12 15:54:41,364: DEBUG/MainProcess] | Worker: New boot order: {Beat, Timer, Hub, Queues (intra), Pool, Autoscaler, Autoreloader, StateDB, Consumer}
[2019-03-12 15:54:41,403: DEBUG/MainProcess] | Consumer: Preparing bootsteps.
[2019-03-12 15:54:41,407: DEBUG/MainProcess] | Consumer: Building graph...
[2019-03-12 15:54:41,450: DEBUG/MainProcess] | Consumer: New boot order: {Connection, Agent, Events, Heart, Mingle, Gossip, Tasks, Control, event loop}
[2019-03-12 15:54:41,489: DEBUG/MainProcess] | Worker: Starting Hub
[2019-03-12 15:54:41,491: DEBUG/MainProcess] ^-- substep ok
[2019-03-12 15:54:41,492: DEBUG/MainProcess] | Worker: Starting Pool
[2019-03-12 15:54:41,648: DEBUG/MainProcess] ^-- substep ok
[2019-03-12 15:54:41,651: DEBUG/MainProcess] | Worker: Starting Consumer
[2019-03-12 15:54:41,652: DEBUG/MainProcess] | Consumer: Starting Connection
[2019-03-12 15:54:41,679: INFO/MainProcess] Connected to redis://127.0.0.1:6379/0
[2019-03-12 15:54:41,680: DEBUG/MainProcess] ^-- substep ok
[2019-03-12 15:54:41,682: DEBUG/MainProcess] | Consumer: Starting Events
[2019-03-12 15:54:41,709: DEBUG/MainProcess] ^-- substep ok
[2019-03-12 15:54:41,711: DEBUG/MainProcess] | Consumer: Starting Heart
[2019-03-12 15:54:41,714: DEBUG/MainProcess] ^-- substep ok
[2019-03-12 15:54:41,715: DEBUG/MainProcess] | Consumer: Starting Mingle
[2019-03-12 15:54:41,716: INFO/MainProcess] mingle: searching for neighbors
[2019-03-12 15:54:42,726: INFO/MainProcess] mingle: all alone
[2019-03-12 15:54:42,727: DEBUG/MainProcess] ^-- substep ok
[2019-03-12 15:54:42,728: DEBUG/MainProcess] | Consumer: Starting Gossip
[2019-03-12 15:54:42,734: DEBUG/MainProcess] ^-- substep ok
[2019-03-12 15:54:42,735: DEBUG/MainProcess] | Consumer: Starting Tasks
[2019-03-12 15:54:42,743: DEBUG/MainProcess] ^-- substep ok
[2019-03-12 15:54:42,744: DEBUG/MainProcess] | Consumer: Starting Control
[2019-03-12 15:54:42,748: DEBUG/MainProcess] ^-- substep ok
[2019-03-12 15:54:42,749: DEBUG/MainProcess] | Consumer: Starting event loop
[2019-03-12 15:54:42,751: WARNING/MainProcess] celery@localhost.localdomain ready.
[2019-03-12 15:54:42,752: DEBUG/MainProcess] | Worker: Hub.register Pool...
[2019-03-12 15:54:42,755: DEBUG/MainProcess] basic.qos: prefetch_count->8
[2019-03-12 15:57:09,407: INFO/MainProcess] Received task: 代码上线[0792bf08-e20a-43ad-99dc-e32c7512eaf0]
[2019-03-12 15:57:09,410: DEBUG/MainProcess] TaskPool: Apply <function _fast_trace_task at 0x7ffa59c481e0> (args:('代码上线', '0792bf08-e20a-43ad-99dc-e32c7512eaf0', ('18', {'status': 3, 'name': 'payask', 'version': 'v2.1.8', 'assign_to': <User: tompson>}), {}, {'task': '代码上线', 'id': '0792bf08-e20a-43ad-99dc-e32c7512eaf0', 'args': ('18', {'status': 3, 'name': 'payask', 'version': 'v2.1.8', 'assign_to': <User: tompson>}), 'kwargs': {}, 'retries': 0, 'eta': None, 'expires': None, 'utc': True, 'callbacks': None, 'errbacks': None, 'timelimit': (None, None), 'taskset': None, 'chord': None, 'headers': {}, 'reply_to': 'ef118679-18e4-3db9-be71-68661484d148', 'correlation_id': '0792bf08-e20a-43ad-99dc-e32c7512eaf0', 'delivery_info': {'exchange': 'celery', 'routing_key': 'celery', 'priority': 0, 'redelivered': None}, 'hostname': 'celery@localhost.localdomain', 'is_eager': False, 'group': None}) kwargs:{})
[2019-03-12 15:57:09,417: WARNING/Worker-2] {'status': 3, 'name': 'payask', 'version': 'v2.1.8', 'assign_to': <User: tompson>}
[2019-03-12 15:57:09,419: DEBUG/MainProcess] Task accepted: 代码上线[0792bf08-e20a-43ad-99dc-e32c7512eaf0] pid:19898
[2019-03-12 15:57:09,437: DEBUG/Worker-2] Starting new HTTP connection (1): 10.5.0.9:9001
[2019-03-12 15:57:09,556: DEBUG/Worker-2] http://10.5.0.9:9001 "GET /jenkins/crumbIssuer/api/json HTTP/1.1" 200 133
[2019-03-12 15:57:09,585: DEBUG/Worker-2] http://10.5.0.9:9001 "GET /jenkins/job/payask/api/json?depth=0 HTTP/1.1" 200 684
[2019-03-12 15:57:09,629: DEBUG/Worker-2] http://10.5.0.9:9001 "POST /jenkins/job/payask/buildWithParameters?Tag=v2.1.8 HTTP/1.1" 201 0
[2019-03-12 15:57:19,658: DEBUG/Worker-2] http://10.5.0.9:9001 "GET /jenkins/job/payask/8/consoleText HTTP/1.1" 200 591
[2019-03-12 15:57:19,680: INFO/MainProcess] Task 代码上线[0792bf08-e20a-43ad-99dc-e32c7512eaf0] succeeded in 10.264575768000213s: '[payask] Project release completed.......'
[2019-03-12 17:28:49,388: DEBUG/MainProcess] | Worker: Closing Hub...
[2019-03-12 17:28:49,395: DEBUG/MainProcess] | Worker: Closing Pool...
[2019-03-12 17:28:49,397: DEBUG/MainProcess] | Worker: Closing Consumer...
[2019-03-12 17:28:49,399: DEBUG/MainProcess] | Worker: Stopping Consumer...
[2019-03-12 17:28:49,401: DEBUG/MainProcess] | Consumer: Closing Connection...
[2019-03-12 17:28:49,403: DEBUG/MainProcess] | Consumer: Closing Events...
[2019-03-12 17:28:49,405: DEBUG/MainProcess] | Consumer: Closing Heart...
[2019-03-12 17:28:49,408: DEBUG/MainProcess] | Consumer: Closing Mingle...
[2019-03-12 17:28:49,411: DEBUG/MainProcess] | Consumer: Closing Gossip...
[2019-03-12 17:28:49,413: DEBUG/MainProcess] | Consumer: Closing Tasks...
[2019-03-12 17:28:49,416: DEBUG/MainProcess] | Consumer: Closing Control...
[2019-03-12 17:28:49,417: DEBUG/MainProcess] | Consumer: Closing event loop...
[2019-03-12 17:28:49,422: DEBUG/MainProcess] | Consumer: Stopping event loop...
[2019-03-12 17:28:49,424: DEBUG/MainProcess] | Consumer: Stopping Control...
[2019-03-12 17:28:49,428: DEBUG/MainProcess] | Consumer: Stopping Tasks...
[2019-03-12 17:28:49,429: DEBUG/MainProcess] Canceling task consumer...
[2019-03-12 17:28:49,430: DEBUG/MainProcess] | Consumer: Stopping Gossip...
[2019-03-12 17:28:49,433: DEBUG/MainProcess] | Consumer: Stopping Mingle...
[2019-03-12 17:28:49,434: DEBUG/MainProcess] | Consumer: Stopping Heart...
[2019-03-12 17:28:49,437: DEBUG/MainProcess] | Consumer: Stopping Events...
[2019-03-12 17:28:49,438: DEBUG/MainProcess] | Consumer: Stopping Connection...
[2019-03-12 17:28:49,439: DEBUG/MainProcess] | Worker: Stopping Pool...
[2019-03-12 17:28:50,449: DEBUG/MainProcess] | Worker: Stopping Hub...
[2019-03-12 17:28:50,450: DEBUG/MainProcess] | Consumer: Shutdown Control...
[2019-03-12 17:28:50,451: DEBUG/MainProcess] | Consumer: Shutdown Tasks...
[2019-03-12 17:28:50,453: DEBUG/MainProcess] Canceling task consumer...
[2019-03-12 17:28:50,454: DEBUG/MainProcess] Closing consumer channel...
[2019-03-12 17:28:50,456: DEBUG/MainProcess] | Consumer: Shutdown Gossip...
[2019-03-12 17:28:50,457: DEBUG/MainProcess] | Consumer: Shutdown Heart...
[2019-03-12 17:28:50,458: DEBUG/MainProcess] | Consumer: Shutdown Events...
[2019-03-12 17:28:50,459: DEBUG/MainProcess] | Consumer: Shutdown Connection...
[2019-03-12 17:28:50,460: DEBUG/MainProcess] removing tasks from inqueue until task handler finished
[2019-03-12 17:28:57,989: DEBUG/MainProcess] | Worker: Preparing bootsteps.
[2019-03-12 17:28:57,997: DEBUG/MainProcess] | Worker: Building graph...
[2019-03-12 17:28:58,000: DEBUG/MainProcess] | Worker: New boot order: {Timer, Hub, Queues (intra), Pool, Autoscaler, Beat, StateDB, Autoreloader, Consumer}
[2019-03-12 17:28:58,039: DEBUG/MainProcess] | Consumer: Preparing bootsteps.
[2019-03-12 17:28:58,042: DEBUG/MainProcess] | Consumer: Building graph...
[2019-03-12 17:28:58,086: DEBUG/MainProcess] | Consumer: New boot order: {Connection, Events, Mingle, Gossip, Agent, Heart, Tasks, Control, event loop}
[2019-03-12 17:28:58,120: DEBUG/MainProcess] | Worker: Starting Hub
[2019-03-12 17:28:58,121: DEBUG/MainProcess] ^-- substep ok
[2019-03-12 17:28:58,122: DEBUG/MainProcess] | Worker: Starting Pool
[2019-03-12 17:28:58,269: DEBUG/MainProcess] ^-- substep ok
[2019-03-12 17:28:58,271: DEBUG/MainProcess] | Worker: Starting Consumer
[2019-03-12 17:28:58,272: DEBUG/MainProcess] | Consumer: Starting Connection
[2019-03-12 17:28:58,634: INFO/MainProcess] Connected to redis://:**@10.5.0.9:6300/0
[2019-03-12 17:28:58,636: DEBUG/MainProcess] ^-- substep ok
[2019-03-12 17:28:58,636: DEBUG/MainProcess] | Consumer: Starting Events
[2019-03-12 17:28:59,071: DEBUG/MainProcess] ^-- substep ok
[2019-03-12 17:28:59,073: DEBUG/MainProcess] | Consumer: Starting Mingle
[2019-03-12 17:28:59,075: INFO/MainProcess] mingle: searching for neighbors
[2019-03-12 17:29:00,314: INFO/MainProcess] mingle: all alone
[2019-03-12 17:29:00,316: DEBUG/MainProcess] ^-- substep ok
[2019-03-12 17:29:00,318: DEBUG/MainProcess] | Consumer: Starting Gossip
[2019-03-12 17:29:00,622: DEBUG/MainProcess] ^-- substep ok
[2019-03-12 17:29:00,624: DEBUG/MainProcess] | Consumer: Starting Heart
[2019-03-12 17:29:00,641: DEBUG/MainProcess] ^-- substep ok
[2019-03-12 17:29:00,643: DEBUG/MainProcess] | Consumer: Starting Tasks
[2019-03-12 17:29:00,719: DEBUG/MainProcess] ^-- substep ok
[2019-03-12 17:29:00,721: DEBUG/MainProcess] | Consumer: Starting Control
[2019-03-12 17:29:01,052: DEBUG/MainProcess] ^-- substep ok
[2019-03-12 17:29:01,053: DEBUG/MainProcess] | Consumer: Starting event loop
[2019-03-12 17:29:01,055: WARNING/MainProcess] celery@localhost.localdomain ready.
[2019-03-12 17:29:01,056: DEBUG/MainProcess] | Worker: Hub.register Pool...
[2019-03-12 17:29:01,058: DEBUG/MainProcess] basic.qos: prefetch_count->8
[2019-03-12 17:29:01,375: INFO/MainProcess] Received task: 代码上线[85f6ac58-b6c3-4f5c-ab66-12cbe929097b]
[2019-03-12 17:29:01,385: DEBUG/MainProcess] TaskPool: Apply <function _fast_trace_task at 0x7f56117671e0> (args:('代码上线', '85f6ac58-b6c3-4f5c-ab66-12cbe929097b', ('19', {'status': 3, 'name': 'payask', 'version': 'v2.1.8', 'assign_to': <User: tompson>}), {}, {'task': '代码上线', 'id': '85f6ac58-b6c3-4f5c-ab66-12cbe929097b', 'args': ('19', {'status': 3, 'name': 'payask', 'version': 'v2.1.8', 'assign_to': <User: tompson>}), 'kwargs': {}, 'retries': 0, 'eta': None, 'expires': None, 'utc': True, 'callbacks': None, 'errbacks': None, 'timelimit': (None, None), 'taskset': None, 'chord': None, 'headers': {}, 'reply_to': '8a9fc371-60ae-3b2d-8079-c64d74ad5f8f', 'correlation_id': '85f6ac58-b6c3-4f5c-ab66-12cbe929097b', 'delivery_info': {'exchange': 'celery', 'routing_key': 'celery', 'priority': 0, 'redelivered': None}, 'hostname': 'celery@localhost.localdomain', 'is_eager': False, 'group': None}) kwargs:{})
[2019-03-12 17:29:01,396: WARNING/Worker-2] {'status': 3, 'name': 'payask', 'version': 'v2.1.8', 'assign_to': <User: tompson>}
[2019-03-12 17:29:01,412: DEBUG/Worker-2] Starting new HTTP connection (1): 10.5.0.9:9001
[2019-03-12 17:29:01,479: DEBUG/MainProcess] Task accepted: 代码上线[85f6ac58-b6c3-4f5c-ab66-12cbe929097b] pid:21031
[2019-03-12 17:29:01,585: DEBUG/Worker-2] http://10.5.0.9:9001 "GET /jenkins/crumbIssuer/api/json HTTP/1.1" 200 133
[2019-03-12 17:29:01,628: DEBUG/Worker-2] http://10.5.0.9:9001 "GET /jenkins/job/payask/api/json?depth=0 HTTP/1.1" 200 690
[2019-03-12 17:29:01,655: DEBUG/Worker-2] http://10.5.0.9:9001 "POST /jenkins/job/payask/buildWithParameters?Tag=v2.1.8 HTTP/1.1" 201 0
[2019-03-12 17:29:11,685: DEBUG/Worker-2] http://10.5.0.9:9001 "GET /jenkins/job/payask/9/consoleText HTTP/1.1" 200 588
[2019-03-12 17:29:11,708: INFO/MainProcess] Task 代码上线[85f6ac58-b6c3-4f5c-ab66-12cbe929097b] succeeded in 10.313425672007725s: '[payask] Project release completed.......'
[2019-03-12 17:29:47,667: INFO/MainProcess] Received task: 代码上线[2e58712b-f774-4a81-a0d1-20ed8571adba]
[2019-03-12 17:29:47,668: DEBUG/MainProcess] TaskPool: Apply <function _fast_trace_task at 0x7f56117671e0> (args:('代码上线', '2e58712b-f774-4a81-a0d1-20ed8571adba', ('20', {'status': 3, 'name': 'payask', 'version': 'v2.1.8', 'assign_to': <User: tompson>}), {}, {'task': '代码上线', 'id': '2e58712b-f774-4a81-a0d1-20ed8571adba', 'args': ('20', {'status': 3, 'name': 'payask', 'version': 'v2.1.8', 'assign_to': <User: tompson>}), 'kwargs': {}, 'retries': 0, 'eta': None, 'expires': None, 'utc': True, 'callbacks': None, 'errbacks': None, 'timelimit': (None, None), 'taskset': None, 'chord': None, 'headers': {}, 'reply_to': '8a9fc371-60ae-3b2d-8079-c64d74ad5f8f', 'correlation_id': '2e58712b-f774-4a81-a0d1-20ed8571adba', 'delivery_info': {'exchange': 'celery', 'routing_key': 'celery', 'priority': 0, 'redelivered': None}, 'hostname': 'celery@localhost.localdomain', 'is_eager': False, 'group': None}) kwargs:{})
[2019-03-12 17:29:47,672: WARNING/Worker-1] {'status': 3, 'name': 'payask', 'version': 'v2.1.8', 'assign_to': <User: tompson>}
[2019-03-12 17:29:47,686: DEBUG/Worker-1] Starting new HTTP connection (1): 10.5.0.9:9001
[2019-03-12 17:29:47,764: DEBUG/MainProcess] Task accepted: 代码上线[2e58712b-f774-4a81-a0d1-20ed8571adba] pid:21030
[2019-03-12 17:29:47,868: DEBUG/Worker-1] http://10.5.0.9:9001 "GET /jenkins/crumbIssuer/api/json HTTP/1.1" 200 133
[2019-03-12 17:29:47,899: DEBUG/Worker-1] http://10.5.0.9:9001 "GET /jenkins/job/payask/api/json?depth=0 HTTP/1.1" 200 698
[2019-03-12 17:29:47,919: DEBUG/Worker-1] http://10.5.0.9:9001 "POST /jenkins/job/payask/buildWithParameters?Tag=v2.1.8 HTTP/1.1" 201 0
[2019-03-12 17:29:57,945: DEBUG/Worker-1] http://10.5.0.9:9001 "GET /jenkins/job/payask/10/consoleText HTTP/1.1" 200 589
[2019-03-12 17:29:57,983: INFO/MainProcess] Task 代码上线[2e58712b-f774-4a81-a0d1-20ed8571adba] succeeded in 10.310694478001096s: '[payask] Project release completed.......'
[2019-03-12 19:11:11,944: WARNING/MainProcess] consumer: Connection to broker lost. Trying to re-establish the connection...
Traceback (most recent call last):
  File "/home/vagrant/python3.6env/lib/python3.6/site-packages/redis/connection.py", line 174, in _read_from_socket
    data = recv(self._sock, socket_read_size)
  File "/home/vagrant/python3.6env/lib/python3.6/site-packages/redis/_compat.py", line 79, in recv
    return sock.recv(*args, **kwargs)
ConnectionResetError: [Errno 104] Connection reset by peer

During handling of the above exception, another exception occurred:

Traceback (most recent call last):
  File "/home/vagrant/python3.6env/lib/python3.6/site-packages/redis/client.py", line 668, in execute_command
    return self.parse_response(connection, command_name, **options)
  File "/home/vagrant/python3.6env/lib/python3.6/site-packages/redis/client.py", line 680, in parse_response
    response = connection.read_response()
  File "/home/vagrant/python3.6env/lib/python3.6/site-packages/redis/connection.py", line 624, in read_response
    response = self._parser.read_response()
  File "/home/vagrant/python3.6env/lib/python3.6/site-packages/redis/connection.py", line 284, in read_response
    response = self._buffer.readline()
  File "/home/vagrant/python3.6env/lib/python3.6/site-packages/redis/connection.py", line 216, in readline
    self._read_from_socket()
  File "/home/vagrant/python3.6env/lib/python3.6/site-packages/redis/connection.py", line 191, in _read_from_socket
    (e.args,))
redis.exceptions.ConnectionError: Error while reading from socket: (104, 'Connection reset by peer')

During handling of the above exception, another exception occurred:

Traceback (most recent call last):
  File "/home/vagrant/python3.6env/lib/python3.6/site-packages/redis/connection.py", line 484, in connect
    sock = self._connect()
  File "/home/vagrant/python3.6env/lib/python3.6/site-packages/redis/connection.py", line 541, in _connect
    raise err
  File "/home/vagrant/python3.6env/lib/python3.6/site-packages/redis/connection.py", line 529, in _connect
    sock.connect(socket_address)
TimeoutError: [Errno 110] Connection timed out

During handling of the above exception, another exception occurred:

Traceback (most recent call last):
  File "/home/vagrant/python3.6env/lib/python3.6/site-packages/celery/worker/consumer.py", line 280, in start
    blueprint.start(self)
  File "/home/vagrant/python3.6env/lib/python3.6/site-packages/celery/bootsteps.py", line 123, in start
    step.start(parent)
  File "/home/vagrant/python3.6env/lib/python3.6/site-packages/celery/worker/consumer.py", line 884, in start
    c.loop(*c.loop_args())
  File "/home/vagrant/python3.6env/lib/python3.6/site-packages/celery/worker/loops.py", line 76, in asynloop
    next(loop)
  File "/home/vagrant/python3.6env/lib/python3.6/site-packages/kombu/async/hub.py", line 281, in create_loop
    poll_timeout = fire_timers(propagate=propagate) if scheduled else 1
  File "/home/vagrant/python3.6env/lib/python3.6/site-packages/kombu/async/hub.py", line 140, in fire_timers
    entry()
  File "/home/vagrant/python3.6env/lib/python3.6/site-packages/kombu/async/timer.py", line 64, in __call__
    return self.fun(*self.args, **self.kwargs)
  File "/home/vagrant/python3.6env/lib/python3.6/site-packages/kombu/async/timer.py", line 132, in _reschedules
    return fun(*args, **kwargs)
  File "/home/vagrant/python3.6env/lib/python3.6/site-packages/kombu/transport/redis.py", line 322, in maybe_restore_messages
    num=channel.unacked_restore_limit,
  File "/home/vagrant/python3.6env/lib/python3.6/site-packages/kombu/transport/redis.py", line 188, in restore_visible
    self.unacked_mutex_expire):
  File "/usr/local/python3.6/lib/python3.6/contextlib.py", line 81, in __enter__
    return next(self.gen)
  File "/home/vagrant/python3.6env/lib/python3.6/site-packages/kombu/transport/redis.py", line 112, in Mutex
    i_won = client.setnx(name, lock_id)
  File "/home/vagrant/python3.6env/lib/python3.6/site-packages/redis/client.py", line 1196, in setnx
    return self.execute_command('SETNX', name, value)
  File "/home/vagrant/python3.6env/lib/python3.6/site-packages/redis/client.py", line 673, in execute_command
    connection.send_command(*args)
  File "/home/vagrant/python3.6env/lib/python3.6/site-packages/redis/connection.py", line 610, in send_command
    self.send_packed_command(self.pack_command(*args))
  File "/home/vagrant/python3.6env/lib/python3.6/site-packages/redis/connection.py", line 585, in send_packed_command
    self.connect()
  File "/home/vagrant/python3.6env/lib/python3.6/site-packages/redis/connection.py", line 489, in connect
    raise ConnectionError(self._error_message(e))
redis.exceptions.ConnectionError: Error 110 connecting to 10.5.0.9:6300. Connection timed out.
[2019-03-12 19:15:26,664: DEBUG/MainProcess] | Consumer: Restarting event loop...
[2019-03-12 19:15:26,666: DEBUG/MainProcess] | Consumer: Restarting Control...
[2019-03-12 19:17:33,896: DEBUG/MainProcess] | Consumer: Restarting Tasks...
[2019-03-12 19:17:33,897: DEBUG/MainProcess] Canceling task consumer...
[2019-03-12 19:17:33,898: DEBUG/MainProcess] | Consumer: Restarting Heart...
[2019-03-12 19:21:48,361: DEBUG/MainProcess] | Consumer: Restarting Gossip...
[2019-03-12 19:21:48,365: ERROR/MainProcess] Error on restarting Gossip: AttributeError("'NoneType' object has no attribute 'hostname'",)
Traceback (most recent call last):
  File "/home/vagrant/python3.6env/lib/python3.6/site-packages/redis/connection.py", line 174, in _read_from_socket
    data = recv(self._sock, socket_read_size)
  File "/home/vagrant/python3.6env/lib/python3.6/site-packages/redis/_compat.py", line 79, in recv
    return sock.recv(*args, **kwargs)
ConnectionResetError: [Errno 104] Connection reset by peer

During handling of the above exception, another exception occurred:

Traceback (most recent call last):
  File "/home/vagrant/python3.6env/lib/python3.6/site-packages/redis/client.py", line 668, in execute_command
    return self.parse_response(connection, command_name, **options)
  File "/home/vagrant/python3.6env/lib/python3.6/site-packages/redis/client.py", line 680, in parse_response
    response = connection.read_response()
  File "/home/vagrant/python3.6env/lib/python3.6/site-packages/redis/connection.py", line 624, in read_response
    response = self._parser.read_response()
  File "/home/vagrant/python3.6env/lib/python3.6/site-packages/redis/connection.py", line 284, in read_response
    response = self._buffer.readline()
  File "/home/vagrant/python3.6env/lib/python3.6/site-packages/redis/connection.py", line 216, in readline
    self._read_from_socket()
  File "/home/vagrant/python3.6env/lib/python3.6/site-packages/redis/connection.py", line 191, in _read_from_socket
    (e.args,))
redis.exceptions.ConnectionError: Error while reading from socket: (104, 'Connection reset by peer')

During handling of the above exception, another exception occurred:

Traceback (most recent call last):
  File "/home/vagrant/python3.6env/lib/python3.6/site-packages/redis/connection.py", line 484, in connect
    sock = self._connect()
  File "/home/vagrant/python3.6env/lib/python3.6/site-packages/redis/connection.py", line 541, in _connect
    raise err
  File "/home/vagrant/python3.6env/lib/python3.6/site-packages/redis/connection.py", line 529, in _connect
    sock.connect(socket_address)
TimeoutError: [Errno 110] Connection timed out

During handling of the above exception, another exception occurred:

Traceback (most recent call last):
  File "/home/vagrant/python3.6env/lib/python3.6/site-packages/celery/worker/consumer.py", line 280, in start
    blueprint.start(self)
  File "/home/vagrant/python3.6env/lib/python3.6/site-packages/celery/bootsteps.py", line 123, in start
    step.start(parent)
  File "/home/vagrant/python3.6env/lib/python3.6/site-packages/celery/worker/consumer.py", line 884, in start
    c.loop(*c.loop_args())
  File "/home/vagrant/python3.6env/lib/python3.6/site-packages/celery/worker/loops.py", line 76, in asynloop
    next(loop)
  File "/home/vagrant/python3.6env/lib/python3.6/site-packages/kombu/async/hub.py", line 281, in create_loop
    poll_timeout = fire_timers(propagate=propagate) if scheduled else 1
  File "/home/vagrant/python3.6env/lib/python3.6/site-packages/kombu/async/hub.py", line 140, in fire_timers
    entry()
  File "/home/vagrant/python3.6env/lib/python3.6/site-packages/kombu/async/timer.py", line 64, in __call__
    return self.fun(*self.args, **self.kwargs)
  File "/home/vagrant/python3.6env/lib/python3.6/site-packages/kombu/async/timer.py", line 132, in _reschedules
    return fun(*args, **kwargs)
  File "/home/vagrant/python3.6env/lib/python3.6/site-packages/kombu/transport/redis.py", line 322, in maybe_restore_messages
    num=channel.unacked_restore_limit,
  File "/home/vagrant/python3.6env/lib/python3.6/site-packages/kombu/transport/redis.py", line 188, in restore_visible
    self.unacked_mutex_expire):
  File "/usr/local/python3.6/lib/python3.6/contextlib.py", line 81, in __enter__
    return next(self.gen)
  File "/home/vagrant/python3.6env/lib/python3.6/site-packages/kombu/transport/redis.py", line 112, in Mutex
    i_won = client.setnx(name, lock_id)
  File "/home/vagrant/python3.6env/lib/python3.6/site-packages/redis/client.py", line 1196, in setnx
    return self.execute_command('SETNX', name, value)
  File "/home/vagrant/python3.6env/lib/python3.6/site-packages/redis/client.py", line 673, in execute_command
    connection.send_command(*args)
  File "/home/vagrant/python3.6env/lib/python3.6/site-packages/redis/connection.py", line 610, in send_command
    self.send_packed_command(self.pack_command(*args))
  File "/home/vagrant/python3.6env/lib/python3.6/site-packages/redis/connection.py", line 585, in send_packed_command
    self.connect()
  File "/home/vagrant/python3.6env/lib/python3.6/site-packages/redis/connection.py", line 489, in connect
    raise ConnectionError(self._error_message(e))
redis.exceptions.ConnectionError: Error 110 connecting to 10.5.0.9:6300. Connection timed out.

During handling of the above exception, another exception occurred:

Traceback (most recent call last):
  File "/home/vagrant/python3.6env/lib/python3.6/site-packages/celery/bootsteps.py", line 155, in send_all
    fun(parent, *args)
  File "/home/vagrant/python3.6env/lib/python3.6/site-packages/celery/bootsteps.py", line 409, in stop
    self._close(c, True)
  File "/home/vagrant/python3.6env/lib/python3.6/site-packages/celery/bootsteps.py", line 422, in _close
    ignore_errors(c.connection, channel.close)
  File "/home/vagrant/python3.6env/lib/python3.6/site-packages/kombu/common.py", line 289, in ignore_errors
    return fun(*args, **kwargs)
  File "/home/vagrant/python3.6env/lib/python3.6/site-packages/kombu/transport/redis.py", line 782, in close
    self.queue_delete(queue)
  File "/home/vagrant/python3.6env/lib/python3.6/site-packages/kombu/transport/virtual/__init__.py", line 460, in queue_delete
    self._delete(queue, exchange, *meta)
  File "/home/vagrant/python3.6env/lib/python3.6/site-packages/kombu/transport/redis.py", line 738, in _delete
    with self.conn_or_acquire() as client:
  File "/usr/local/python3.6/lib/python3.6/contextlib.py", line 81, in __enter__
    return next(self.gen)
  File "/home/vagrant/python3.6env/lib/python3.6/site-packages/kombu/transport/redis.py", line 903, in conn_or_acquire
    yield self._create_client()
  File "/home/vagrant/python3.6env/lib/python3.6/site-packages/kombu/transport/redis.py", line 874, in _create_client
    return self.Client(connection_pool=self.pool)
  File "/home/vagrant/python3.6env/lib/python3.6/site-packages/kombu/transport/redis.py", line 908, in pool
    self._pool = self._get_pool()
  File "/home/vagrant/python3.6env/lib/python3.6/site-packages/kombu/transport/redis.py", line 877, in _get_pool
    params = self._connparams(async=async)
  File "/home/vagrant/python3.6env/lib/python3.6/site-packages/kombu/transport/redis.py", line 820, in _connparams
    'host': conninfo.hostname or '127.0.0.1',
AttributeError: 'NoneType' object has no attribute 'hostname'
[2019-03-12 19:21:48,376: DEBUG/MainProcess] | Consumer: Restarting Mingle...
[2019-03-12 19:21:48,378: DEBUG/MainProcess] | Consumer: Restarting Events...
[2019-03-12 19:21:48,380: DEBUG/MainProcess] | Consumer: Restarting Connection...
[2019-03-12 19:21:48,382: DEBUG/MainProcess] | Consumer: Starting Connection
[2019-03-12 19:23:55,722: ERROR/MainProcess] consumer: Cannot connect to redis://:**@10.5.0.9:6300/0: .
Trying again in 2.00 seconds...

[2019-03-12 19:26:05,001: ERROR/MainProcess] consumer: Cannot connect to redis://:**@10.5.0.9:6300/0: .
Trying again in 4.00 seconds...

[2019-03-12 19:28:16,201: ERROR/MainProcess] consumer: Cannot connect to redis://:**@10.5.0.9:6300/0: .
Trying again in 6.00 seconds...

[2019-03-12 19:30:29,448: ERROR/MainProcess] consumer: Cannot connect to redis://:**@10.5.0.9:6300/0: .
Trying again in 8.00 seconds...

[2019-03-12 19:32:44,744: ERROR/MainProcess] consumer: Cannot connect to redis://:**@10.5.0.9:6300/0: .
Trying again in 10.00 seconds...

[2019-03-12 19:35:01,962: ERROR/MainProcess] consumer: Cannot connect to redis://:**@10.5.0.9:6300/0: .
Trying again in 12.00 seconds...

[2019-03-12 19:37:21,224: ERROR/MainProcess] consumer: Cannot connect to redis://:**@10.5.0.9:6300/0: .
Trying again in 14.00 seconds...

[2019-03-12 19:39:42,538: ERROR/MainProcess] consumer: Cannot connect to redis://:**@10.5.0.9:6300/0: .
Trying again in 16.00 seconds...

[2019-03-12 19:42:06,154: ERROR/MainProcess] consumer: Cannot connect to redis://:**@10.5.0.9:6300/0: .
Trying again in 18.00 seconds...

[2019-03-12 19:44:31,434: ERROR/MainProcess] consumer: Cannot connect to redis://:**@10.5.0.9:6300/0: .
Trying again in 20.00 seconds...

[2019-03-12 19:46:59,016: ERROR/MainProcess] consumer: Cannot connect to redis://:**@10.5.0.9:6300/0: .
Trying again in 22.00 seconds...

[2019-03-12 19:49:28,265: ERROR/MainProcess] consumer: Cannot connect to redis://:**@10.5.0.9:6300/0: .
Trying again in 24.00 seconds...

[2019-03-12 19:52:00,075: ERROR/MainProcess] consumer: Cannot connect to redis://:**@10.5.0.9:6300/0: .
Trying again in 26.00 seconds...

[2019-03-12 19:54:33,417: ERROR/MainProcess] consumer: Cannot connect to redis://:**@10.5.0.9:6300/0: .
Trying again in 28.00 seconds...

[2019-03-12 19:57:08,808: ERROR/MainProcess] consumer: Cannot connect to redis://:**@10.5.0.9:6300/0: .
Trying again in 30.00 seconds...

[2019-03-12 19:59:46,121: ERROR/MainProcess] consumer: Cannot connect to redis://:**@10.5.0.9:6300/0: .
Trying again in 32.00 seconds...

[2019-03-12 20:02:25,481: ERROR/MainProcess] consumer: Cannot connect to redis://:**@10.5.0.9:6300/0: .
Trying again in 32.00 seconds...

[2019-03-12 20:05:04,809: ERROR/MainProcess] consumer: Cannot connect to redis://:**@10.5.0.9:6300/0: .
Trying again in 32.00 seconds...

[2019-03-12 20:07:44,201: ERROR/MainProcess] consumer: Cannot connect to redis://:**@10.5.0.9:6300/0: .
Trying again in 32.00 seconds...

[2019-03-12 20:10:23,561: ERROR/MainProcess] consumer: Cannot connect to redis://:**@10.5.0.9:6300/0: .
Trying again in 32.00 seconds...

[2019-03-12 20:13:02,935: ERROR/MainProcess] consumer: Cannot connect to redis://:**@10.5.0.9:6300/0: .
Trying again in 32.00 seconds...

[2019-03-12 20:15:42,353: ERROR/MainProcess] consumer: Cannot connect to redis://:**@10.5.0.9:6300/0: .
Trying again in 32.00 seconds...

[2019-03-12 20:18:22,152: ERROR/MainProcess] consumer: Cannot connect to redis://:**@10.5.0.9:6300/0: .
Trying again in 32.00 seconds...

[2019-03-12 20:21:01,384: ERROR/MainProcess] consumer: Cannot connect to redis://:**@10.5.0.9:6300/0: .
Trying again in 32.00 seconds...

[2019-03-12 20:23:40,749: ERROR/MainProcess] consumer: Cannot connect to redis://:**@10.5.0.9:6300/0: .
Trying again in 32.00 seconds...

[2019-03-12 20:26:20,104: ERROR/MainProcess] consumer: Cannot connect to redis://:**@10.5.0.9:6300/0: .
Trying again in 32.00 seconds...

[2019-03-12 20:28:59,721: ERROR/MainProcess] consumer: Cannot connect to redis://:**@10.5.0.9:6300/0: .
Trying again in 32.00 seconds...

[2019-03-12 20:31:39,081: ERROR/MainProcess] consumer: Cannot connect to redis://:**@10.5.0.9:6300/0: .
Trying again in 32.00 seconds...

[2019-03-12 20:34:18,569: ERROR/MainProcess] consumer: Cannot connect to redis://:**@10.5.0.9:6300/0: .
Trying again in 32.00 seconds...

[2019-03-12 20:36:58,374: ERROR/MainProcess] consumer: Cannot connect to redis://:**@10.5.0.9:6300/0: .
Trying again in 32.00 seconds...

[2019-03-12 20:39:37,673: ERROR/MainProcess] consumer: Cannot connect to redis://:**@10.5.0.9:6300/0: .
Trying again in 32.00 seconds...

[2019-03-12 20:42:17,290: ERROR/MainProcess] consumer: Cannot connect to redis://:**@10.5.0.9:6300/0: .
Trying again in 32.00 seconds...

[2019-03-12 20:44:56,521: ERROR/MainProcess] consumer: Cannot connect to redis://:**@10.5.0.9:6300/0: .
Trying again in 32.00 seconds...

[2019-03-12 20:47:36,008: ERROR/MainProcess] consumer: Cannot connect to redis://:**@10.5.0.9:6300/0: .
Trying again in 32.00 seconds...

[2019-03-12 20:50:15,753: ERROR/MainProcess] consumer: Cannot connect to redis://:**@10.5.0.9:6300/0: .
Trying again in 32.00 seconds...

[2019-03-12 20:52:55,241: ERROR/MainProcess] consumer: Cannot connect to redis://:**@10.5.0.9:6300/0: .
Trying again in 32.00 seconds...

[2019-03-12 20:55:34,987: ERROR/MainProcess] consumer: Cannot connect to redis://:**@10.5.0.9:6300/0: .
Trying again in 32.00 seconds...

[2019-03-12 20:58:14,218: ERROR/MainProcess] consumer: Cannot connect to redis://:**@10.5.0.9:6300/0: .
Trying again in 32.00 seconds...

[2019-03-12 21:00:53,577: ERROR/MainProcess] consumer: Cannot connect to redis://:**@10.5.0.9:6300/0: .
Trying again in 32.00 seconds...

[2019-03-12 21:03:33,192: ERROR/MainProcess] consumer: Cannot connect to redis://:**@10.5.0.9:6300/0: .
Trying again in 32.00 seconds...

[2019-03-12 21:06:12,425: ERROR/MainProcess] consumer: Cannot connect to redis://:**@10.5.0.9:6300/0: .
Trying again in 32.00 seconds...

[2019-03-12 21:08:52,168: ERROR/MainProcess] consumer: Cannot connect to redis://:**@10.5.0.9:6300/0: .
Trying again in 32.00 seconds...

[2019-03-12 21:11:31,912: ERROR/MainProcess] consumer: Cannot connect to redis://:**@10.5.0.9:6300/0: .
Trying again in 32.00 seconds...

[2019-03-12 21:14:11,144: ERROR/MainProcess] consumer: Cannot connect to redis://:**@10.5.0.9:6300/0: .
Trying again in 32.00 seconds...

[2019-03-12 21:16:50,504: ERROR/MainProcess] consumer: Cannot connect to redis://:**@10.5.0.9:6300/0: .
Trying again in 32.00 seconds...

[2019-03-12 21:19:29,866: ERROR/MainProcess] consumer: Cannot connect to redis://:**@10.5.0.9:6300/0: .
Trying again in 32.00 seconds...

[2019-03-12 21:22:09,226: ERROR/MainProcess] consumer: Cannot connect to redis://:**@10.5.0.9:6300/0: .
Trying again in 32.00 seconds...

[2019-03-12 21:24:48,585: ERROR/MainProcess] consumer: Cannot connect to redis://:**@10.5.0.9:6300/0: .
Trying again in 32.00 seconds...

[2019-03-12 21:27:28,329: ERROR/MainProcess] consumer: Cannot connect to redis://:**@10.5.0.9:6300/0: .
Trying again in 32.00 seconds...

[2019-03-12 21:30:07,945: ERROR/MainProcess] consumer: Cannot connect to redis://:**@10.5.0.9:6300/0: .
Trying again in 32.00 seconds...

[2019-03-12 21:32:47,323: ERROR/MainProcess] consumer: Cannot connect to redis://:**@10.5.0.9:6300/0: .
Trying again in 32.00 seconds...

[2019-03-12 21:35:27,176: ERROR/MainProcess] consumer: Cannot connect to redis://:**@10.5.0.9:6300/0: .
Trying again in 32.00 seconds...

[2019-03-12 21:38:06,665: ERROR/MainProcess] consumer: Cannot connect to redis://:**@10.5.0.9:6300/0: .
Trying again in 32.00 seconds...

[2019-03-12 21:40:46,026: ERROR/MainProcess] consumer: Cannot connect to redis://:**@10.5.0.9:6300/0: .
Trying again in 32.00 seconds...

[2019-03-12 21:43:25,521: ERROR/MainProcess] consumer: Cannot connect to redis://:**@10.5.0.9:6300/0: .
Trying again in 32.00 seconds...

[2019-03-12 21:46:04,874: ERROR/MainProcess] consumer: Cannot connect to redis://:**@10.5.0.9:6300/0: .
Trying again in 32.00 seconds...

[2019-03-12 21:48:44,233: ERROR/MainProcess] consumer: Cannot connect to redis://:**@10.5.0.9:6300/0: .
Trying again in 32.00 seconds...

[2019-03-12 21:51:23,933: ERROR/MainProcess] consumer: Cannot connect to redis://:**@10.5.0.9:6300/0: .
Trying again in 32.00 seconds...

[2019-03-12 21:54:03,721: ERROR/MainProcess] consumer: Cannot connect to redis://:**@10.5.0.9:6300/0: .
Trying again in 32.00 seconds...

[2019-03-12 21:56:43,337: ERROR/MainProcess] consumer: Cannot connect to redis://:**@10.5.0.9:6300/0: .
Trying again in 32.00 seconds...

[2019-03-12 21:59:22,954: ERROR/MainProcess] consumer: Cannot connect to redis://:**@10.5.0.9:6300/0: .
Trying again in 32.00 seconds...

[2019-03-12 22:02:02,546: ERROR/MainProcess] consumer: Cannot connect to redis://:**@10.5.0.9:6300/0: .
Trying again in 32.00 seconds...

[2019-03-12 22:04:41,929: ERROR/MainProcess] consumer: Cannot connect to redis://:**@10.5.0.9:6300/0: .
Trying again in 32.00 seconds...

[2019-03-12 22:07:21,288: ERROR/MainProcess] consumer: Cannot connect to redis://:**@10.5.0.9:6300/0: .
Trying again in 32.00 seconds...

[2019-03-12 22:10:00,649: ERROR/MainProcess] consumer: Cannot connect to redis://:**@10.5.0.9:6300/0: .
Trying again in 32.00 seconds...

[2019-03-12 22:12:40,009: ERROR/MainProcess] consumer: Cannot connect to redis://:**@10.5.0.9:6300/0: .
Trying again in 32.00 seconds...

[2019-03-12 22:15:19,626: ERROR/MainProcess] consumer: Cannot connect to redis://:**@10.5.0.9:6300/0: .
Trying again in 32.00 seconds...

[2019-03-12 22:17:58,856: ERROR/MainProcess] consumer: Cannot connect to redis://:**@10.5.0.9:6300/0: .
Trying again in 32.00 seconds...

[2019-03-12 22:20:38,346: ERROR/MainProcess] consumer: Cannot connect to redis://:**@10.5.0.9:6300/0: .
Trying again in 32.00 seconds...

[2019-03-12 22:23:17,704: ERROR/MainProcess] consumer: Cannot connect to redis://:**@10.5.0.9:6300/0: .
Trying again in 32.00 seconds...

[2019-03-12 22:25:57,065: ERROR/MainProcess] consumer: Cannot connect to redis://:**@10.5.0.9:6300/0: .
Trying again in 32.00 seconds...

[2019-03-12 22:28:36,424: ERROR/MainProcess] consumer: Cannot connect to redis://:**@10.5.0.9:6300/0: .
Trying again in 32.00 seconds...

[2019-03-12 22:31:15,914: ERROR/MainProcess] consumer: Cannot connect to redis://:**@10.5.0.9:6300/0: .
Trying again in 32.00 seconds...

[2019-03-12 22:33:55,529: ERROR/MainProcess] consumer: Cannot connect to redis://:**@10.5.0.9:6300/0: .
Trying again in 32.00 seconds...

[2019-03-12 22:36:35,274: ERROR/MainProcess] consumer: Cannot connect to redis://:**@10.5.0.9:6300/0: .
Trying again in 32.00 seconds...

[2019-03-12 22:39:15,029: ERROR/MainProcess] consumer: Cannot connect to redis://:**@10.5.0.9:6300/0: .
Trying again in 32.00 seconds...

[2019-03-12 22:41:54,378: ERROR/MainProcess] consumer: Cannot connect to redis://:**@10.5.0.9:6300/0: .
Trying again in 32.00 seconds...

[2019-03-12 22:44:34,249: ERROR/MainProcess] consumer: Cannot connect to redis://:**@10.5.0.9:6300/0: .
Trying again in 32.00 seconds...

[2019-03-12 22:47:14,002: ERROR/MainProcess] consumer: Cannot connect to redis://:**@10.5.0.9:6300/0: .
Trying again in 32.00 seconds...

[2019-03-12 22:49:53,352: ERROR/MainProcess] consumer: Cannot connect to redis://:**@10.5.0.9:6300/0: .
Trying again in 32.00 seconds...

[2019-03-12 22:52:32,969: ERROR/MainProcess] consumer: Cannot connect to redis://:**@10.5.0.9:6300/0: .
Trying again in 32.00 seconds...

[2019-03-12 22:55:12,329: ERROR/MainProcess] consumer: Cannot connect to redis://:**@10.5.0.9:6300/0: .
Trying again in 32.00 seconds...

[2019-03-12 22:57:51,688: ERROR/MainProcess] consumer: Cannot connect to redis://:**@10.5.0.9:6300/0: .
Trying again in 32.00 seconds...

[2019-03-12 23:00:30,921: ERROR/MainProcess] consumer: Cannot connect to redis://:**@10.5.0.9:6300/0: .
Trying again in 32.00 seconds...

[2019-03-12 23:03:10,152: ERROR/MainProcess] consumer: Cannot connect to redis://:**@10.5.0.9:6300/0: .
Trying again in 32.00 seconds...

[2019-03-12 23:05:49,384: ERROR/MainProcess] consumer: Cannot connect to redis://:**@10.5.0.9:6300/0: .
Trying again in 32.00 seconds...

[2019-03-12 23:08:28,618: ERROR/MainProcess] consumer: Cannot connect to redis://:**@10.5.0.9:6300/0: .
Trying again in 32.00 seconds...

[2019-03-12 23:11:08,233: ERROR/MainProcess] consumer: Cannot connect to redis://:**@10.5.0.9:6300/0: .
Trying again in 32.00 seconds...

[2019-03-12 23:13:47,593: ERROR/MainProcess] consumer: Cannot connect to redis://:**@10.5.0.9:6300/0: .
Trying again in 32.00 seconds...

[2019-03-12 23:16:26,956: ERROR/MainProcess] consumer: Cannot connect to redis://:**@10.5.0.9:6300/0: .
Trying again in 32.00 seconds...

[2019-03-12 23:19:06,825: ERROR/MainProcess] consumer: Cannot connect to redis://:**@10.5.0.9:6300/0: .
Trying again in 32.00 seconds...

[2019-03-12 23:21:46,058: ERROR/MainProcess] consumer: Cannot connect to redis://:**@10.5.0.9:6300/0: .
Trying again in 32.00 seconds...

[2019-03-12 23:24:25,419: ERROR/MainProcess] consumer: Cannot connect to redis://:**@10.5.0.9:6300/0: .
Trying again in 32.00 seconds...

[2019-03-12 23:27:04,776: ERROR/MainProcess] consumer: Cannot connect to redis://:**@10.5.0.9:6300/0: .
Trying again in 32.00 seconds...

[2019-03-12 23:29:44,267: ERROR/MainProcess] consumer: Cannot connect to redis://:**@10.5.0.9:6300/0: .
Trying again in 32.00 seconds...

[2019-03-12 23:32:24,136: ERROR/MainProcess] consumer: Cannot connect to redis://:**@10.5.0.9:6300/0: .
Trying again in 32.00 seconds...

[2019-03-12 23:35:03,938: ERROR/MainProcess] consumer: Cannot connect to redis://:**@10.5.0.9:6300/0: .
Trying again in 32.00 seconds...

[2019-03-12 23:37:43,240: ERROR/MainProcess] consumer: Cannot connect to redis://:**@10.5.0.9:6300/0: .
Trying again in 32.00 seconds...

[2019-03-12 23:40:22,730: ERROR/MainProcess] consumer: Cannot connect to redis://:**@10.5.0.9:6300/0: .
Trying again in 32.00 seconds...

[2019-03-12 23:43:02,088: ERROR/MainProcess] consumer: Cannot connect to redis://:**@10.5.0.9:6300/0: .
Trying again in 32.00 seconds...

[2019-03-12 23:45:41,450: WARNING/MainProcess] consumer: Connection to broker lost. Trying to re-establish the connection...
Traceback (most recent call last):
  File "/home/vagrant/python3.6env/lib/python3.6/site-packages/kombu/transport/virtual/__init__.py", line 789, in create_channel
    return self._avail_channels.pop()
IndexError: pop from empty list

During handling of the above exception, another exception occurred:

Traceback (most recent call last):
  File "/home/vagrant/python3.6env/lib/python3.6/site-packages/redis/connection.py", line 484, in connect
    sock = self._connect()
  File "/home/vagrant/python3.6env/lib/python3.6/site-packages/redis/connection.py", line 541, in _connect
    raise err
  File "/home/vagrant/python3.6env/lib/python3.6/site-packages/redis/connection.py", line 529, in _connect
    sock.connect(socket_address)
TimeoutError: [Errno 110] Connection timed out

During handling of the above exception, another exception occurred:

Traceback (most recent call last):
  File "/home/vagrant/python3.6env/lib/python3.6/site-packages/redis/client.py", line 667, in execute_command
    connection.send_command(*args)
  File "/home/vagrant/python3.6env/lib/python3.6/site-packages/redis/connection.py", line 610, in send_command
    self.send_packed_command(self.pack_command(*args))
  File "/home/vagrant/python3.6env/lib/python3.6/site-packages/redis/connection.py", line 585, in send_packed_command
    self.connect()
  File "/home/vagrant/python3.6env/lib/python3.6/site-packages/redis/connection.py", line 489, in connect
    raise ConnectionError(self._error_message(e))
redis.exceptions.ConnectionError: Error 110 connecting to 10.5.0.9:6300. Connection timed out.

During handling of the above exception, another exception occurred:

Traceback (most recent call last):
  File "/home/vagrant/python3.6env/lib/python3.6/site-packages/kombu/transport/redis.py", line 464, in __init__
    self.client.info()
  File "/home/vagrant/python3.6env/lib/python3.6/site-packages/redis/client.py", line 760, in info
    return self.execute_command('INFO')
  File "/home/vagrant/python3.6env/lib/python3.6/site-packages/redis/client.py", line 670, in execute_command
    connection.disconnect()
  File "/home/vagrant/python3.6env/lib/python3.6/site-packages/kombu/transport/redis.py", line 866, in disconnect
    channel._on_connection_disconnect(self)
  File "/home/vagrant/python3.6env/lib/python3.6/site-packages/kombu/transport/redis.py", line 496, in _on_connection_disconnect
    self._disconnect_pools()
  File "/home/vagrant/python3.6env/lib/python3.6/site-packages/kombu/transport/redis.py", line 484, in _disconnect_pools
    self._async_pool.disconnect()
  File "/home/vagrant/python3.6env/lib/python3.6/site-packages/redis/connection.py", line 998, in disconnect
    connection.disconnect()
  File "/home/vagrant/python3.6env/lib/python3.6/site-packages/kombu/transport/redis.py", line 866, in disconnect
    channel._on_connection_disconnect(self)
  File "/home/vagrant/python3.6env/lib/python3.6/site-packages/kombu/transport/redis.py", line 498, in _on_connection_disconnect
    raise get_redis_ConnectionError()
redis.exceptions.ConnectionError

During handling of the above exception, another exception occurred:

Traceback (most recent call last):
  File "/home/vagrant/python3.6env/lib/python3.6/site-packages/celery/worker/consumer.py", line 280, in start
    blueprint.start(self)
  File "/home/vagrant/python3.6env/lib/python3.6/site-packages/celery/bootsteps.py", line 123, in start
    step.start(parent)
  File "/home/vagrant/python3.6env/lib/python3.6/site-packages/celery/worker/consumer.py", line 525, in start
    c.connection = c.connect()
  File "/home/vagrant/python3.6env/lib/python3.6/site-packages/celery/worker/consumer.py", line 377, in connect
    callback=maybe_shutdown,
  File "/home/vagrant/python3.6env/lib/python3.6/site-packages/kombu/connection.py", line 382, in ensure_connection
    interval_start, interval_step, interval_max, callback)
  File "/home/vagrant/python3.6env/lib/python3.6/site-packages/kombu/utils/__init__.py", line 246, in retry_over_time
    return fun(*args, **kwargs)
  File "/home/vagrant/python3.6env/lib/python3.6/site-packages/kombu/connection.py", line 250, in connect
    return self.connection
  File "/home/vagrant/python3.6env/lib/python3.6/site-packages/kombu/connection.py", line 756, in connection
    self._connection = self._establish_connection()
  File "/home/vagrant/python3.6env/lib/python3.6/site-packages/kombu/connection.py", line 711, in _establish_connection
    conn = self.transport.establish_connection()
  File "/home/vagrant/python3.6env/lib/python3.6/site-packages/kombu/transport/virtual/__init__.py", line 809, in establish_connection
    self._avail_channels.append(self.create_channel(self))
  File "/home/vagrant/python3.6env/lib/python3.6/site-packages/kombu/transport/virtual/__init__.py", line 791, in create_channel
    channel = self.Channel(connection)
  File "/home/vagrant/python3.6env/lib/python3.6/site-packages/kombu/transport/redis.py", line 466, in __init__
    self._disconnect_pools()
  File "/home/vagrant/python3.6env/lib/python3.6/site-packages/kombu/transport/redis.py", line 484, in _disconnect_pools
    self._async_pool.disconnect()
  File "/home/vagrant/python3.6env/lib/python3.6/site-packages/redis/connection.py", line 998, in disconnect
    connection.disconnect()
  File "/home/vagrant/python3.6env/lib/python3.6/site-packages/kombu/transport/redis.py", line 866, in disconnect
    channel._on_connection_disconnect(self)
  File "/home/vagrant/python3.6env/lib/python3.6/site-packages/kombu/transport/redis.py", line 498, in _on_connection_disconnect
    raise get_redis_ConnectionError()
redis.exceptions.ConnectionError
[2019-03-12 23:45:41,457: DEBUG/MainProcess] | Consumer: Restarting event loop...
[2019-03-12 23:45:41,458: DEBUG/MainProcess] | Consumer: Restarting Control...
[2019-03-12 23:45:41,460: DEBUG/MainProcess] | Consumer: Restarting Tasks...
[2019-03-12 23:45:41,461: DEBUG/MainProcess] Canceling task consumer...
[2019-03-12 23:45:41,462: DEBUG/MainProcess] | Consumer: Restarting Heart...
[2019-03-12 23:45:41,463: DEBUG/MainProcess] | Consumer: Restarting Gossip...
[2019-03-12 23:45:41,464: DEBUG/MainProcess] | Consumer: Restarting Mingle...
[2019-03-12 23:45:41,465: DEBUG/MainProcess] | Consumer: Restarting Events...
[2019-03-12 23:45:41,466: DEBUG/MainProcess] | Consumer: Restarting Connection...
[2019-03-12 23:45:41,467: DEBUG/MainProcess] | Consumer: Starting Connection
[2019-03-12 23:47:48,809: ERROR/MainProcess] consumer: Cannot connect to redis://:**@10.5.0.9:6300/0: .
Trying again in 2.00 seconds...

[2019-03-12 23:49:58,089: ERROR/MainProcess] consumer: Cannot connect to redis://:**@10.5.0.9:6300/0: .
Trying again in 4.00 seconds...

[2019-03-12 23:52:09,288: ERROR/MainProcess] consumer: Cannot connect to redis://:**@10.5.0.9:6300/0: .
Trying again in 6.00 seconds...

[2019-03-12 23:54:22,545: ERROR/MainProcess] consumer: Cannot connect to redis://:**@10.5.0.9:6300/0: .
Trying again in 8.00 seconds...

[2019-03-12 23:56:37,834: ERROR/MainProcess] consumer: Cannot connect to redis://:**@10.5.0.9:6300/0: .
Trying again in 10.00 seconds...

[2019-03-12 23:58:55,049: ERROR/MainProcess] consumer: Cannot connect to redis://:**@10.5.0.9:6300/0: .
Trying again in 12.00 seconds...

[2019-03-13 00:01:14,313: ERROR/MainProcess] consumer: Cannot connect to redis://:**@10.5.0.9:6300/0: .
Trying again in 14.00 seconds...

[2019-03-13 00:03:35,625: ERROR/MainProcess] consumer: Cannot connect to redis://:**@10.5.0.9:6300/0: .
Trying again in 16.00 seconds...

[2019-03-13 00:05:58,985: ERROR/MainProcess] consumer: Cannot connect to redis://:**@10.5.0.9:6300/0: .
Trying again in 18.00 seconds...

[2019-03-13 00:08:24,264: ERROR/MainProcess] consumer: Cannot connect to redis://:**@10.5.0.9:6300/0: .
Trying again in 20.00 seconds...

[2019-03-13 00:10:51,594: ERROR/MainProcess] consumer: Cannot connect to redis://:**@10.5.0.9:6300/0: .
Trying again in 22.00 seconds...

[2019-03-13 00:13:21,353: ERROR/MainProcess] consumer: Cannot connect to redis://:**@10.5.0.9:6300/0: .
Trying again in 24.00 seconds...

[2019-03-13 00:15:52,930: ERROR/MainProcess] consumer: Cannot connect to redis://:**@10.5.0.9:6300/0: .
Trying again in 26.00 seconds...

[2019-03-13 00:18:26,561: ERROR/MainProcess] consumer: Cannot connect to redis://:**@10.5.0.9:6300/0: .
Trying again in 28.00 seconds...

[2019-03-13 00:21:01,896: ERROR/MainProcess] consumer: Cannot connect to redis://:**@10.5.0.9:6300/0: .
Trying again in 30.00 seconds...

[2019-03-13 00:23:39,336: ERROR/MainProcess] consumer: Cannot connect to redis://:**@10.5.0.9:6300/0: .
Trying again in 32.00 seconds...

[2019-03-13 00:26:18,825: ERROR/MainProcess] consumer: Cannot connect to redis://:**@10.5.0.9:6300/0: .
Trying again in 32.00 seconds...

[2019-03-13 00:28:58,186: ERROR/MainProcess] consumer: Cannot connect to redis://:**@10.5.0.9:6300/0: .
Trying again in 32.00 seconds...

[2019-03-13 00:31:37,545: ERROR/MainProcess] consumer: Cannot connect to redis://:**@10.5.0.9:6300/0: .
Trying again in 32.00 seconds...

[2019-03-13 00:34:16,905: ERROR/MainProcess] consumer: Cannot connect to redis://:**@10.5.0.9:6300/0: .
Trying again in 32.00 seconds...

[2019-03-13 00:36:56,265: ERROR/MainProcess] consumer: Cannot connect to redis://:**@10.5.0.9:6300/0: .
Trying again in 32.00 seconds...

[2019-03-13 00:39:35,755: ERROR/MainProcess] consumer: Cannot connect to redis://:**@10.5.0.9:6300/0: .
Trying again in 32.00 seconds...

[2019-03-13 00:42:15,243: ERROR/MainProcess] consumer: Cannot connect to redis://:**@10.5.0.9:6300/0: .
Trying again in 32.00 seconds...

[2019-03-13 00:44:54,732: ERROR/MainProcess] consumer: Cannot connect to redis://:**@10.5.0.9:6300/0: .
Trying again in 32.00 seconds...

[2019-03-13 00:47:34,091: ERROR/MainProcess] consumer: Cannot connect to redis://:**@10.5.0.9:6300/0: .
Trying again in 32.00 seconds...

[2019-03-13 00:50:13,449: ERROR/MainProcess] consumer: Cannot connect to redis://:**@10.5.0.9:6300/0: .
Trying again in 32.00 seconds...

[2019-03-13 00:52:52,809: ERROR/MainProcess] consumer: Cannot connect to redis://:**@10.5.0.9:6300/0: .
Trying again in 32.00 seconds...

[2019-03-13 00:55:32,169: ERROR/MainProcess] consumer: Cannot connect to redis://:**@10.5.0.9:6300/0: .
Trying again in 32.00 seconds...

[2019-03-13 00:58:11,848: ERROR/MainProcess] consumer: Cannot connect to redis://:**@10.5.0.9:6300/0: .
Trying again in 32.00 seconds...

[2019-03-13 01:00:51,147: ERROR/MainProcess] consumer: Cannot connect to redis://:**@10.5.0.9:6300/0: .
Trying again in 32.00 seconds...

[2019-03-13 01:03:30,505: ERROR/MainProcess] consumer: Cannot connect to redis://:**@10.5.0.9:6300/0: .
Trying again in 32.00 seconds...

[2019-03-13 01:06:09,994: ERROR/MainProcess] consumer: Cannot connect to redis://:**@10.5.0.9:6300/0: .
Trying again in 32.00 seconds...

[2019-03-13 01:08:49,352: ERROR/MainProcess] consumer: Cannot connect to redis://:**@10.5.0.9:6300/0: .
Trying again in 32.00 seconds...

[2019-03-13 01:11:28,840: ERROR/MainProcess] consumer: Cannot connect to redis://:**@10.5.0.9:6300/0: .
Trying again in 32.00 seconds...

[2019-03-13 01:14:08,456: ERROR/MainProcess] consumer: Cannot connect to redis://:**@10.5.0.9:6300/0: .
Trying again in 32.00 seconds...

[2019-03-13 01:16:48,076: ERROR/MainProcess] consumer: Cannot connect to redis://:**@10.5.0.9:6300/0: .
Trying again in 32.00 seconds...

[2019-03-13 01:19:27,305: ERROR/MainProcess] consumer: Cannot connect to redis://:**@10.5.0.9:6300/0: .
Trying again in 32.00 seconds...

[2019-03-13 01:22:06,664: ERROR/MainProcess] consumer: Cannot connect to redis://:**@10.5.0.9:6300/0: .
Trying again in 32.00 seconds...

[2019-03-13 01:24:46,360: ERROR/MainProcess] consumer: Cannot connect to redis://:**@10.5.0.9:6300/0: .
Trying again in 32.00 seconds...

[2019-03-13 01:27:25,640: ERROR/MainProcess] consumer: Cannot connect to redis://:**@10.5.0.9:6300/0: .
Trying again in 32.00 seconds...

[2019-03-13 01:30:05,290: ERROR/MainProcess] consumer: Cannot connect to redis://:**@10.5.0.9:6300/0: .
Trying again in 32.00 seconds...

[2019-03-13 01:32:44,746: ERROR/MainProcess] consumer: Cannot connect to redis://:**@10.5.0.9:6300/0: .
Trying again in 32.00 seconds...

[2019-03-13 01:35:24,233: ERROR/MainProcess] consumer: Cannot connect to redis://:**@10.5.0.9:6300/0: .
Trying again in 32.00 seconds...

[2019-03-13 01:38:03,849: ERROR/MainProcess] consumer: Cannot connect to redis://:**@10.5.0.9:6300/0: .
Trying again in 32.00 seconds...

[2019-03-13 01:40:43,210: ERROR/MainProcess] consumer: Cannot connect to redis://:**@10.5.0.9:6300/0: .
Trying again in 32.00 seconds...

[2019-03-13 01:43:22,953: ERROR/MainProcess] consumer: Cannot connect to redis://:**@10.5.0.9:6300/0: .
Trying again in 32.00 seconds...

[2019-03-13 01:46:02,440: ERROR/MainProcess] consumer: Cannot connect to redis://:**@10.5.0.9:6300/0: .
Trying again in 32.00 seconds...

[2019-03-13 01:48:42,070: ERROR/MainProcess] consumer: Cannot connect to redis://:**@10.5.0.9:6300/0: .
Trying again in 32.00 seconds...

[2019-03-13 01:51:21,672: ERROR/MainProcess] consumer: Cannot connect to redis://:**@10.5.0.9:6300/0: .
Trying again in 32.00 seconds...

[2019-03-13 01:54:01,160: ERROR/MainProcess] consumer: Cannot connect to redis://:**@10.5.0.9:6300/0: .
Trying again in 32.00 seconds...

[2019-03-13 01:56:40,649: ERROR/MainProcess] consumer: Cannot connect to redis://:**@10.5.0.9:6300/0: .
Trying again in 32.00 seconds...

[2019-03-13 01:59:20,138: ERROR/MainProcess] consumer: Cannot connect to redis://:**@10.5.0.9:6300/0: .
Trying again in 32.00 seconds...

[2019-03-13 02:01:59,497: ERROR/MainProcess] consumer: Cannot connect to redis://:**@10.5.0.9:6300/0: .
Trying again in 32.00 seconds...

[2019-03-13 02:04:38,856: ERROR/MainProcess] consumer: Cannot connect to redis://:**@10.5.0.9:6300/0: .
Trying again in 32.00 seconds...

[2019-03-13 02:07:18,216: ERROR/MainProcess] consumer: Cannot connect to redis://:**@10.5.0.9:6300/0: .
Trying again in 32.00 seconds...

[2019-03-13 02:09:58,090: ERROR/MainProcess] consumer: Cannot connect to redis://:**@10.5.0.9:6300/0: .
Trying again in 32.00 seconds...

[2019-03-13 02:12:37,448: ERROR/MainProcess] consumer: Cannot connect to redis://:**@10.5.0.9:6300/0: .
Trying again in 32.00 seconds...

[2019-03-13 02:15:16,810: ERROR/MainProcess] consumer: Cannot connect to redis://:**@10.5.0.9:6300/0: .
Trying again in 32.00 seconds...

[2019-03-13 02:17:56,169: ERROR/MainProcess] consumer: Cannot connect to redis://:**@10.5.0.9:6300/0: .
Trying again in 32.00 seconds...

[2019-03-13 02:20:35,665: ERROR/MainProcess] consumer: Cannot connect to redis://:**@10.5.0.9:6300/0: .
Trying again in 32.00 seconds...

[2019-03-13 02:23:15,273: ERROR/MainProcess] consumer: Cannot connect to redis://:**@10.5.0.9:6300/0: .
Trying again in 32.00 seconds...

[2019-03-13 02:25:54,635: ERROR/MainProcess] consumer: Cannot connect to redis://:**@10.5.0.9:6300/0: .
Trying again in 32.00 seconds...

[2019-03-13 02:28:33,993: ERROR/MainProcess] consumer: Cannot connect to redis://:**@10.5.0.9:6300/0: .
Trying again in 32.00 seconds...

[2019-03-13 02:31:13,655: ERROR/MainProcess] consumer: Cannot connect to redis://:**@10.5.0.9:6300/0: .
Trying again in 32.00 seconds...

[2019-03-13 02:33:53,155: ERROR/MainProcess] consumer: Cannot connect to redis://:**@10.5.0.9:6300/0: .
Trying again in 32.00 seconds...

[2019-03-13 02:36:32,456: ERROR/MainProcess] consumer: Cannot connect to redis://:**@10.5.0.9:6300/0: .
Trying again in 32.00 seconds...

[2019-03-13 02:39:12,073: ERROR/MainProcess] consumer: Cannot connect to redis://:**@10.5.0.9:6300/0: .
Trying again in 32.00 seconds...

[2019-03-13 02:41:51,433: ERROR/MainProcess] consumer: Cannot connect to redis://:**@10.5.0.9:6300/0: .
Trying again in 32.00 seconds...

[2019-03-13 02:44:30,792: ERROR/MainProcess] consumer: Cannot connect to redis://:**@10.5.0.9:6300/0: .
Trying again in 32.00 seconds...

[2019-03-13 02:47:10,153: ERROR/MainProcess] consumer: Cannot connect to redis://:**@10.5.0.9:6300/0: .
Trying again in 32.00 seconds...

[2019-03-13 02:49:49,513: ERROR/MainProcess] consumer: Cannot connect to redis://:**@10.5.0.9:6300/0: .
Trying again in 32.00 seconds...

[2019-03-13 02:52:29,138: ERROR/MainProcess] consumer: Cannot connect to redis://:**@10.5.0.9:6300/0: .
Trying again in 32.00 seconds...

[2019-03-13 02:55:08,686: ERROR/MainProcess] consumer: Cannot connect to redis://:**@10.5.0.9:6300/0: .
Trying again in 32.00 seconds...

[2019-03-13 02:57:47,978: ERROR/MainProcess] consumer: Cannot connect to redis://:**@10.5.0.9:6300/0: .
Trying again in 32.00 seconds...

[2019-03-13 03:00:27,465: ERROR/MainProcess] consumer: Cannot connect to redis://:**@10.5.0.9:6300/0: .
Trying again in 32.00 seconds...

[2019-03-13 03:03:06,929: ERROR/MainProcess] consumer: Cannot connect to redis://:**@10.5.0.9:6300/0: .
Trying again in 32.00 seconds...

[2019-03-13 03:05:46,314: ERROR/MainProcess] consumer: Cannot connect to redis://:**@10.5.0.9:6300/0: .
Trying again in 32.00 seconds...

[2019-03-13 03:08:25,675: ERROR/MainProcess] consumer: Cannot connect to redis://:**@10.5.0.9:6300/0: .
Trying again in 32.00 seconds...

[2019-03-13 03:11:05,033: ERROR/MainProcess] consumer: Cannot connect to redis://:**@10.5.0.9:6300/0: .
Trying again in 32.00 seconds...

[2019-03-13 03:13:44,394: ERROR/MainProcess] consumer: Cannot connect to redis://:**@10.5.0.9:6300/0: .
Trying again in 32.00 seconds...

[2019-03-13 03:16:23,752: ERROR/MainProcess] consumer: Cannot connect to redis://:**@10.5.0.9:6300/0: .
Trying again in 32.00 seconds...

[2019-03-13 03:19:03,112: ERROR/MainProcess] consumer: Cannot connect to redis://:**@10.5.0.9:6300/0: .
Trying again in 32.00 seconds...

[2019-03-13 03:21:42,472: ERROR/MainProcess] consumer: Cannot connect to redis://:**@10.5.0.9:6300/0: .
Trying again in 32.00 seconds...

[2019-03-13 03:24:21,834: ERROR/MainProcess] consumer: Cannot connect to redis://:**@10.5.0.9:6300/0: .
Trying again in 32.00 seconds...

[2019-03-13 03:27:01,194: ERROR/MainProcess] consumer: Cannot connect to redis://:**@10.5.0.9:6300/0: .
Trying again in 32.00 seconds...

[2019-03-13 03:29:40,554: ERROR/MainProcess] consumer: Cannot connect to redis://:**@10.5.0.9:6300/0: .
Trying again in 32.00 seconds...

[2019-03-13 03:32:20,042: ERROR/MainProcess] consumer: Cannot connect to redis://:**@10.5.0.9:6300/0: .
Trying again in 32.00 seconds...

[2019-03-13 03:34:59,400: ERROR/MainProcess] consumer: Cannot connect to redis://:**@10.5.0.9:6300/0: .
Trying again in 32.00 seconds...

[2019-03-13 03:37:38,915: ERROR/MainProcess] consumer: Cannot connect to redis://:**@10.5.0.9:6300/0: .
Trying again in 32.00 seconds...

[2019-03-13 03:40:18,250: ERROR/MainProcess] consumer: Cannot connect to redis://:**@10.5.0.9:6300/0: .
Trying again in 32.00 seconds...

[2019-03-13 03:42:57,609: ERROR/MainProcess] consumer: Cannot connect to redis://:**@10.5.0.9:6300/0: .
Trying again in 32.00 seconds...

[2019-03-13 03:45:37,098: ERROR/MainProcess] consumer: Cannot connect to redis://:**@10.5.0.9:6300/0: .
Trying again in 32.00 seconds...

[2019-03-13 03:48:17,611: ERROR/MainProcess] consumer: Cannot connect to redis://:**@10.5.0.9:6300/0: .
Trying again in 32.00 seconds...

[2019-03-13 03:50:56,969: ERROR/MainProcess] consumer: Cannot connect to redis://:**@10.5.0.9:6300/0: .
Trying again in 32.00 seconds...

[2019-03-13 03:53:36,329: ERROR/MainProcess] consumer: Cannot connect to redis://:**@10.5.0.9:6300/0: .
Trying again in 32.00 seconds...

[2019-03-13 03:56:15,942: ERROR/MainProcess] consumer: Cannot connect to redis://:**@10.5.0.9:6300/0: .
Trying again in 32.00 seconds...

[2019-03-13 03:58:55,304: ERROR/MainProcess] consumer: Cannot connect to redis://:**@10.5.0.9:6300/0: .
Trying again in 32.00 seconds...

[2019-03-13 04:01:34,536: ERROR/MainProcess] consumer: Cannot connect to redis://:**@10.5.0.9:6300/0: .
Trying again in 32.00 seconds...

[2019-03-13 04:04:14,161: ERROR/MainProcess] consumer: Cannot connect to redis://:**@10.5.0.9:6300/0: .
Trying again in 32.00 seconds...

[2019-03-13 04:06:53,897: ERROR/MainProcess] consumer: Cannot connect to redis://:**@10.5.0.9:6300/0: .
Trying again in 32.00 seconds...

[2019-03-13 04:09:33,257: WARNING/MainProcess] consumer: Connection to broker lost. Trying to re-establish the connection...
Traceback (most recent call last):
  File "/home/vagrant/python3.6env/lib/python3.6/site-packages/kombu/transport/virtual/__init__.py", line 789, in create_channel
    return self._avail_channels.pop()
IndexError: pop from empty list

During handling of the above exception, another exception occurred:

Traceback (most recent call last):
  File "/home/vagrant/python3.6env/lib/python3.6/site-packages/redis/connection.py", line 484, in connect
    sock = self._connect()
  File "/home/vagrant/python3.6env/lib/python3.6/site-packages/redis/connection.py", line 541, in _connect
    raise err
  File "/home/vagrant/python3.6env/lib/python3.6/site-packages/redis/connection.py", line 529, in _connect
    sock.connect(socket_address)
TimeoutError: [Errno 110] Connection timed out

During handling of the above exception, another exception occurred:

Traceback (most recent call last):
  File "/home/vagrant/python3.6env/lib/python3.6/site-packages/redis/client.py", line 667, in execute_command
    connection.send_command(*args)
  File "/home/vagrant/python3.6env/lib/python3.6/site-packages/redis/connection.py", line 610, in send_command
    self.send_packed_command(self.pack_command(*args))
  File "/home/vagrant/python3.6env/lib/python3.6/site-packages/redis/connection.py", line 585, in send_packed_command
    self.connect()
  File "/home/vagrant/python3.6env/lib/python3.6/site-packages/redis/connection.py", line 489, in connect
    raise ConnectionError(self._error_message(e))
redis.exceptions.ConnectionError: Error 110 connecting to 10.5.0.9:6300. Connection timed out.

During handling of the above exception, another exception occurred:

Traceback (most recent call last):
  File "/home/vagrant/python3.6env/lib/python3.6/site-packages/kombu/transport/redis.py", line 464, in __init__
    self.client.info()
  File "/home/vagrant/python3.6env/lib/python3.6/site-packages/redis/client.py", line 760, in info
    return self.execute_command('INFO')
  File "/home/vagrant/python3.6env/lib/python3.6/site-packages/redis/client.py", line 670, in execute_command
    connection.disconnect()
  File "/home/vagrant/python3.6env/lib/python3.6/site-packages/kombu/transport/redis.py", line 866, in disconnect
    channel._on_connection_disconnect(self)
  File "/home/vagrant/python3.6env/lib/python3.6/site-packages/kombu/transport/redis.py", line 496, in _on_connection_disconnect
    self._disconnect_pools()
  File "/home/vagrant/python3.6env/lib/python3.6/site-packages/kombu/transport/redis.py", line 484, in _disconnect_pools
    self._async_pool.disconnect()
  File "/home/vagrant/python3.6env/lib/python3.6/site-packages/redis/connection.py", line 998, in disconnect
    connection.disconnect()
  File "/home/vagrant/python3.6env/lib/python3.6/site-packages/kombu/transport/redis.py", line 866, in disconnect
    channel._on_connection_disconnect(self)
  File "/home/vagrant/python3.6env/lib/python3.6/site-packages/kombu/transport/redis.py", line 498, in _on_connection_disconnect
    raise get_redis_ConnectionError()
redis.exceptions.ConnectionError

During handling of the above exception, another exception occurred:

Traceback (most recent call last):
  File "/home/vagrant/python3.6env/lib/python3.6/site-packages/celery/worker/consumer.py", line 280, in start
    blueprint.start(self)
  File "/home/vagrant/python3.6env/lib/python3.6/site-packages/celery/bootsteps.py", line 123, in start
    step.start(parent)
  File "/home/vagrant/python3.6env/lib/python3.6/site-packages/celery/worker/consumer.py", line 525, in start
    c.connection = c.connect()
  File "/home/vagrant/python3.6env/lib/python3.6/site-packages/celery/worker/consumer.py", line 377, in connect
    callback=maybe_shutdown,
  File "/home/vagrant/python3.6env/lib/python3.6/site-packages/kombu/connection.py", line 382, in ensure_connection
    interval_start, interval_step, interval_max, callback)
  File "/home/vagrant/python3.6env/lib/python3.6/site-packages/kombu/utils/__init__.py", line 246, in retry_over_time
    return fun(*args, **kwargs)
  File "/home/vagrant/python3.6env/lib/python3.6/site-packages/kombu/connection.py", line 250, in connect
    return self.connection
  File "/home/vagrant/python3.6env/lib/python3.6/site-packages/kombu/connection.py", line 756, in connection
    self._connection = self._establish_connection()
  File "/home/vagrant/python3.6env/lib/python3.6/site-packages/kombu/connection.py", line 711, in _establish_connection
    conn = self.transport.establish_connection()
  File "/home/vagrant/python3.6env/lib/python3.6/site-packages/kombu/transport/virtual/__init__.py", line 809, in establish_connection
    self._avail_channels.append(self.create_channel(self))
  File "/home/vagrant/python3.6env/lib/python3.6/site-packages/kombu/transport/virtual/__init__.py", line 791, in create_channel
    channel = self.Channel(connection)
  File "/home/vagrant/python3.6env/lib/python3.6/site-packages/kombu/transport/redis.py", line 466, in __init__
    self._disconnect_pools()
  File "/home/vagrant/python3.6env/lib/python3.6/site-packages/kombu/transport/redis.py", line 484, in _disconnect_pools
    self._async_pool.disconnect()
  File "/home/vagrant/python3.6env/lib/python3.6/site-packages/redis/connection.py", line 998, in disconnect
    connection.disconnect()
  File "/home/vagrant/python3.6env/lib/python3.6/site-packages/kombu/transport/redis.py", line 866, in disconnect
    channel._on_connection_disconnect(self)
  File "/home/vagrant/python3.6env/lib/python3.6/site-packages/kombu/transport/redis.py", line 498, in _on_connection_disconnect
    raise get_redis_ConnectionError()
redis.exceptions.ConnectionError
[2019-03-13 04:09:33,269: DEBUG/MainProcess] | Consumer: Restarting event loop...
[2019-03-13 04:09:33,273: DEBUG/MainProcess] | Consumer: Restarting Control...
[2019-03-13 04:09:33,276: DEBUG/MainProcess] | Consumer: Restarting Tasks...
[2019-03-13 04:09:33,280: DEBUG/MainProcess] Canceling task consumer...
[2019-03-13 04:09:33,283: DEBUG/MainProcess] | Consumer: Restarting Heart...
[2019-03-13 04:09:33,286: DEBUG/MainProcess] | Consumer: Restarting Gossip...
[2019-03-13 04:09:33,290: DEBUG/MainProcess] | Consumer: Restarting Mingle...
[2019-03-13 04:09:33,293: DEBUG/MainProcess] | Consumer: Restarting Events...
[2019-03-13 04:09:33,302: DEBUG/MainProcess] | Consumer: Restarting Connection...
[2019-03-13 04:09:33,306: DEBUG/MainProcess] | Consumer: Starting Connection
[2019-03-13 04:11:40,616: ERROR/MainProcess] consumer: Cannot connect to redis://:**@10.5.0.9:6300/0: .
Trying again in 2.00 seconds...

[2019-03-13 04:13:49,899: ERROR/MainProcess] consumer: Cannot connect to redis://:**@10.5.0.9:6300/0: .
Trying again in 4.00 seconds...

[2019-03-13 04:16:01,097: ERROR/MainProcess] consumer: Cannot connect to redis://:**@10.5.0.9:6300/0: .
Trying again in 6.00 seconds...

[2019-03-13 04:18:14,345: ERROR/MainProcess] consumer: Cannot connect to redis://:**@10.5.0.9:6300/0: .
Trying again in 8.00 seconds...

[2019-03-13 04:20:29,641: ERROR/MainProcess] consumer: Cannot connect to redis://:**@10.5.0.9:6300/0: .
Trying again in 10.00 seconds...

[2019-03-13 04:22:46,857: ERROR/MainProcess] consumer: Cannot connect to redis://:**@10.5.0.9:6300/0: .
Trying again in 12.00 seconds...

[2019-03-13 04:25:06,129: ERROR/MainProcess] consumer: Cannot connect to redis://:**@10.5.0.9:6300/0: .
Trying again in 14.00 seconds...

[2019-03-13 04:27:27,432: ERROR/MainProcess] consumer: Cannot connect to redis://:**@10.5.0.9:6300/0: .
Trying again in 16.00 seconds...

[2019-03-13 04:29:51,049: ERROR/MainProcess] consumer: Cannot connect to redis://:**@10.5.0.9:6300/0: .
Trying again in 18.00 seconds...

[2019-03-13 04:32:16,329: ERROR/MainProcess] consumer: Cannot connect to redis://:**@10.5.0.9:6300/0: .
Trying again in 20.00 seconds...

[2019-03-13 04:34:43,658: ERROR/MainProcess] consumer: Cannot connect to redis://:**@10.5.0.9:6300/0: .
Trying again in 22.00 seconds...

[2019-03-13 04:37:12,905: ERROR/MainProcess] consumer: Cannot connect to redis://:**@10.5.0.9:6300/0: .
Trying again in 24.00 seconds...

[2019-03-13 04:39:44,482: ERROR/MainProcess] consumer: Cannot connect to redis://:**@10.5.0.9:6300/0: .
Trying again in 26.00 seconds...

[2019-03-13 04:42:17,800: ERROR/MainProcess] consumer: Cannot connect to redis://:**@10.5.0.9:6300/0: .
Trying again in 28.00 seconds...

[2019-03-13 04:44:53,194: ERROR/MainProcess] consumer: Cannot connect to redis://:**@10.5.0.9:6300/0: .
Trying again in 30.00 seconds...

[2019-03-13 04:47:30,634: ERROR/MainProcess] consumer: Cannot connect to redis://:**@10.5.0.9:6300/0: .
Trying again in 32.00 seconds...

[2019-03-13 04:50:10,120: ERROR/MainProcess] consumer: Cannot connect to redis://:**@10.5.0.9:6300/0: .
Trying again in 32.00 seconds...

[2019-03-13 04:52:49,610: ERROR/MainProcess] consumer: Cannot connect to redis://:**@10.5.0.9:6300/0: .
Trying again in 32.00 seconds...

[2019-03-13 04:55:28,968: ERROR/MainProcess] consumer: Cannot connect to redis://:**@10.5.0.9:6300/0: .
Trying again in 32.00 seconds...

[2019-03-13 04:58:08,330: ERROR/MainProcess] consumer: Cannot connect to redis://:**@10.5.0.9:6300/0: .
Trying again in 32.00 seconds...

[2019-03-13 05:00:48,072: ERROR/MainProcess] consumer: Cannot connect to redis://:**@10.5.0.9:6300/0: .
Trying again in 32.00 seconds...

[2019-03-13 05:03:27,817: ERROR/MainProcess] consumer: Cannot connect to redis://:**@10.5.0.9:6300/0: .
Trying again in 32.00 seconds...

[2019-03-13 05:06:07,049: ERROR/MainProcess] consumer: Cannot connect to redis://:**@10.5.0.9:6300/0: .
Trying again in 32.00 seconds...

[2019-03-13 05:08:46,408: ERROR/MainProcess] consumer: Cannot connect to redis://:**@10.5.0.9:6300/0: .
Trying again in 32.00 seconds...

[2019-03-13 05:11:25,769: ERROR/MainProcess] consumer: Cannot connect to redis://:**@10.5.0.9:6300/0: .
Trying again in 32.00 seconds...

[2019-03-13 05:14:05,770: ERROR/MainProcess] consumer: Cannot connect to redis://:**@10.5.0.9:6300/0: .
Trying again in 32.00 seconds...

[2019-03-13 05:16:45,256: ERROR/MainProcess] consumer: Cannot connect to redis://:**@10.5.0.9:6300/0: .
Trying again in 32.00 seconds...

[2019-03-13 05:19:24,489: ERROR/MainProcess] consumer: Cannot connect to redis://:**@10.5.0.9:6300/0: .
Trying again in 32.00 seconds...

[2019-03-13 05:22:03,850: ERROR/MainProcess] consumer: Cannot connect to redis://:**@10.5.0.9:6300/0: .
Trying again in 32.00 seconds...

[2019-03-13 05:24:43,211: ERROR/MainProcess] consumer: Cannot connect to redis://:**@10.5.0.9:6300/0: .
Trying again in 32.00 seconds...

[2019-03-13 05:27:22,568: ERROR/MainProcess] consumer: Cannot connect to redis://:**@10.5.0.9:6300/0: .
Trying again in 32.00 seconds...

[2019-03-13 05:30:01,933: ERROR/MainProcess] consumer: Cannot connect to redis://:**@10.5.0.9:6300/0: .
Trying again in 32.00 seconds...

[2019-03-13 05:32:41,161: ERROR/MainProcess] consumer: Cannot connect to redis://:**@10.5.0.9:6300/0: .
Trying again in 32.00 seconds...

[2019-03-13 05:35:20,522: ERROR/MainProcess] consumer: Cannot connect to redis://:**@10.5.0.9:6300/0: .
Trying again in 32.00 seconds...

[2019-03-13 05:37:59,926: ERROR/MainProcess] consumer: Cannot connect to redis://:**@10.5.0.9:6300/0: .
Trying again in 32.00 seconds...

[2019-03-13 05:40:39,374: ERROR/MainProcess] consumer: Cannot connect to redis://:**@10.5.0.9:6300/0: .
Trying again in 32.00 seconds...

[2019-03-13 05:43:18,986: ERROR/MainProcess] consumer: Cannot connect to redis://:**@10.5.0.9:6300/0: .
Trying again in 32.00 seconds...

[2019-03-13 05:45:58,345: ERROR/MainProcess] consumer: Cannot connect to redis://:**@10.5.0.9:6300/0: .
Trying again in 32.00 seconds...

[2019-03-13 05:48:37,705: ERROR/MainProcess] consumer: Cannot connect to redis://:**@10.5.0.9:6300/0: .
Trying again in 32.00 seconds...

[2019-03-13 05:51:17,193: ERROR/MainProcess] consumer: Cannot connect to redis://:**@10.5.0.9:6300/0: .
Trying again in 32.00 seconds...

[2019-03-13 05:53:57,065: ERROR/MainProcess] consumer: Cannot connect to redis://:**@10.5.0.9:6300/0: .
Trying again in 32.00 seconds...

[2019-03-13 05:56:36,296: ERROR/MainProcess] consumer: Cannot connect to redis://:**@10.5.0.9:6300/0: .
Trying again in 32.00 seconds...

[2019-03-13 05:59:15,529: ERROR/MainProcess] consumer: Cannot connect to redis://:**@10.5.0.9:6300/0: .
Trying again in 32.00 seconds...

[2019-03-13 06:01:54,894: ERROR/MainProcess] consumer: Cannot connect to redis://:**@10.5.0.9:6300/0: .
Trying again in 32.00 seconds...

[2019-03-13 06:04:34,248: ERROR/MainProcess] consumer: Cannot connect to redis://:**@10.5.0.9:6300/0: .
Trying again in 32.00 seconds...

[2019-03-13 06:07:13,865: ERROR/MainProcess] consumer: Cannot connect to redis://:**@10.5.0.9:6300/0: .
Trying again in 32.00 seconds...

[2019-03-13 06:09:53,225: ERROR/MainProcess] consumer: Cannot connect to redis://:**@10.5.0.9:6300/0: .
Trying again in 32.00 seconds...

[2019-03-13 06:12:32,714: ERROR/MainProcess] consumer: Cannot connect to redis://:**@10.5.0.9:6300/0: .
Trying again in 32.00 seconds...

[2019-03-13 06:15:12,200: ERROR/MainProcess] consumer: Cannot connect to redis://:**@10.5.0.9:6300/0: .
Trying again in 32.00 seconds...

[2019-03-13 06:17:51,561: ERROR/MainProcess] consumer: Cannot connect to redis://:**@10.5.0.9:6300/0: .
Trying again in 32.00 seconds...

[2019-03-13 06:20:31,179: ERROR/MainProcess] consumer: Cannot connect to redis://:**@10.5.0.9:6300/0: .
Trying again in 32.00 seconds...

[2019-03-13 06:23:10,666: ERROR/MainProcess] consumer: Cannot connect to redis://:**@10.5.0.9:6300/0: .
Trying again in 32.00 seconds...

[2019-03-13 06:25:50,152: ERROR/MainProcess] consumer: Cannot connect to redis://:**@10.5.0.9:6300/0: .
Trying again in 32.00 seconds...

[2019-03-13 06:28:29,938: ERROR/MainProcess] consumer: Cannot connect to redis://:**@10.5.0.9:6300/0: .
Trying again in 32.00 seconds...

[2019-03-13 06:31:09,266: ERROR/MainProcess] consumer: Cannot connect to redis://:**@10.5.0.9:6300/0: .
Trying again in 32.00 seconds...

[2019-03-13 06:33:48,616: ERROR/MainProcess] consumer: Cannot connect to redis://:**@10.5.0.9:6300/0: .
Trying again in 32.00 seconds...

[2019-03-13 06:36:27,984: ERROR/MainProcess] consumer: Cannot connect to redis://:**@10.5.0.9:6300/0: .
Trying again in 32.00 seconds...

[2019-03-13 06:39:07,336: ERROR/MainProcess] consumer: Cannot connect to redis://:**@10.5.0.9:6300/0: .
Trying again in 32.00 seconds...

[2019-03-13 06:41:46,697: ERROR/MainProcess] consumer: Cannot connect to redis://:**@10.5.0.9:6300/0: .
Trying again in 32.00 seconds...

[2019-03-13 06:44:26,368: ERROR/MainProcess] consumer: Cannot connect to redis://:**@10.5.0.9:6300/0: .
Trying again in 32.00 seconds...

[2019-03-13 06:47:05,673: ERROR/MainProcess] consumer: Cannot connect to redis://:**@10.5.0.9:6300/0: .
Trying again in 32.00 seconds...

[2019-03-13 06:49:45,035: ERROR/MainProcess] consumer: Cannot connect to redis://:**@10.5.0.9:6300/0: .
Trying again in 32.00 seconds...

[2019-03-13 06:52:24,521: ERROR/MainProcess] consumer: Cannot connect to redis://:**@10.5.0.9:6300/0: .
Trying again in 32.00 seconds...

[2019-03-13 06:55:04,010: ERROR/MainProcess] consumer: Cannot connect to redis://:**@10.5.0.9:6300/0: .
Trying again in 32.00 seconds...

[2019-03-13 06:57:43,369: ERROR/MainProcess] consumer: Cannot connect to redis://:**@10.5.0.9:6300/0: .
Trying again in 32.00 seconds...

[2019-03-13 07:00:22,730: ERROR/MainProcess] consumer: Cannot connect to redis://:**@10.5.0.9:6300/0: .
Trying again in 32.00 seconds...

[2019-03-13 07:03:02,217: ERROR/MainProcess] consumer: Cannot connect to redis://:**@10.5.0.9:6300/0: .
Trying again in 32.00 seconds...

[2019-03-13 07:05:42,032: ERROR/MainProcess] consumer: Cannot connect to redis://:**@10.5.0.9:6300/0: .
Trying again in 32.00 seconds...

[2019-03-13 07:08:21,704: ERROR/MainProcess] consumer: Cannot connect to redis://:**@10.5.0.9:6300/0: .
Trying again in 32.00 seconds...

[2019-03-13 07:11:01,066: ERROR/MainProcess] consumer: Cannot connect to redis://:**@10.5.0.9:6300/0: .
Trying again in 32.00 seconds...

[2019-03-13 07:13:40,553: ERROR/MainProcess] consumer: Cannot connect to redis://:**@10.5.0.9:6300/0: .
Trying again in 32.00 seconds...

[2019-03-13 07:16:19,913: ERROR/MainProcess] consumer: Cannot connect to redis://:**@10.5.0.9:6300/0: .
Trying again in 32.00 seconds...

[2019-03-13 07:18:59,148: ERROR/MainProcess] consumer: Cannot connect to redis://:**@10.5.0.9:6300/0: .
Trying again in 32.00 seconds...

[2019-03-13 07:21:39,018: ERROR/MainProcess] consumer: Cannot connect to redis://:**@10.5.0.9:6300/0: .
Trying again in 32.00 seconds...

[2019-03-13 07:24:18,396: ERROR/MainProcess] consumer: Cannot connect to redis://:**@10.5.0.9:6300/0: .
Trying again in 32.00 seconds...

[2019-03-13 07:26:58,122: ERROR/MainProcess] consumer: Cannot connect to redis://:**@10.5.0.9:6300/0: .
Trying again in 32.00 seconds...

[2019-03-13 07:29:37,352: ERROR/MainProcess] consumer: Cannot connect to redis://:**@10.5.0.9:6300/0: .
Trying again in 32.00 seconds...

[2019-03-13 07:32:16,712: ERROR/MainProcess] consumer: Cannot connect to redis://:**@10.5.0.9:6300/0: .
Trying again in 32.00 seconds...

[2019-03-13 07:34:56,074: ERROR/MainProcess] consumer: Cannot connect to redis://:**@10.5.0.9:6300/0: .
Trying again in 32.00 seconds...

[2019-03-13 07:37:35,305: ERROR/MainProcess] consumer: Cannot connect to redis://:**@10.5.0.9:6300/0: .
Trying again in 32.00 seconds...

[2019-03-13 07:40:14,665: ERROR/MainProcess] consumer: Cannot connect to redis://:**@10.5.0.9:6300/0: .
Trying again in 32.00 seconds...

[2019-03-13 07:42:54,802: ERROR/MainProcess] consumer: Cannot connect to redis://:**@10.5.0.9:6300/0: .
Trying again in 32.00 seconds...

[2019-03-13 07:45:34,537: ERROR/MainProcess] consumer: Cannot connect to redis://:**@10.5.0.9:6300/0: .
Trying again in 32.00 seconds...

[2019-03-13 07:48:13,897: ERROR/MainProcess] consumer: Cannot connect to redis://:**@10.5.0.9:6300/0: .
Trying again in 32.00 seconds...

[2019-03-13 07:50:53,513: ERROR/MainProcess] consumer: Cannot connect to redis://:**@10.5.0.9:6300/0: .
Trying again in 32.00 seconds...

[2019-03-13 07:53:32,873: ERROR/MainProcess] consumer: Cannot connect to redis://:**@10.5.0.9:6300/0: .
Trying again in 32.00 seconds...

[2019-03-13 07:56:12,232: ERROR/MainProcess] consumer: Cannot connect to redis://:**@10.5.0.9:6300/0: .
Trying again in 32.00 seconds...

[2019-03-13 07:58:51,592: ERROR/MainProcess] consumer: Cannot connect to redis://:**@10.5.0.9:6300/0: .
Trying again in 32.00 seconds...

[2019-03-13 08:01:30,953: ERROR/MainProcess] consumer: Cannot connect to redis://:**@10.5.0.9:6300/0: .
Trying again in 32.00 seconds...

[2019-03-13 08:04:10,312: ERROR/MainProcess] consumer: Cannot connect to redis://:**@10.5.0.9:6300/0: .
Trying again in 32.00 seconds...

[2019-03-13 08:06:49,672: ERROR/MainProcess] consumer: Cannot connect to redis://:**@10.5.0.9:6300/0: .
Trying again in 32.00 seconds...

[2019-03-13 08:09:28,904: ERROR/MainProcess] consumer: Cannot connect to redis://:**@10.5.0.9:6300/0: .
Trying again in 32.00 seconds...

[2019-03-13 08:12:08,394: ERROR/MainProcess] consumer: Cannot connect to redis://:**@10.5.0.9:6300/0: .
Trying again in 32.00 seconds...

[2019-03-13 08:14:47,753: ERROR/MainProcess] consumer: Cannot connect to redis://:**@10.5.0.9:6300/0: .
Trying again in 32.00 seconds...

[2019-03-13 08:17:27,240: ERROR/MainProcess] consumer: Cannot connect to redis://:**@10.5.0.9:6300/0: .
Trying again in 32.00 seconds...

[2019-03-13 08:20:07,136: ERROR/MainProcess] consumer: Cannot connect to redis://:**@10.5.0.9:6300/0: .
Trying again in 32.00 seconds...

[2019-03-13 08:22:46,478: ERROR/MainProcess] consumer: Cannot connect to redis://:**@10.5.0.9:6300/0: .
Trying again in 32.00 seconds...

[2019-03-13 08:25:25,833: ERROR/MainProcess] consumer: Cannot connect to redis://:**@10.5.0.9:6300/0: .
Trying again in 32.00 seconds...

[2019-03-13 08:28:05,320: ERROR/MainProcess] consumer: Cannot connect to redis://:**@10.5.0.9:6300/0: .
Trying again in 32.00 seconds...

[2019-03-13 08:30:44,937: ERROR/MainProcess] consumer: Cannot connect to redis://:**@10.5.0.9:6300/0: .
Trying again in 32.00 seconds...

[2019-03-13 08:33:24,299: WARNING/MainProcess] consumer: Connection to broker lost. Trying to re-establish the connection...
Traceback (most recent call last):
  File "/home/vagrant/python3.6env/lib/python3.6/site-packages/kombu/transport/virtual/__init__.py", line 789, in create_channel
    return self._avail_channels.pop()
IndexError: pop from empty list

During handling of the above exception, another exception occurred:

Traceback (most recent call last):
  File "/home/vagrant/python3.6env/lib/python3.6/site-packages/redis/connection.py", line 484, in connect
    sock = self._connect()
  File "/home/vagrant/python3.6env/lib/python3.6/site-packages/redis/connection.py", line 541, in _connect
    raise err
  File "/home/vagrant/python3.6env/lib/python3.6/site-packages/redis/connection.py", line 529, in _connect
    sock.connect(socket_address)
TimeoutError: [Errno 110] Connection timed out

During handling of the above exception, another exception occurred:

Traceback (most recent call last):
  File "/home/vagrant/python3.6env/lib/python3.6/site-packages/redis/client.py", line 667, in execute_command
    connection.send_command(*args)
  File "/home/vagrant/python3.6env/lib/python3.6/site-packages/redis/connection.py", line 610, in send_command
    self.send_packed_command(self.pack_command(*args))
  File "/home/vagrant/python3.6env/lib/python3.6/site-packages/redis/connection.py", line 585, in send_packed_command
    self.connect()
  File "/home/vagrant/python3.6env/lib/python3.6/site-packages/redis/connection.py", line 489, in connect
    raise ConnectionError(self._error_message(e))
redis.exceptions.ConnectionError: Error 110 connecting to 10.5.0.9:6300. Connection timed out.

During handling of the above exception, another exception occurred:

Traceback (most recent call last):
  File "/home/vagrant/python3.6env/lib/python3.6/site-packages/kombu/transport/redis.py", line 464, in __init__
    self.client.info()
  File "/home/vagrant/python3.6env/lib/python3.6/site-packages/redis/client.py", line 760, in info
    return self.execute_command('INFO')
  File "/home/vagrant/python3.6env/lib/python3.6/site-packages/redis/client.py", line 670, in execute_command
    connection.disconnect()
  File "/home/vagrant/python3.6env/lib/python3.6/site-packages/kombu/transport/redis.py", line 866, in disconnect
    channel._on_connection_disconnect(self)
  File "/home/vagrant/python3.6env/lib/python3.6/site-packages/kombu/transport/redis.py", line 496, in _on_connection_disconnect
    self._disconnect_pools()
  File "/home/vagrant/python3.6env/lib/python3.6/site-packages/kombu/transport/redis.py", line 484, in _disconnect_pools
    self._async_pool.disconnect()
  File "/home/vagrant/python3.6env/lib/python3.6/site-packages/redis/connection.py", line 998, in disconnect
    connection.disconnect()
  File "/home/vagrant/python3.6env/lib/python3.6/site-packages/kombu/transport/redis.py", line 866, in disconnect
    channel._on_connection_disconnect(self)
  File "/home/vagrant/python3.6env/lib/python3.6/site-packages/kombu/transport/redis.py", line 498, in _on_connection_disconnect
    raise get_redis_ConnectionError()
redis.exceptions.ConnectionError

During handling of the above exception, another exception occurred:

Traceback (most recent call last):
  File "/home/vagrant/python3.6env/lib/python3.6/site-packages/celery/worker/consumer.py", line 280, in start
    blueprint.start(self)
  File "/home/vagrant/python3.6env/lib/python3.6/site-packages/celery/bootsteps.py", line 123, in start
    step.start(parent)
  File "/home/vagrant/python3.6env/lib/python3.6/site-packages/celery/worker/consumer.py", line 525, in start
    c.connection = c.connect()
  File "/home/vagrant/python3.6env/lib/python3.6/site-packages/celery/worker/consumer.py", line 377, in connect
    callback=maybe_shutdown,
  File "/home/vagrant/python3.6env/lib/python3.6/site-packages/kombu/connection.py", line 382, in ensure_connection
    interval_start, interval_step, interval_max, callback)
  File "/home/vagrant/python3.6env/lib/python3.6/site-packages/kombu/utils/__init__.py", line 246, in retry_over_time
    return fun(*args, **kwargs)
  File "/home/vagrant/python3.6env/lib/python3.6/site-packages/kombu/connection.py", line 250, in connect
    return self.connection
  File "/home/vagrant/python3.6env/lib/python3.6/site-packages/kombu/connection.py", line 756, in connection
    self._connection = self._establish_connection()
  File "/home/vagrant/python3.6env/lib/python3.6/site-packages/kombu/connection.py", line 711, in _establish_connection
    conn = self.transport.establish_connection()
  File "/home/vagrant/python3.6env/lib/python3.6/site-packages/kombu/transport/virtual/__init__.py", line 809, in establish_connection
    self._avail_channels.append(self.create_channel(self))
  File "/home/vagrant/python3.6env/lib/python3.6/site-packages/kombu/transport/virtual/__init__.py", line 791, in create_channel
    channel = self.Channel(connection)
  File "/home/vagrant/python3.6env/lib/python3.6/site-packages/kombu/transport/redis.py", line 466, in __init__
    self._disconnect_pools()
  File "/home/vagrant/python3.6env/lib/python3.6/site-packages/kombu/transport/redis.py", line 484, in _disconnect_pools
    self._async_pool.disconnect()
  File "/home/vagrant/python3.6env/lib/python3.6/site-packages/redis/connection.py", line 998, in disconnect
    connection.disconnect()
  File "/home/vagrant/python3.6env/lib/python3.6/site-packages/kombu/transport/redis.py", line 866, in disconnect
    channel._on_connection_disconnect(self)
  File "/home/vagrant/python3.6env/lib/python3.6/site-packages/kombu/transport/redis.py", line 498, in _on_connection_disconnect
    raise get_redis_ConnectionError()
redis.exceptions.ConnectionError
[2019-03-13 08:33:24,309: DEBUG/MainProcess] | Consumer: Restarting event loop...
[2019-03-13 08:33:24,313: DEBUG/MainProcess] | Consumer: Restarting Control...
[2019-03-13 08:33:24,316: DEBUG/MainProcess] | Consumer: Restarting Tasks...
[2019-03-13 08:33:24,320: DEBUG/MainProcess] Canceling task consumer...
[2019-03-13 08:33:24,325: DEBUG/MainProcess] | Consumer: Restarting Heart...
[2019-03-13 08:33:24,328: DEBUG/MainProcess] | Consumer: Restarting Gossip...
[2019-03-13 08:33:24,330: DEBUG/MainProcess] | Consumer: Restarting Mingle...
[2019-03-13 08:33:24,332: DEBUG/MainProcess] | Consumer: Restarting Events...
[2019-03-13 08:33:24,334: DEBUG/MainProcess] | Consumer: Restarting Connection...
[2019-03-13 08:33:24,335: DEBUG/MainProcess] | Consumer: Starting Connection
[2019-03-13 08:35:31,657: ERROR/MainProcess] consumer: Cannot connect to redis://:**@10.5.0.9:6300/0: .
Trying again in 2.00 seconds...

[2019-03-13 08:37:40,937: ERROR/MainProcess] consumer: Cannot connect to redis://:**@10.5.0.9:6300/0: .
Trying again in 4.00 seconds...

[2019-03-13 08:39:52,264: ERROR/MainProcess] consumer: Cannot connect to redis://:**@10.5.0.9:6300/0: .
Trying again in 6.00 seconds...

[2019-03-13 08:42:05,512: ERROR/MainProcess] consumer: Cannot connect to redis://:**@10.5.0.9:6300/0: .
Trying again in 8.00 seconds...

[2019-03-13 08:44:20,809: ERROR/MainProcess] consumer: Cannot connect to redis://:**@10.5.0.9:6300/0: .
Trying again in 10.00 seconds...

[2019-03-13 08:46:38,160: ERROR/MainProcess] consumer: Cannot connect to redis://:**@10.5.0.9:6300/0: .
Trying again in 12.00 seconds...

[2019-03-13 08:48:57,546: ERROR/MainProcess] consumer: Cannot connect to redis://:**@10.5.0.9:6300/0: .
Trying again in 14.00 seconds...

[2019-03-13 08:51:18,857: ERROR/MainProcess] consumer: Cannot connect to redis://:**@10.5.0.9:6300/0: .
Trying again in 16.00 seconds...

[2019-03-13 08:53:42,090: ERROR/MainProcess] consumer: Cannot connect to redis://:**@10.5.0.9:6300/0: .
Trying again in 18.00 seconds...

[2019-03-13 08:56:07,368: ERROR/MainProcess] consumer: Cannot connect to redis://:**@10.5.0.9:6300/0: .
Trying again in 20.00 seconds...

[2019-03-13 08:58:34,697: ERROR/MainProcess] consumer: Cannot connect to redis://:**@10.5.0.9:6300/0: .
Trying again in 22.00 seconds...

[2019-03-13 09:01:03,945: ERROR/MainProcess] consumer: Cannot connect to redis://:**@10.5.0.9:6300/0: .
Trying again in 24.00 seconds...

[2019-03-13 09:01:59,457: INFO/MainProcess] Connected to redis://:**@10.5.0.9:6300/0
[2019-03-13 09:01:59,458: DEBUG/MainProcess] ^-- substep ok
[2019-03-13 09:01:59,461: DEBUG/MainProcess] | Consumer: Starting Events
[2019-03-13 09:01:59,902: DEBUG/MainProcess] ^-- substep ok
[2019-03-13 09:01:59,904: DEBUG/MainProcess] | Consumer: Starting Mingle
[2019-03-13 09:01:59,905: INFO/MainProcess] mingle: searching for neighbors
[2019-03-13 09:02:01,119: INFO/MainProcess] mingle: all alone
[2019-03-13 09:02:01,120: DEBUG/MainProcess] ^-- substep ok
[2019-03-13 09:02:01,122: DEBUG/MainProcess] | Consumer: Starting Gossip
[2019-03-13 09:02:01,323: DEBUG/MainProcess] ^-- substep ok
[2019-03-13 09:02:01,326: DEBUG/MainProcess] | Consumer: Starting Heart
[2019-03-13 09:02:01,338: DEBUG/MainProcess] ^-- substep ok
[2019-03-13 09:02:01,340: DEBUG/MainProcess] | Consumer: Starting Tasks
[2019-03-13 09:02:01,360: DEBUG/MainProcess] ^-- substep ok
[2019-03-13 09:02:01,362: DEBUG/MainProcess] | Consumer: Starting Control
[2019-03-13 09:02:01,727: DEBUG/MainProcess] ^-- substep ok
[2019-03-13 09:02:01,730: DEBUG/MainProcess] | Consumer: Starting event loop
[2019-03-13 09:02:01,732: DEBUG/MainProcess] | Worker: Hub.register Pool...
[2019-03-13 09:02:01,735: DEBUG/MainProcess] basic.qos: prefetch_count->8
[2019-03-13 15:36:10,415: INFO/MainProcess] Received task: 代码上线[b57a54e6-fcdb-4927-96cc-6b41c4db8c33]
[2019-03-13 15:36:10,417: DEBUG/MainProcess] TaskPool: Apply <function _fast_trace_task at 0x7f56117671e0> (args:('代码上线', 'b57a54e6-fcdb-4927-96cc-6b41c4db8c33', ('22', {'status': 3, 'name': 'payask', 'version': 'v2.1.8', 'assign_to': <User: carl>}), {}, {'task': '代码上线', 'id': 'b57a54e6-fcdb-4927-96cc-6b41c4db8c33', 'args': ('22', {'status': 3, 'name': 'payask', 'version': 'v2.1.8', 'assign_to': <User: carl>}), 'kwargs': {}, 'retries': 0, 'eta': None, 'expires': None, 'utc': True, 'callbacks': None, 'errbacks': None, 'timelimit': (None, None), 'taskset': None, 'chord': None, 'headers': {}, 'reply_to': 'f705f80b-8ba2-368f-9bbe-b67eab197430', 'correlation_id': 'b57a54e6-fcdb-4927-96cc-6b41c4db8c33', 'delivery_info': {'exchange': 'celery', 'routing_key': 'celery', 'priority': 0, 'redelivered': None}, 'hostname': 'celery@localhost.localdomain', 'is_eager': False, 'group': None}) kwargs:{})
[2019-03-13 15:36:10,421: WARNING/Worker-2] {'status': 3, 'name': 'payask', 'version': 'v2.1.8', 'assign_to': <User: carl>}
[2019-03-13 15:36:10,431: DEBUG/Worker-2] Starting new HTTP connection (1): 10.5.0.9:9001
[2019-03-13 15:36:10,475: DEBUG/MainProcess] Task accepted: 代码上线[b57a54e6-fcdb-4927-96cc-6b41c4db8c33] pid:21031
[2019-03-13 15:36:10,581: DEBUG/Worker-2] http://10.5.0.9:9001 "GET /jenkins/crumbIssuer/api/json HTTP/1.1" 200 133
[2019-03-13 15:36:10,624: DEBUG/Worker-2] http://10.5.0.9:9001 "GET /jenkins/job/payask/api/json?depth=0 HTTP/1.1" 200 703
[2019-03-13 15:36:10,684: DEBUG/Worker-2] http://10.5.0.9:9001 "POST /jenkins/job/payask/buildWithParameters?Tag=v2.1.8 HTTP/1.1" 201 0
[2019-03-13 15:36:20,716: DEBUG/Worker-2] http://10.5.0.9:9001 "GET /jenkins/job/payask/11/consoleText HTTP/1.1" 200 590
[2019-03-13 15:36:20,741: INFO/MainProcess] Task 代码上线[b57a54e6-fcdb-4927-96cc-6b41c4db8c33] succeeded in 10.320643207000103s: '[payask] Project release completed.......'
[2019-03-13 17:27:49,796: WARNING/MainProcess] Substantial drift from celery@n_05 may mean clocks are out of sync.  Current drift is
66 seconds.  [orig: 2019-03-13 17:27:49.795623 recv: 2019-03-13 17:26:43.991482]

[2019-03-13 17:27:49,798: DEBUG/MainProcess] celery@n_05 joined the party
[2019-03-13 17:27:49,802: DEBUG/MainProcess] pidbox received method hello(from_node='celery@n_05', revoked={}) [reply_to:{'exchange': 'reply.celery.pidbox', 'routing_key': 'c20fd71d-6bb1-3d11-9f2a-e8fa501f8592'} ticket:cccc7473-8f22-4210-ab40-205a5d228160]
[2019-03-13 17:27:49,804: INFO/MainProcess] sync with celery@n_05
[2019-03-13 17:28:00,558: DEBUG/MainProcess] celery@n_05 left
[2019-03-13 17:28:10,035: INFO/MainProcess] Received task: 代码上线[18d75deb-a923-4649-a9da-7d1e5a273aa2]
[2019-03-13 17:28:10,036: DEBUG/MainProcess] TaskPool: Apply <function _fast_trace_task at 0x7f56117671e0> (args:('代码上线', '18d75deb-a923-4649-a9da-7d1e5a273aa2', ('1', {'status': 3, 'name': 'payask', 'version': 'v2.1.6', 'assign_to': <User: tompson>}), {}, {'task': '代码上线', 'id': '18d75deb-a923-4649-a9da-7d1e5a273aa2', 'args': ('1', {'status': 3, 'name': 'payask', 'version': 'v2.1.6', 'assign_to': <User: tompson>}), 'kwargs': {}, 'retries': 0, 'eta': None, 'expires': None, 'utc': True, 'callbacks': None, 'errbacks': None, 'timelimit': (None, None), 'taskset': None, 'chord': None, 'headers': {}, 'reply_to': '5d5a7798-4983-35dd-9577-aa7d332c7dba', 'correlation_id': '18d75deb-a923-4649-a9da-7d1e5a273aa2', 'delivery_info': {'exchange': 'celery', 'routing_key': 'celery', 'priority': 0, 'redelivered': None}, 'hostname': 'celery@localhost.localdomain', 'is_eager': False, 'group': None}) kwargs:{})
[2019-03-13 17:28:10,039: WARNING/Worker-1] {'status': 3, 'name': 'payask', 'version': 'v2.1.6', 'assign_to': <User: tompson>}
[2019-03-13 17:28:10,043: DEBUG/Worker-1] Starting new HTTP connection (1): 10.5.0.9:9001
[2019-03-13 17:28:10,138: DEBUG/MainProcess] Task accepted: 代码上线[18d75deb-a923-4649-a9da-7d1e5a273aa2] pid:21030
[2019-03-13 17:28:10,240: DEBUG/Worker-1] http://10.5.0.9:9001 "GET /jenkins/crumbIssuer/api/json HTTP/1.1" 200 133
[2019-03-13 17:28:10,259: DEBUG/Worker-1] http://10.5.0.9:9001 "GET /jenkins/job/payask/api/json?depth=0 HTTP/1.1" 200 709
[2019-03-13 17:28:10,294: DEBUG/Worker-1] http://10.5.0.9:9001 "POST /jenkins/job/payask/buildWithParameters?Tag=v2.1.6 HTTP/1.1" 201 0
[2019-03-13 17:28:20,336: DEBUG/Worker-1] http://10.5.0.9:9001 "GET /jenkins/job/payask/12/consoleText HTTP/1.1" 200 661
[2019-03-13 17:28:20,351: INFO/MainProcess] Task 代码上线[18d75deb-a923-4649-a9da-7d1e5a273aa2] succeeded in 10.312451665988192s: '[payask] Project release completed.......'
[2019-03-13 17:32:36,798: DEBUG/MainProcess] pidbox received method hello(from_node='celery@n_05', revoked={}) [reply_to:{'exchange': 'reply.celery.pidbox', 'routing_key': 'f75f1cf8-f172-3ee8-ab3b-39d8a4ab3163'} ticket:2ae9ea7f-4348-4f0d-bc2e-d880802ad0f2]
[2019-03-13 17:32:36,800: INFO/MainProcess] sync with celery@n_05
[2019-03-13 17:32:37,841: DEBUG/MainProcess] celery@n_05 joined the party
[2019-03-13 17:35:54,232: INFO/MainProcess] Received task: 代码上线[423b16d9-1fee-409f-b2a1-b3b1278a3d12]
[2019-03-13 17:35:54,235: DEBUG/MainProcess] TaskPool: Apply <function _fast_trace_task at 0x7f56117671e0> (args:('代码上线', '423b16d9-1fee-409f-b2a1-b3b1278a3d12', ('2', {'status': 3, 'name': 'payask', 'version': 'v2.1.6', 'assign_to': <User: tompson>}), {}, {'task': '代码上线', 'id': '423b16d9-1fee-409f-b2a1-b3b1278a3d12', 'args': ('2', {'status': 3, 'name': 'payask', 'version': 'v2.1.6', 'assign_to': <User: tompson>}), 'kwargs': {}, 'retries': 0, 'eta': None, 'expires': None, 'utc': True, 'callbacks': None, 'errbacks': None, 'timelimit': (None, None), 'taskset': None, 'chord': None, 'headers': {}, 'reply_to': '5d5a7798-4983-35dd-9577-aa7d332c7dba', 'correlation_id': '423b16d9-1fee-409f-b2a1-b3b1278a3d12', 'delivery_info': {'exchange': 'celery', 'routing_key': 'celery', 'priority': 0, 'redelivered': None}, 'hostname': 'celery@localhost.localdomain', 'is_eager': False, 'group': None}) kwargs:{})
[2019-03-13 17:35:54,339: WARNING/Worker-2] {'status': 3, 'name': 'payask', 'version': 'v2.1.6', 'assign_to': <User: tompson>}
[2019-03-13 17:35:54,345: DEBUG/Worker-2] Starting new HTTP connection (1): 10.5.0.9:9001
[2019-03-13 17:35:54,354: DEBUG/MainProcess] Task accepted: 代码上线[423b16d9-1fee-409f-b2a1-b3b1278a3d12] pid:21031
[2019-03-13 17:35:54,493: DEBUG/Worker-2] http://10.5.0.9:9001 "GET /jenkins/crumbIssuer/api/json HTTP/1.1" 200 133
[2019-03-13 17:35:54,515: DEBUG/Worker-2] http://10.5.0.9:9001 "GET /jenkins/job/payask/api/json?depth=0 HTTP/1.1" 200 714
[2019-03-13 17:35:54,548: DEBUG/Worker-2] http://10.5.0.9:9001 "POST /jenkins/job/payask/buildWithParameters?Tag=v2.1.6 HTTP/1.1" 201 0
[2019-03-13 17:36:04,577: DEBUG/Worker-2] http://10.5.0.9:9001 "GET /jenkins/job/payask/13/consoleText HTTP/1.1" 200 593
[2019-03-13 17:36:04,590: INFO/MainProcess] Task 代码上线[423b16d9-1fee-409f-b2a1-b3b1278a3d12] succeeded in 10.251034773973515s: '[payask] Project release completed.......'
[2019-03-13 17:56:38,803: INFO/MainProcess] Received task: 代码上线[8a1f8091-5766-417b-b246-1c5d068f7a98]
[2019-03-13 17:56:38,807: DEBUG/MainProcess] TaskPool: Apply <function _fast_trace_task at 0x7f56117671e0> (args:('代码上线', '8a1f8091-5766-417b-b246-1c5d068f7a98', ('3', {'status': 3, 'name': 'payask', 'version': 'v2.1.6', 'assign_to': <User: tompson>}), {}, {'task': '代码上线', 'id': '8a1f8091-5766-417b-b246-1c5d068f7a98', 'args': ('3', {'status': 3, 'name': 'payask', 'version': 'v2.1.6', 'assign_to': <User: tompson>}), 'kwargs': {}, 'retries': 0, 'eta': None, 'expires': None, 'utc': True, 'callbacks': None, 'errbacks': None, 'timelimit': (None, None), 'taskset': None, 'chord': None, 'headers': {}, 'reply_to': '0d224888-9f3f-33db-b67e-264830b9b86c', 'correlation_id': '8a1f8091-5766-417b-b246-1c5d068f7a98', 'delivery_info': {'exchange': 'celery', 'routing_key': 'celery', 'priority': 0, 'redelivered': None}, 'hostname': 'celery@localhost.localdomain', 'is_eager': False, 'group': None}) kwargs:{})
[2019-03-13 17:56:38,810: WARNING/Worker-1] {'status': 3, 'name': 'payask', 'version': 'v2.1.6', 'assign_to': <User: tompson>}
[2019-03-13 17:56:38,815: DEBUG/Worker-1] Starting new HTTP connection (1): 10.5.0.9:9001
[2019-03-13 17:56:38,841: DEBUG/MainProcess] Task accepted: 代码上线[8a1f8091-5766-417b-b246-1c5d068f7a98] pid:21030
[2019-03-13 17:56:38,949: DEBUG/Worker-1] http://10.5.0.9:9001 "GET /jenkins/crumbIssuer/api/json HTTP/1.1" 200 133
[2019-03-13 17:56:38,975: DEBUG/Worker-1] http://10.5.0.9:9001 "GET /jenkins/job/payask/api/json?depth=0 HTTP/1.1" 200 720
[2019-03-13 17:56:38,997: DEBUG/Worker-1] http://10.5.0.9:9001 "POST /jenkins/job/payask/buildWithParameters?Tag=v2.1.6 HTTP/1.1" 201 0
[2019-03-13 17:56:49,026: DEBUG/Worker-1] http://10.5.0.9:9001 "GET /jenkins/job/payask/14/consoleText HTTP/1.1" 200 593
[2019-03-13 17:56:49,041: INFO/MainProcess] Task 代码上线[8a1f8091-5766-417b-b246-1c5d068f7a98] succeeded in 10.231298233993584s: '[payask] Project release completed.......'
[2019-03-13 18:07:17,767: DEBUG/MainProcess] celery@n_05 left
[2019-03-13 18:07:34,048: DEBUG/MainProcess] pidbox received method hello(from_node='celery@n_05', revoked={}) [reply_to:{'exchange': 'reply.celery.pidbox', 'routing_key': 'a3a7e31b-ea27-3a5f-89f6-6a8d81d77050'} ticket:ab952c74-a231-4f8d-a0e8-1f64b5026752]
[2019-03-13 18:07:34,051: INFO/MainProcess] sync with celery@n_05
[2019-03-13 18:07:35,264: DEBUG/MainProcess] celery@n_05 joined the party
[2019-03-13 18:20:33,891: INFO/MainProcess] Received task: 代码上线[e419e7fd-9ab3-43e4-b31c-4e8fdedad5d9]
[2019-03-13 18:20:33,895: DEBUG/MainProcess] TaskPool: Apply <function _fast_trace_task at 0x7f56117671e0> (args:('代码上线', 'e419e7fd-9ab3-43e4-b31c-4e8fdedad5d9', ('1', {'status': 3, 'name': 'payask', 'version': 'v2.1.6', 'assign_to': <User: tompson>}), {}, {'task': '代码上线', 'id': 'e419e7fd-9ab3-43e4-b31c-4e8fdedad5d9', 'args': ('1', {'status': 3, 'name': 'payask', 'version': 'v2.1.6', 'assign_to': <User: tompson>}), 'kwargs': {}, 'retries': 0, 'eta': None, 'expires': None, 'utc': True, 'callbacks': None, 'errbacks': None, 'timelimit': (None, None), 'taskset': None, 'chord': None, 'headers': {}, 'reply_to': 'eadcaf99-a0ec-3daf-93a1-4ea4207a3785', 'correlation_id': 'e419e7fd-9ab3-43e4-b31c-4e8fdedad5d9', 'delivery_info': {'exchange': 'celery', 'routing_key': 'celery', 'priority': 0, 'redelivered': None}, 'hostname': 'celery@localhost.localdomain', 'is_eager': False, 'group': None}) kwargs:{})
[2019-03-13 18:20:33,900: WARNING/Worker-2] {'status': 3, 'name': 'payask', 'version': 'v2.1.6', 'assign_to': <User: tompson>}
[2019-03-13 18:20:33,905: DEBUG/Worker-2] Starting new HTTP connection (1): 10.5.0.9:9001
[2019-03-13 18:20:33,918: DEBUG/MainProcess] Task accepted: 代码上线[e419e7fd-9ab3-43e4-b31c-4e8fdedad5d9] pid:21031
[2019-03-13 18:20:34,045: DEBUG/Worker-2] http://10.5.0.9:9001 "GET /jenkins/crumbIssuer/api/json HTTP/1.1" 200 133
[2019-03-13 18:20:34,065: DEBUG/Worker-2] http://10.5.0.9:9001 "GET /jenkins/job/payask/api/json?depth=0 HTTP/1.1" 200 726
[2019-03-13 18:20:34,092: DEBUG/Worker-2] http://10.5.0.9:9001 "POST /jenkins/job/payask/buildWithParameters?Tag=v2.1.6 HTTP/1.1" 201 0
[2019-03-13 18:20:44,145: DEBUG/Worker-2] http://10.5.0.9:9001 "GET /jenkins/job/payask/15/consoleText HTTP/1.1" 200 593
[2019-03-13 18:20:44,161: INFO/MainProcess] Task 代码上线[e419e7fd-9ab3-43e4-b31c-4e8fdedad5d9] succeeded in 10.261857039004099s: '[payask] Project release completed.......'
[2019-03-13 18:26:54,176: DEBUG/MainProcess] celery@n_05 left
[2019-03-13 18:27:00,074: DEBUG/MainProcess] celery@n_05 joined the party
[2019-03-13 18:27:00,118: DEBUG/MainProcess] pidbox received method hello(from_node='celery@n_05', revoked={}) [reply_to:{'exchange': 'reply.celery.pidbox', 'routing_key': '3d13b90e-2802-353a-acec-644e0eabb45f'} ticket:f757367b-dc28-4ae1-81ad-08ff666333ba]
[2019-03-13 18:27:00,119: INFO/MainProcess] sync with celery@n_05
[2019-03-13 18:55:58,669: INFO/MainProcess] missed heartbeat from celery@n_05
[2019-03-13 19:19:47,529: WARNING/MainProcess] consumer: Connection to broker lost. Trying to re-establish the connection...
Traceback (most recent call last):
  File "/home/vagrant/python3.6env/lib/python3.6/site-packages/redis/connection.py", line 174, in _read_from_socket
    data = recv(self._sock, socket_read_size)
  File "/home/vagrant/python3.6env/lib/python3.6/site-packages/redis/_compat.py", line 79, in recv
    return sock.recv(*args, **kwargs)
ConnectionResetError: [Errno 104] Connection reset by peer

During handling of the above exception, another exception occurred:

Traceback (most recent call last):
  File "/home/vagrant/python3.6env/lib/python3.6/site-packages/redis/client.py", line 668, in execute_command
    return self.parse_response(connection, command_name, **options)
  File "/home/vagrant/python3.6env/lib/python3.6/site-packages/redis/client.py", line 680, in parse_response
    response = connection.read_response()
  File "/home/vagrant/python3.6env/lib/python3.6/site-packages/redis/connection.py", line 624, in read_response
    response = self._parser.read_response()
  File "/home/vagrant/python3.6env/lib/python3.6/site-packages/redis/connection.py", line 284, in read_response
    response = self._buffer.readline()
  File "/home/vagrant/python3.6env/lib/python3.6/site-packages/redis/connection.py", line 216, in readline
    self._read_from_socket()
  File "/home/vagrant/python3.6env/lib/python3.6/site-packages/redis/connection.py", line 191, in _read_from_socket
    (e.args,))
redis.exceptions.ConnectionError: Error while reading from socket: (104, 'Connection reset by peer')

During handling of the above exception, another exception occurred:

Traceback (most recent call last):
  File "/home/vagrant/python3.6env/lib/python3.6/site-packages/redis/connection.py", line 484, in connect
    sock = self._connect()
  File "/home/vagrant/python3.6env/lib/python3.6/site-packages/redis/connection.py", line 541, in _connect
    raise err
  File "/home/vagrant/python3.6env/lib/python3.6/site-packages/redis/connection.py", line 529, in _connect
    sock.connect(socket_address)
TimeoutError: [Errno 110] Connection timed out

During handling of the above exception, another exception occurred:

Traceback (most recent call last):
  File "/home/vagrant/python3.6env/lib/python3.6/site-packages/celery/worker/consumer.py", line 280, in start
    blueprint.start(self)
  File "/home/vagrant/python3.6env/lib/python3.6/site-packages/celery/bootsteps.py", line 123, in start
    step.start(parent)
  File "/home/vagrant/python3.6env/lib/python3.6/site-packages/celery/worker/consumer.py", line 884, in start
    c.loop(*c.loop_args())
  File "/home/vagrant/python3.6env/lib/python3.6/site-packages/celery/worker/loops.py", line 76, in asynloop
    next(loop)
  File "/home/vagrant/python3.6env/lib/python3.6/site-packages/kombu/async/hub.py", line 281, in create_loop
    poll_timeout = fire_timers(propagate=propagate) if scheduled else 1
  File "/home/vagrant/python3.6env/lib/python3.6/site-packages/kombu/async/hub.py", line 140, in fire_timers
    entry()
  File "/home/vagrant/python3.6env/lib/python3.6/site-packages/kombu/async/timer.py", line 64, in __call__
    return self.fun(*self.args, **self.kwargs)
  File "/home/vagrant/python3.6env/lib/python3.6/site-packages/kombu/async/timer.py", line 132, in _reschedules
    return fun(*args, **kwargs)
  File "/home/vagrant/python3.6env/lib/python3.6/site-packages/kombu/transport/redis.py", line 322, in maybe_restore_messages
    num=channel.unacked_restore_limit,
  File "/home/vagrant/python3.6env/lib/python3.6/site-packages/kombu/transport/redis.py", line 188, in restore_visible
    self.unacked_mutex_expire):
  File "/usr/local/python3.6/lib/python3.6/contextlib.py", line 81, in __enter__
    return next(self.gen)
  File "/home/vagrant/python3.6env/lib/python3.6/site-packages/kombu/transport/redis.py", line 112, in Mutex
    i_won = client.setnx(name, lock_id)
  File "/home/vagrant/python3.6env/lib/python3.6/site-packages/redis/client.py", line 1196, in setnx
    return self.execute_command('SETNX', name, value)
  File "/home/vagrant/python3.6env/lib/python3.6/site-packages/redis/client.py", line 673, in execute_command
    connection.send_command(*args)
  File "/home/vagrant/python3.6env/lib/python3.6/site-packages/redis/connection.py", line 610, in send_command
    self.send_packed_command(self.pack_command(*args))
  File "/home/vagrant/python3.6env/lib/python3.6/site-packages/redis/connection.py", line 585, in send_packed_command
    self.connect()
  File "/home/vagrant/python3.6env/lib/python3.6/site-packages/redis/connection.py", line 489, in connect
    raise ConnectionError(self._error_message(e))
redis.exceptions.ConnectionError: Error 110 connecting to 10.5.0.9:6300. Connection timed out.
[2019-03-13 19:24:01,994: DEBUG/MainProcess] | Consumer: Restarting event loop...
[2019-03-13 19:24:01,995: DEBUG/MainProcess] | Consumer: Restarting Control...
[2019-03-13 19:26:09,224: DEBUG/MainProcess] | Consumer: Restarting Tasks...
[2019-03-13 19:26:09,225: DEBUG/MainProcess] Canceling task consumer...
[2019-03-13 19:26:09,226: DEBUG/MainProcess] | Consumer: Restarting Heart...
[2019-03-13 19:30:23,689: DEBUG/MainProcess] | Consumer: Restarting Gossip...
[2019-03-13 19:30:23,693: ERROR/MainProcess] Error on restarting Gossip: AttributeError("'NoneType' object has no attribute 'hostname'",)
Traceback (most recent call last):
  File "/home/vagrant/python3.6env/lib/python3.6/site-packages/redis/connection.py", line 174, in _read_from_socket
    data = recv(self._sock, socket_read_size)
  File "/home/vagrant/python3.6env/lib/python3.6/site-packages/redis/_compat.py", line 79, in recv
    return sock.recv(*args, **kwargs)
ConnectionResetError: [Errno 104] Connection reset by peer

During handling of the above exception, another exception occurred:

Traceback (most recent call last):
  File "/home/vagrant/python3.6env/lib/python3.6/site-packages/redis/client.py", line 668, in execute_command
    return self.parse_response(connection, command_name, **options)
  File "/home/vagrant/python3.6env/lib/python3.6/site-packages/redis/client.py", line 680, in parse_response
    response = connection.read_response()
  File "/home/vagrant/python3.6env/lib/python3.6/site-packages/redis/connection.py", line 624, in read_response
    response = self._parser.read_response()
  File "/home/vagrant/python3.6env/lib/python3.6/site-packages/redis/connection.py", line 284, in read_response
    response = self._buffer.readline()
  File "/home/vagrant/python3.6env/lib/python3.6/site-packages/redis/connection.py", line 216, in readline
    self._read_from_socket()
  File "/home/vagrant/python3.6env/lib/python3.6/site-packages/redis/connection.py", line 191, in _read_from_socket
    (e.args,))
redis.exceptions.ConnectionError: Error while reading from socket: (104, 'Connection reset by peer')

During handling of the above exception, another exception occurred:

Traceback (most recent call last):
  File "/home/vagrant/python3.6env/lib/python3.6/site-packages/redis/connection.py", line 484, in connect
    sock = self._connect()
  File "/home/vagrant/python3.6env/lib/python3.6/site-packages/redis/connection.py", line 541, in _connect
    raise err
  File "/home/vagrant/python3.6env/lib/python3.6/site-packages/redis/connection.py", line 529, in _connect
    sock.connect(socket_address)
TimeoutError: [Errno 110] Connection timed out

During handling of the above exception, another exception occurred:

Traceback (most recent call last):
  File "/home/vagrant/python3.6env/lib/python3.6/site-packages/celery/worker/consumer.py", line 280, in start
    blueprint.start(self)
  File "/home/vagrant/python3.6env/lib/python3.6/site-packages/celery/bootsteps.py", line 123, in start
    step.start(parent)
  File "/home/vagrant/python3.6env/lib/python3.6/site-packages/celery/worker/consumer.py", line 884, in start
    c.loop(*c.loop_args())
  File "/home/vagrant/python3.6env/lib/python3.6/site-packages/celery/worker/loops.py", line 76, in asynloop
    next(loop)
  File "/home/vagrant/python3.6env/lib/python3.6/site-packages/kombu/async/hub.py", line 281, in create_loop
    poll_timeout = fire_timers(propagate=propagate) if scheduled else 1
  File "/home/vagrant/python3.6env/lib/python3.6/site-packages/kombu/async/hub.py", line 140, in fire_timers
    entry()
  File "/home/vagrant/python3.6env/lib/python3.6/site-packages/kombu/async/timer.py", line 64, in __call__
    return self.fun(*self.args, **self.kwargs)
  File "/home/vagrant/python3.6env/lib/python3.6/site-packages/kombu/async/timer.py", line 132, in _reschedules
    return fun(*args, **kwargs)
  File "/home/vagrant/python3.6env/lib/python3.6/site-packages/kombu/transport/redis.py", line 322, in maybe_restore_messages
    num=channel.unacked_restore_limit,
  File "/home/vagrant/python3.6env/lib/python3.6/site-packages/kombu/transport/redis.py", line 188, in restore_visible
    self.unacked_mutex_expire):
  File "/usr/local/python3.6/lib/python3.6/contextlib.py", line 81, in __enter__
    return next(self.gen)
  File "/home/vagrant/python3.6env/lib/python3.6/site-packages/kombu/transport/redis.py", line 112, in Mutex
    i_won = client.setnx(name, lock_id)
  File "/home/vagrant/python3.6env/lib/python3.6/site-packages/redis/client.py", line 1196, in setnx
    return self.execute_command('SETNX', name, value)
  File "/home/vagrant/python3.6env/lib/python3.6/site-packages/redis/client.py", line 673, in execute_command
    connection.send_command(*args)
  File "/home/vagrant/python3.6env/lib/python3.6/site-packages/redis/connection.py", line 610, in send_command
    self.send_packed_command(self.pack_command(*args))
  File "/home/vagrant/python3.6env/lib/python3.6/site-packages/redis/connection.py", line 585, in send_packed_command
    self.connect()
  File "/home/vagrant/python3.6env/lib/python3.6/site-packages/redis/connection.py", line 489, in connect
    raise ConnectionError(self._error_message(e))
redis.exceptions.ConnectionError: Error 110 connecting to 10.5.0.9:6300. Connection timed out.

During handling of the above exception, another exception occurred:

Traceback (most recent call last):
  File "/home/vagrant/python3.6env/lib/python3.6/site-packages/celery/bootsteps.py", line 155, in send_all
    fun(parent, *args)
  File "/home/vagrant/python3.6env/lib/python3.6/site-packages/celery/bootsteps.py", line 409, in stop
    self._close(c, True)
  File "/home/vagrant/python3.6env/lib/python3.6/site-packages/celery/bootsteps.py", line 422, in _close
    ignore_errors(c.connection, channel.close)
  File "/home/vagrant/python3.6env/lib/python3.6/site-packages/kombu/common.py", line 289, in ignore_errors
    return fun(*args, **kwargs)
  File "/home/vagrant/python3.6env/lib/python3.6/site-packages/kombu/transport/redis.py", line 782, in close
    self.queue_delete(queue)
  File "/home/vagrant/python3.6env/lib/python3.6/site-packages/kombu/transport/virtual/__init__.py", line 460, in queue_delete
    self._delete(queue, exchange, *meta)
  File "/home/vagrant/python3.6env/lib/python3.6/site-packages/kombu/transport/redis.py", line 738, in _delete
    with self.conn_or_acquire() as client:
  File "/usr/local/python3.6/lib/python3.6/contextlib.py", line 81, in __enter__
    return next(self.gen)
  File "/home/vagrant/python3.6env/lib/python3.6/site-packages/kombu/transport/redis.py", line 903, in conn_or_acquire
    yield self._create_client()
  File "/home/vagrant/python3.6env/lib/python3.6/site-packages/kombu/transport/redis.py", line 874, in _create_client
    return self.Client(connection_pool=self.pool)
  File "/home/vagrant/python3.6env/lib/python3.6/site-packages/kombu/transport/redis.py", line 908, in pool
    self._pool = self._get_pool()
  File "/home/vagrant/python3.6env/lib/python3.6/site-packages/kombu/transport/redis.py", line 877, in _get_pool
    params = self._connparams(async=async)
  File "/home/vagrant/python3.6env/lib/python3.6/site-packages/kombu/transport/redis.py", line 820, in _connparams
    'host': conninfo.hostname or '127.0.0.1',
AttributeError: 'NoneType' object has no attribute 'hostname'
[2019-03-13 19:30:23,700: DEBUG/MainProcess] | Consumer: Restarting Mingle...
[2019-03-13 19:30:23,702: DEBUG/MainProcess] | Consumer: Restarting Events...
[2019-03-13 19:30:23,704: DEBUG/MainProcess] | Consumer: Restarting Connection...
[2019-03-13 19:30:23,705: DEBUG/MainProcess] | Consumer: Starting Connection
[2019-03-13 19:32:31,048: ERROR/MainProcess] consumer: Cannot connect to redis://:**@10.5.0.9:6300/0: .
Trying again in 2.00 seconds...

[2019-03-13 19:34:40,329: ERROR/MainProcess] consumer: Cannot connect to redis://:**@10.5.0.9:6300/0: .
Trying again in 4.00 seconds...

[2019-03-13 19:36:51,533: ERROR/MainProcess] consumer: Cannot connect to redis://:**@10.5.0.9:6300/0: .
Trying again in 6.00 seconds...

[2019-03-13 19:39:04,776: ERROR/MainProcess] consumer: Cannot connect to redis://:**@10.5.0.9:6300/0: .
Trying again in 8.00 seconds...

[2019-03-13 19:41:20,074: ERROR/MainProcess] consumer: Cannot connect to redis://:**@10.5.0.9:6300/0: .
Trying again in 10.00 seconds...

[2019-03-13 19:43:37,417: ERROR/MainProcess] consumer: Cannot connect to redis://:**@10.5.0.9:6300/0: .
Trying again in 12.00 seconds...

[2019-03-13 19:45:56,681: ERROR/MainProcess] consumer: Cannot connect to redis://:**@10.5.0.9:6300/0: .
Trying again in 14.00 seconds...

[2019-03-13 19:48:17,993: ERROR/MainProcess] consumer: Cannot connect to redis://:**@10.5.0.9:6300/0: .
Trying again in 16.00 seconds...

[2019-03-13 19:50:41,225: ERROR/MainProcess] consumer: Cannot connect to redis://:**@10.5.0.9:6300/0: .
Trying again in 18.00 seconds...

[2019-03-13 19:53:06,505: ERROR/MainProcess] consumer: Cannot connect to redis://:**@10.5.0.9:6300/0: .
Trying again in 20.00 seconds...

[2019-03-13 19:55:33,832: ERROR/MainProcess] consumer: Cannot connect to redis://:**@10.5.0.9:6300/0: .
Trying again in 22.00 seconds...

[2019-03-13 19:58:03,209: ERROR/MainProcess] consumer: Cannot connect to redis://:**@10.5.0.9:6300/0: .
Trying again in 24.00 seconds...

[2019-03-13 20:00:34,505: ERROR/MainProcess] consumer: Cannot connect to redis://:**@10.5.0.9:6300/0: .
Trying again in 26.00 seconds...

[2019-03-13 20:03:07,976: ERROR/MainProcess] consumer: Cannot connect to redis://:**@10.5.0.9:6300/0: .
Trying again in 28.00 seconds...

[2019-03-14 14:52:03,703: DEBUG/MainProcess] | Worker: Preparing bootsteps.
[2019-03-14 14:52:03,742: DEBUG/MainProcess] | Worker: Building graph...
[2019-03-14 14:52:03,744: DEBUG/MainProcess] | Worker: New boot order: {Timer, Hub, Queues (intra), Pool, Autoscaler, Beat, StateDB, Autoreloader, Consumer}
[2019-03-14 14:52:03,789: DEBUG/MainProcess] | Consumer: Preparing bootsteps.
[2019-03-14 14:52:03,792: DEBUG/MainProcess] | Consumer: Building graph...
[2019-03-14 14:52:03,858: DEBUG/MainProcess] | Consumer: New boot order: {Connection, Events, Heart, Mingle, Gossip, Agent, Tasks, Control, event loop}
[2019-03-14 14:52:03,899: DEBUG/MainProcess] | Worker: Starting Hub
[2019-03-14 14:52:03,901: DEBUG/MainProcess] ^-- substep ok
[2019-03-14 14:52:03,902: DEBUG/MainProcess] | Worker: Starting Pool
[2019-03-14 14:52:04,993: DEBUG/MainProcess] ^-- substep ok
[2019-03-14 14:52:05,060: DEBUG/MainProcess] | Worker: Starting Consumer
[2019-03-14 14:52:05,061: DEBUG/MainProcess] | Consumer: Starting Connection
[2019-03-14 14:52:05,604: INFO/MainProcess] Connected to redis://:**@10.5.0.9:6300/0
[2019-03-14 14:52:05,608: DEBUG/MainProcess] ^-- substep ok
[2019-03-14 14:52:05,612: DEBUG/MainProcess] | Consumer: Starting Events
[2019-03-14 14:52:06,018: DEBUG/MainProcess] ^-- substep ok
[2019-03-14 14:52:06,025: DEBUG/MainProcess] | Consumer: Starting Heart
[2019-03-14 14:52:06,042: DEBUG/MainProcess] ^-- substep ok
[2019-03-14 14:52:06,046: DEBUG/MainProcess] | Consumer: Starting Mingle
[2019-03-14 14:52:06,054: INFO/MainProcess] mingle: searching for neighbors
[2019-03-14 14:52:07,286: INFO/MainProcess] mingle: all alone
[2019-03-14 14:52:07,290: DEBUG/MainProcess] ^-- substep ok
[2019-03-14 14:52:07,294: DEBUG/MainProcess] | Consumer: Starting Gossip
[2019-03-14 14:52:07,573: DEBUG/MainProcess] ^-- substep ok
[2019-03-14 14:52:07,575: DEBUG/MainProcess] | Consumer: Starting Tasks
[2019-03-14 14:52:07,673: DEBUG/MainProcess] ^-- substep ok
[2019-03-14 14:52:07,674: DEBUG/MainProcess] | Consumer: Starting Control
[2019-03-14 14:52:07,997: DEBUG/MainProcess] ^-- substep ok
[2019-03-14 14:52:07,999: DEBUG/MainProcess] | Consumer: Starting event loop
[2019-03-14 14:52:08,002: WARNING/MainProcess] celery@localhost.localdomain ready.
[2019-03-14 14:52:08,004: DEBUG/MainProcess] | Worker: Hub.register Pool...
[2019-03-14 14:52:08,007: DEBUG/MainProcess] basic.qos: prefetch_count->8
[2019-03-14 14:52:08,352: INFO/MainProcess] Received task: 代码上线[ae255d97-a7ea-4326-b933-77dccea6bbb7]
[2019-03-14 14:52:08,357: DEBUG/MainProcess] TaskPool: Apply <function _fast_trace_task at 0x7fb58d4dd1e0> (args:('代码上线', 'ae255d97-a7ea-4326-b933-77dccea6bbb7', ('23', {'status': 3, 'name': 'payask', 'version': 'v2.1.6', 'assign_to': <User: tompson>, 'deploy_time': '2019-03-14 14:50:54'}), {}, {'task': '代码上线', 'id': 'ae255d97-a7ea-4326-b933-77dccea6bbb7', 'args': ('23', {'status': 3, 'name': 'payask', 'version': 'v2.1.6', 'assign_to': <User: tompson>, 'deploy_time': '2019-03-14 14:50:54'}), 'kwargs': {}, 'retries': 0, 'eta': None, 'expires': None, 'utc': True, 'callbacks': None, 'errbacks': None, 'timelimit': (None, None), 'taskset': None, 'chord': None, 'headers': {}, 'reply_to': '6317b503-7ad1-39b3-9930-cdef85c512cc', 'correlation_id': 'ae255d97-a7ea-4326-b933-77dccea6bbb7', 'delivery_info': {'exchange': 'celery', 'routing_key': 'celery', 'priority': 0, 'redelivered': None}, 'hostname': 'celery@localhost.localdomain', 'is_eager': False, 'group': None}) kwargs:{})
[2019-03-14 14:52:08,439: DEBUG/Worker-2] Starting new HTTP connection (1): 10.5.0.9:9001
[2019-03-14 14:52:08,443: DEBUG/MainProcess] Task accepted: 代码上线[ae255d97-a7ea-4326-b933-77dccea6bbb7] pid:4131
[2019-03-14 14:52:08,655: DEBUG/Worker-2] http://10.5.0.9:9001 "GET /jenkins/crumbIssuer/api/json HTTP/1.1" 200 133
[2019-03-14 14:52:08,717: DEBUG/Worker-2] http://10.5.0.9:9001 "GET /jenkins/job/payask/api/json?depth=0 HTTP/1.1" 200 744
[2019-03-14 14:52:08,738: DEBUG/Worker-2] http://10.5.0.9:9001 "POST /jenkins/job/payask/buildWithParameters?Tag=v2.1.6 HTTP/1.1" 201 0
[2019-03-14 14:52:09,260: DEBUG/MainProcess] celery@n_05 joined the party
[2019-03-14 14:52:18,771: DEBUG/Worker-2] http://10.5.0.9:9001 "GET /jenkins/job/payask/18/consoleText HTTP/1.1" 200 620
[2019-03-14 14:52:18,804: INFO/MainProcess] Task 代码上线[ae255d97-a7ea-4326-b933-77dccea6bbb7] succeeded in 10.374483145999875s: '[payask] Project release completed.......'
[2019-03-14 21:33:07,706: INFO/MainProcess] missed heartbeat from celery@n_05
[2019-03-14 21:33:07,708: DEBUG/MainProcess] celery@n_05 joined the party
[2019-03-14 21:33:28,837: INFO/MainProcess] missed heartbeat from celery@n_05
[2019-03-14 21:33:28,843: WARNING/MainProcess] Substantial drift from celery@n_05 may mean clocks are out of sync.  Current drift is
20 seconds.  [orig: 2019-03-14 21:33:28.843119 recv: 2019-03-14 21:33:08.697557]

[2019-03-14 21:33:28,846: DEBUG/MainProcess] celery@n_05 joined the party
[2019-03-14 21:33:44,409: INFO/MainProcess] missed heartbeat from celery@n_05
[2019-03-14 21:33:44,421: DEBUG/MainProcess] celery@n_05 joined the party
[2019-03-14 21:33:53,166: INFO/MainProcess] missed heartbeat from celery@n_05
[2019-03-14 21:33:54,896: DEBUG/MainProcess] celery@n_05 joined the party
[2019-03-14 21:34:08,722: INFO/MainProcess] missed heartbeat from celery@n_05
[2019-03-14 21:34:09,079: DEBUG/MainProcess] celery@n_05 joined the party
[2019-03-14 21:34:17,468: INFO/MainProcess] missed heartbeat from celery@n_05
[2019-03-14 21:34:21,066: DEBUG/MainProcess] celery@n_05 joined the party
[2019-03-14 21:34:30,249: INFO/MainProcess] missed heartbeat from celery@n_05
[2019-03-14 21:34:32,166: DEBUG/MainProcess] celery@n_05 joined the party
[2019-03-14 21:34:45,815: INFO/MainProcess] missed heartbeat from celery@n_05
[2019-03-14 21:34:45,822: DEBUG/MainProcess] celery@n_05 joined the party
[2019-03-14 21:34:54,554: INFO/MainProcess] missed heartbeat from celery@n_05
[2019-03-14 21:34:57,115: DEBUG/MainProcess] celery@n_05 joined the party
[2019-03-14 21:35:10,179: INFO/MainProcess] missed heartbeat from celery@n_05
[2019-03-14 21:35:11,217: DEBUG/MainProcess] celery@n_05 joined the party
[2019-03-14 21:35:23,734: INFO/MainProcess] missed heartbeat from celery@n_05
[2019-03-14 21:35:23,742: DEBUG/MainProcess] celery@n_05 joined the party
[2019-03-14 21:35:44,871: INFO/MainProcess] missed heartbeat from celery@n_05
[2019-03-14 21:36:01,023: DEBUG/MainProcess] celery@n_05 joined the party
[2019-03-14 21:36:09,204: INFO/MainProcess] missed heartbeat from celery@n_05
[2019-03-14 21:36:12,784: DEBUG/MainProcess] celery@n_05 joined the party
[2019-03-14 21:36:22,043: INFO/MainProcess] missed heartbeat from celery@n_05
[2019-03-14 21:36:23,690: DEBUG/MainProcess] celery@n_05 joined the party
[2019-03-14 21:36:37,667: INFO/MainProcess] missed heartbeat from celery@n_05
[2019-03-14 21:36:37,675: DEBUG/MainProcess] celery@n_05 joined the party
[2019-03-14 21:36:46,363: INFO/MainProcess] missed heartbeat from celery@n_05
[2019-03-14 21:36:49,389: DEBUG/MainProcess] celery@n_05 joined the party
[2019-03-14 21:37:01,929: INFO/MainProcess] missed heartbeat from celery@n_05
[2019-03-14 21:37:01,938: DEBUG/MainProcess] celery@n_05 joined the party
[2019-03-14 21:37:15,482: INFO/MainProcess] missed heartbeat from celery@n_05
[2019-03-14 21:37:15,484: DEBUG/MainProcess] celery@n_05 joined the party
[2019-03-14 21:37:36,621: INFO/MainProcess] missed heartbeat from celery@n_05
[2019-03-14 21:37:53,093: DEBUG/MainProcess] celery@n_05 joined the party
[2019-03-14 21:38:00,939: INFO/MainProcess] missed heartbeat from celery@n_05
[2019-03-14 21:38:02,958: DEBUG/MainProcess] celery@n_05 joined the party
[2019-03-14 21:38:16,508: INFO/MainProcess] missed heartbeat from celery@n_05
[2019-03-14 21:38:16,515: DEBUG/MainProcess] celery@n_05 joined the party
[2019-03-14 21:38:25,264: INFO/MainProcess] missed heartbeat from celery@n_05
[2019-03-14 21:38:29,139: DEBUG/MainProcess] celery@n_05 joined the party
[2019-03-14 21:38:39,533: INFO/MainProcess] missed heartbeat from celery@n_05
[2019-03-14 21:38:39,876: DEBUG/MainProcess] celery@n_05 joined the party
[2019-03-14 21:38:50,314: INFO/MainProcess] missed heartbeat from celery@n_05
[2019-03-14 21:38:53,496: DEBUG/MainProcess] celery@n_05 joined the party
[2019-03-14 21:39:05,868: INFO/MainProcess] missed heartbeat from celery@n_05
[2019-03-14 21:39:05,876: DEBUG/MainProcess] celery@n_05 joined the party
[2019-03-14 21:39:14,651: INFO/MainProcess] missed heartbeat from celery@n_05
[2019-03-14 21:39:17,570: DEBUG/MainProcess] celery@n_05 joined the party
[2019-03-14 21:39:27,451: INFO/MainProcess] missed heartbeat from celery@n_05
[2019-03-14 21:39:29,407: DEBUG/MainProcess] celery@n_05 joined the party
[2019-03-14 21:39:43,055: INFO/MainProcess] missed heartbeat from celery@n_05
[2019-03-14 21:39:43,337: DEBUG/MainProcess] celery@n_05 joined the party
[2019-03-14 21:39:51,807: INFO/MainProcess] missed heartbeat from celery@n_05
[2019-03-14 21:39:55,449: DEBUG/MainProcess] celery@n_05 joined the party
[2019-03-14 21:40:07,377: INFO/MainProcess] missed heartbeat from celery@n_05
[2019-03-14 21:40:07,379: DEBUG/MainProcess] celery@n_05 joined the party
[2019-03-14 21:40:20,930: INFO/MainProcess] missed heartbeat from celery@n_05
[2019-03-14 21:40:20,933: DEBUG/MainProcess] celery@n_05 joined the party
[2019-03-14 21:40:42,065: INFO/MainProcess] missed heartbeat from celery@n_05
[2019-03-14 21:40:57,640: DEBUG/MainProcess] celery@n_05 joined the party
[2019-03-14 21:41:18,775: INFO/MainProcess] missed heartbeat from celery@n_05
[2019-03-14 21:41:18,901: DEBUG/MainProcess] celery@n_05 joined the party
[2019-03-14 21:41:34,344: INFO/MainProcess] missed heartbeat from celery@n_05
[2019-03-14 21:41:34,351: DEBUG/MainProcess] celery@n_05 joined the party
[2019-03-14 21:41:43,096: INFO/MainProcess] missed heartbeat from celery@n_05
[2019-03-14 21:41:45,711: DEBUG/MainProcess] celery@n_05 joined the party
[2019-03-14 21:41:58,652: INFO/MainProcess] missed heartbeat from celery@n_05
[2019-03-14 21:41:58,659: DEBUG/MainProcess] celery@n_05 joined the party
[2019-03-14 21:42:12,202: INFO/MainProcess] missed heartbeat from celery@n_05
[2019-03-14 21:42:12,205: DEBUG/MainProcess] celery@n_05 joined the party
[2019-03-14 21:42:33,337: INFO/MainProcess] missed heartbeat from celery@n_05
[2019-03-14 21:42:49,873: DEBUG/MainProcess] celery@n_05 joined the party
[2019-03-14 21:43:10,037: INFO/MainProcess] missed heartbeat from celery@n_05
[2019-03-14 21:43:10,045: DEBUG/MainProcess] celery@n_05 joined the party
[2019-03-15 04:46:21,536: INFO/MainProcess] missed heartbeat from celery@n_05
[2019-03-15 04:46:21,539: DEBUG/MainProcess] celery@n_05 joined the party
[2019-03-15 10:17:39,389: ERROR/MainProcess] Received unregistered task of type '发送邮件'.
The message has been ignored and discarded.

Did you remember to import the module containing this task?
Or maybe you are using relative imports?
Please see http://bit.ly/gLye1c for more information.

The full contents of the message body was:
{'task': '发送邮件', 'id': '99756f53-5a07-42bc-aaae-a4e44870394a', 'args': ('payask上线申请', '第十次', ['tompson@169kang.com', 'ops@169kang.com']), 'kwargs': {}, 'retries': 0, 'eta': None, 'expires': None, 'utc': True, 'callbacks': None, 'errbacks': None, 'timelimit': (None, None), 'taskset': None, 'chord': None} (349b)
Traceback (most recent call last):
  File "/home/vagrant/python3.6env/lib/python3.6/site-packages/celery/worker/consumer.py", line 465, in on_task_received
    strategies[type_](message, body,
KeyError: '发送邮件'
[2019-03-15 11:30:08,885: DEBUG/MainProcess] | Worker: Closing Hub...
[2019-03-15 11:30:08,889: DEBUG/MainProcess] | Worker: Closing Pool...
[2019-03-15 11:30:08,890: DEBUG/MainProcess] | Worker: Closing Consumer...
[2019-03-15 11:30:08,891: DEBUG/MainProcess] | Worker: Stopping Consumer...
[2019-03-15 11:30:08,892: DEBUG/MainProcess] | Consumer: Closing Connection...
[2019-03-15 11:30:08,894: DEBUG/MainProcess] | Consumer: Closing Events...
[2019-03-15 11:30:08,895: DEBUG/MainProcess] | Consumer: Closing Heart...
[2019-03-15 11:30:08,898: DEBUG/MainProcess] | Consumer: Closing Mingle...
[2019-03-15 11:30:08,899: DEBUG/MainProcess] | Consumer: Closing Gossip...
[2019-03-15 11:30:08,900: DEBUG/MainProcess] | Consumer: Closing Tasks...
[2019-03-15 11:30:08,901: DEBUG/MainProcess] | Consumer: Closing Control...
[2019-03-15 11:30:08,903: DEBUG/MainProcess] | Consumer: Closing event loop...
[2019-03-15 11:30:08,904: DEBUG/MainProcess] | Consumer: Stopping event loop...
[2019-03-15 11:30:08,905: DEBUG/MainProcess] | Consumer: Stopping Control...
[2019-03-15 11:30:09,197: DEBUG/MainProcess] | Consumer: Stopping Tasks...
[2019-03-15 11:30:09,198: DEBUG/MainProcess] Canceling task consumer...
[2019-03-15 11:30:09,199: DEBUG/MainProcess] | Consumer: Stopping Gossip...
[2019-03-15 11:30:09,317: DEBUG/MainProcess] | Consumer: Stopping Mingle...
[2019-03-15 11:30:09,318: DEBUG/MainProcess] | Consumer: Stopping Heart...
[2019-03-15 11:30:09,337: DEBUG/MainProcess] | Consumer: Stopping Events...
[2019-03-15 11:30:09,338: DEBUG/MainProcess] | Consumer: Stopping Connection...
[2019-03-15 11:30:09,340: DEBUG/MainProcess] | Worker: Stopping Pool...
[2019-03-15 11:30:09,611: DEBUG/MainProcess] removing tasks from inqueue until task handler finished
[2019-03-15 11:30:17,576: DEBUG/MainProcess] | Worker: Preparing bootsteps.
[2019-03-15 11:30:17,589: DEBUG/MainProcess] | Worker: Building graph...
[2019-03-15 11:30:17,593: DEBUG/MainProcess] | Worker: New boot order: {Beat, Timer, Hub, Queues (intra), Pool, Autoreloader, Autoscaler, StateDB, Consumer}
[2019-03-15 11:30:17,655: DEBUG/MainProcess] | Consumer: Preparing bootsteps.
[2019-03-15 11:30:17,657: DEBUG/MainProcess] | Consumer: Building graph...
[2019-03-15 11:30:17,723: DEBUG/MainProcess] | Consumer: New boot order: {Connection, Agent, Events, Mingle, Tasks, Control, Gossip, Heart, event loop}
[2019-03-15 11:30:17,767: DEBUG/MainProcess] | Worker: Starting Hub
[2019-03-15 11:30:17,769: DEBUG/MainProcess] ^-- substep ok
[2019-03-15 11:30:17,771: DEBUG/MainProcess] | Worker: Starting Pool
[2019-03-15 11:30:17,923: DEBUG/MainProcess] ^-- substep ok
[2019-03-15 11:30:17,925: DEBUG/MainProcess] | Worker: Starting Consumer
[2019-03-15 11:30:17,927: DEBUG/MainProcess] | Consumer: Starting Connection
[2019-03-15 11:30:18,330: INFO/MainProcess] Connected to redis://:**@10.5.0.9:6300/0
[2019-03-15 11:30:18,332: DEBUG/MainProcess] ^-- substep ok
[2019-03-15 11:30:18,335: DEBUG/MainProcess] | Consumer: Starting Events
[2019-03-15 11:30:18,777: DEBUG/MainProcess] ^-- substep ok
[2019-03-15 11:30:18,779: DEBUG/MainProcess] | Consumer: Starting Mingle
[2019-03-15 11:30:18,780: INFO/MainProcess] mingle: searching for neighbors
[2019-03-15 11:30:20,022: INFO/MainProcess] mingle: all alone
[2019-03-15 11:30:20,024: DEBUG/MainProcess] ^-- substep ok
[2019-03-15 11:30:20,025: DEBUG/MainProcess] | Consumer: Starting Tasks
[2019-03-15 11:30:20,054: DEBUG/MainProcess] ^-- substep ok
[2019-03-15 11:30:20,055: DEBUG/MainProcess] | Consumer: Starting Control
[2019-03-15 11:30:20,419: DEBUG/MainProcess] ^-- substep ok
[2019-03-15 11:30:20,422: DEBUG/MainProcess] | Consumer: Starting Gossip
[2019-03-15 11:30:20,791: DEBUG/MainProcess] ^-- substep ok
[2019-03-15 11:30:20,792: DEBUG/MainProcess] | Consumer: Starting Heart
[2019-03-15 11:30:20,805: DEBUG/MainProcess] ^-- substep ok
[2019-03-15 11:30:20,806: DEBUG/MainProcess] | Consumer: Starting event loop
[2019-03-15 11:30:20,808: WARNING/MainProcess] celery@localhost.localdomain ready.
[2019-03-15 11:30:20,809: DEBUG/MainProcess] | Worker: Hub.register Pool...
[2019-03-15 11:30:20,811: DEBUG/MainProcess] basic.qos: prefetch_count->8
[2019-03-15 11:30:21,412: DEBUG/MainProcess] celery@n_05 joined the party
[2019-03-15 11:59:11,846: INFO/MainProcess] Received task: 发送邮件[b26c5eae-dba7-486c-83d3-0f1ae94a3121]
[2019-03-15 11:59:11,852: DEBUG/MainProcess] TaskPool: Apply <function _fast_trace_task at 0x7f983e5e61e0> (args:('发送邮件', 'b26c5eae-dba7-486c-83d3-0f1ae94a3121', ('payask上线申请', '第十一次', ['tompson@169kang.com', 'ops@169kang.com']), {}, {'task': '发送邮件', 'id': 'b26c5eae-dba7-486c-83d3-0f1ae94a3121', 'args': ('payask上线申请', '第十一次', ['tompson@169kang.com', 'ops@169kang.com']), 'kwargs': {}, 'retries': 0, 'eta': None, 'expires': None, 'utc': True, 'callbacks': None, 'errbacks': None, 'timelimit': (None, None), 'taskset': None, 'chord': None, 'headers': {}, 'reply_to': 'a33ffe5a-8c3b-3227-b01e-f22fccd09a0e', 'correlation_id': 'b26c5eae-dba7-486c-83d3-0f1ae94a3121', 'delivery_info': {'exchange': 'celery', 'routing_key': 'celery', 'priority': 0, 'redelivered': None}, 'hostname': 'celery@localhost.localdomain', 'is_eager': False, 'group': None}) kwargs:{})
[2019-03-15 11:59:11,957: DEBUG/MainProcess] Task accepted: 发送邮件[b26c5eae-dba7-486c-83d3-0f1ae94a3121] pid:8973
[2019-03-15 11:59:15,335: INFO/MainProcess] Task 发送邮件[b26c5eae-dba7-486c-83d3-0f1ae94a3121] succeeded in 3.4794543820025865s: '邮件发送成功！！！'
[2019-03-15 13:39:03,845: INFO/MainProcess] Received task: 发送邮件[9f7c07a4-0afc-46ed-89ec-1c55b9bc732f]
[2019-03-15 13:39:03,847: DEBUG/MainProcess] TaskPool: Apply <function _fast_trace_task at 0x7f983e5e61e0> (args:('发送邮件', '9f7c07a4-0afc-46ed-89ec-1c55b9bc732f', ('payask上线申请', '第十二次上线', ['tompson@169kang.com', 'ops@169kang.com']), {}, {'task': '发送邮件', 'id': '9f7c07a4-0afc-46ed-89ec-1c55b9bc732f', 'args': ('payask上线申请', '第十二次上线', ['tompson@169kang.com', 'ops@169kang.com']), 'kwargs': {}, 'retries': 0, 'eta': None, 'expires': None, 'utc': True, 'callbacks': None, 'errbacks': None, 'timelimit': (None, None), 'taskset': None, 'chord': None, 'headers': {}, 'reply_to': 'a33ffe5a-8c3b-3227-b01e-f22fccd09a0e', 'correlation_id': '9f7c07a4-0afc-46ed-89ec-1c55b9bc732f', 'delivery_info': {'exchange': 'celery', 'routing_key': 'celery', 'priority': 0, 'redelivered': None}, 'hostname': 'celery@localhost.localdomain', 'is_eager': False, 'group': None}) kwargs:{})
[2019-03-15 13:39:03,959: DEBUG/MainProcess] Task accepted: 发送邮件[9f7c07a4-0afc-46ed-89ec-1c55b9bc732f] pid:8972
[2019-03-15 13:39:04,757: INFO/MainProcess] Task 发送邮件[9f7c07a4-0afc-46ed-89ec-1c55b9bc732f] succeeded in 0.9015758809982799s: '邮件发送成功！！！'
[2019-03-15 13:52:19,621: INFO/MainProcess] Received task: 发送邮件[1a159fba-23d0-4476-affb-5f587c077c3a]
[2019-03-15 13:52:19,622: DEBUG/MainProcess] TaskPool: Apply <function _fast_trace_task at 0x7f983e5e61e0> (args:('发送邮件', '1a159fba-23d0-4476-affb-5f587c077c3a', ('payask上线申请', '第十四次', ['tompson@169kang.com', 'ops@169kang.com']), {}, {'task': '发送邮件', 'id': '1a159fba-23d0-4476-affb-5f587c077c3a', 'args': ('payask上线申请', '第十四次', ['tompson@169kang.com', 'ops@169kang.com']), 'kwargs': {}, 'retries': 0, 'eta': None, 'expires': None, 'utc': True, 'callbacks': None, 'errbacks': None, 'timelimit': (None, None), 'taskset': None, 'chord': None, 'headers': {}, 'reply_to': 'a33ffe5a-8c3b-3227-b01e-f22fccd09a0e', 'correlation_id': '1a159fba-23d0-4476-affb-5f587c077c3a', 'delivery_info': {'exchange': 'celery', 'routing_key': 'celery', 'priority': 0, 'redelivered': None}, 'hostname': 'celery@localhost.localdomain', 'is_eager': False, 'group': None}) kwargs:{})
[2019-03-15 13:52:19,713: DEBUG/MainProcess] Task accepted: 发送邮件[1a159fba-23d0-4476-affb-5f587c077c3a] pid:8973
[2019-03-15 13:52:20,519: INFO/MainProcess] Task 发送邮件[1a159fba-23d0-4476-affb-5f587c077c3a] succeeded in 0.8841955169918947s: '邮件发送成功！！！'
[2019-03-15 13:59:08,727: INFO/MainProcess] Received task: 发送邮件[81285fe6-fc8e-4c3b-9418-42a3168a267d]
[2019-03-15 13:59:08,729: DEBUG/MainProcess] TaskPool: Apply <function _fast_trace_task at 0x7f983e5e61e0> (args:('发送邮件', '81285fe6-fc8e-4c3b-9418-42a3168a267d', ('payask上线申请', '第十二次上线', ['tompson@169kang.com', 'ops@169kang.com']), {}, {'task': '发送邮件', 'id': '81285fe6-fc8e-4c3b-9418-42a3168a267d', 'args': ('payask上线申请', '第十二次上线', ['tompson@169kang.com', 'ops@169kang.com']), 'kwargs': {}, 'retries': 0, 'eta': None, 'expires': None, 'utc': True, 'callbacks': None, 'errbacks': None, 'timelimit': (None, None), 'taskset': None, 'chord': None, 'headers': {}, 'reply_to': 'a33ffe5a-8c3b-3227-b01e-f22fccd09a0e', 'correlation_id': '81285fe6-fc8e-4c3b-9418-42a3168a267d', 'delivery_info': {'exchange': 'celery', 'routing_key': 'celery', 'priority': 0, 'redelivered': None}, 'hostname': 'celery@localhost.localdomain', 'is_eager': False, 'group': None}) kwargs:{})
[2019-03-15 13:59:08,836: DEBUG/MainProcess] Task accepted: 发送邮件[81285fe6-fc8e-4c3b-9418-42a3168a267d] pid:8972
[2019-03-15 13:59:14,665: INFO/MainProcess] Task 发送邮件[81285fe6-fc8e-4c3b-9418-42a3168a267d] succeeded in 5.931655545005924s: '邮件发送成功！！！'
[2019-03-15 14:32:25,989: DEBUG/MainProcess] celery@n_05 left
[2019-03-15 14:32:31,732: DEBUG/MainProcess] pidbox received method hello(from_node='celery@n_05', revoked={}) [reply_to:{'exchange': 'reply.celery.pidbox', 'routing_key': '783caae5-a607-3a14-9ed7-e176c828e30d'} ticket:b5e95274-d199-4b0c-be7c-c95d154800eb]
[2019-03-15 14:32:31,734: INFO/MainProcess] sync with celery@n_05
[2019-03-15 14:32:32,718: DEBUG/MainProcess] celery@n_05 joined the party
[2019-03-15 15:05:20,236: DEBUG/MainProcess] celery@n_05 left
[2019-03-15 15:05:24,134: DEBUG/MainProcess] pidbox received method hello(from_node='celery@n_05', revoked={}) [reply_to:{'exchange': 'reply.celery.pidbox', 'routing_key': '99bd2830-9ab4-3956-afc9-bd6516c8dd06'} ticket:a70bbfc6-b86f-4c12-915f-12d33c6f4153]
[2019-03-15 15:05:24,135: INFO/MainProcess] sync with celery@n_05
[2019-03-15 15:05:25,148: DEBUG/MainProcess] celery@n_05 joined the party
